File: DSC图/ExpAll_冷榨3.csv
#EXPORTTYPE:                 ,ALL
#FILE:                       ,¿‰’•3.ngb-sd7
#FORMAT:                     ,NETZSCH5
#FTYPE:                      ,ANSI
#IDENTITY:                   ,3
#DECIMAL:                    ,POINT
#SEPARATOR:                  ,COMMA
#MTYPE:                      ,DSC
#INSTRUMENT:                 ,NETZSCH DSC 204F1 Phoenix
#PROJECT:                    ,1
#DATE/TIME:                  ,2023/4/24 16:37:24 (UTC+8)
#CORR. FILE:                 ,
#TEMPCAL:                    ,applied
#SENSITIVITY:                ,applied
#LABORATORY:                 ,
#OPERATOR:                   ,0
#REMARK:                     ,
#SAMPLE:                     ,¿‰’•
#SAMPLE MASS /mg:            ,8.79
#MATERIAL:                   ,
#REFERENCE:                  ,
#REFERENCE MASS /mg:         ,0
#TYPE OF CRUCIBLE:           ,Concavus Pan Al, open
#SAMPLE CRUCIBLE MASS /mg:   ,0
#REFERENCE CRUCIBLE MASS /mg:,0
#M.RANGE /¶ÃV:                ,5000
#TAU-R:                      ,---
#CORR. CODE:                 ,000
#EXO:                        ,+1
#RANGE:                      ,20°„C/10.0(K/min)/120°„C
#SEGMENT:                    ,S1/1
#SEG. 1:                     ,20°„C/10.0(K/min)/120°„C

#*RESULTS:     ,File,Segment,Result,Unit,Y_value,Unit ,Range_Xmin,Unit,Range_Xmax,Unit,Range_Ymin,Unit ,Range_Ymax,Unit
#*Area (DSC)(o),¿‰’•3 ,1      ,-60.04,J/g ,-      ,-    ,42.9      ,°„C  ,115.3     ,°„C  ,-0.4206   ,mW/mg,-0.6201   ,mW/mg
#*Onset (DSC)  ,¿‰’•3 ,1      ,42.9  ,°„C  ,-0.3979,mW/mg,25.8      ,°„C  ,85.7      ,°„C  ,-0.3556   ,mW/mg,-0.7778   ,mW/mg
#*Peak (DSC)   ,¿‰’•3 ,1      ,89.8  ,°„C  ,-0.7817,mW/mg,25.8      ,°„C  ,102.0     ,°„C  ,-0.3556   ,mW/mg,-0.7388   ,mW/mg
#*End (DSC)    ,¿‰’•3 ,1      ,115.3 ,°„C  ,-0.6201,mW/mg,90.5      ,°„C  ,119.8     ,°„C  ,-0.7813   ,mW/mg,-0.5747   ,mW/mg

##Temp./°„C,Time/min,DSC/(mW/mg),Sensit./(uV/mW),Segment
  7.84000,0.00000, 6.775169e-002,3.29862,1
  7.83486,0.01000, 6.178027e-002,3.29862,0
  7.83131,0.02000, 5.591357e-002,3.29862,0
  7.83326,0.03000, 5.049392e-002,3.29862,0
  7.84656,0.04000, 4.523107e-002,3.29862,1
  7.87394,0.05000, 4.001978e-002,3.29862,1
  7.91597,0.06000, 3.417347e-002,3.29862,1
  7.97149,0.07000, 2.742957e-002,3.29862,1
  8.03890,0.08000, 1.968201e-002,3.29862,1
  8.11622,0.09000, 1.072164e-002,3.29862,1
  8.20169,0.10000, 6.786598e-004,3.29862,1
  8.26711,0.11000,-9.656723e-003,3.29862,1
  8.33889,0.12000,-2.062577e-002,3.29862,1
  8.41702,0.13000,-3.207061e-002,3.29862,1
  8.50148,0.14000,-4.354366e-002,3.29862,1
  8.59208,0.15000,-5.491335e-002,3.29861,1
  8.68844,0.16000,-6.636279e-002,3.29861,1
  8.79010,0.17000,-7.770861e-002,3.29861,1
  8.89644,0.18000,-8.876502e-002,3.29861,1
  9.00687,0.19000,-9.976988e-002,3.29861,1
  9.12084,0.20000,      -0.11025,3.29861,1
  9.23780,0.21000,      -0.12015,3.29860,1
  9.35725,0.22000,      -0.13018,3.29860,1
  9.47887,0.23000,      -0.13971,3.29860,1
  9.60228,0.24000,      -0.14877,3.29859,1
  9.72713,0.25000,      -0.15731,3.29859,1
  9.85330,0.26000,      -0.16560,3.29859,1
  9.98049,0.27000,      -0.17367,3.29858,1
 10.10866,0.28000,      -0.18141,3.29858,1
 10.23770,0.29000,      -0.18852,3.29858,1
 10.36748,0.30000,      -0.19527,3.29857,1
 10.49793,0.31000,      -0.20186,3.29857,1
 10.62903,0.32000,      -0.20823,3.29856,1
 10.76075,0.33000,      -0.21393,3.29856,1
 10.89313,0.34000,      -0.21930,3.29855,1
 11.02607,0.35000,      -0.22444,3.29855,1
 11.15952,0.36000,      -0.22961,3.29854,1
 11.29359,0.37000,      -0.23412,3.29854,1
 11.42823,0.38000,      -0.23834,3.29853,1
 11.56344,0.39000,      -0.24277,3.29852,1
 11.69921,0.40000,      -0.24686,3.29852,1
 11.83556,0.41000,      -0.25072,3.29851,1
 11.97249,0.42000,      -0.25454,3.29850,1
 12.10997,0.43000,      -0.25795,3.29850,1
 12.24793,0.44000,      -0.26146,3.29849,1
 12.38649,0.45000,      -0.26473,3.29848,1
 12.52557,0.46000,      -0.26788,3.29847,1
 12.66515,0.47000,      -0.27094,3.29846,1
 12.80528,0.48000,      -0.27356,3.29846,1
 12.94584,0.49000,      -0.27623,3.29845,1
 13.08685,0.50000,      -0.27890,3.29844,1
 13.22836,0.51000,      -0.28146,3.29843,1
 13.37026,0.52000,      -0.28400,3.29842,1
 13.51266,0.53000,      -0.28628,3.29841,1
 13.65534,0.54000,      -0.28842,3.29840,1
 13.79849,0.55000,      -0.29028,3.29839,1
 13.94203,0.56000,      -0.29216,3.29838,1
 14.08587,0.57000,      -0.29433,3.29837,1
 14.23003,0.58000,      -0.29634,3.29836,1
 14.37454,0.59000,      -0.29833,3.29835,1
 14.51934,0.60000,      -0.30008,3.29834,1
 14.66448,0.61000,      -0.30191,3.29832,1
 14.80987,0.62000,      -0.30374,3.29831,1
 14.95554,0.63000,      -0.30526,3.29830,1
 15.10136,0.64000,      -0.30680,3.29829,1
 15.24746,0.65000,      -0.30839,3.29828,1
 15.39374,0.66000,      -0.30977,3.29826,1
 15.54033,0.67000,      -0.31110,3.29825,1
 15.68700,0.68000,      -0.31264,3.29824,1
 15.83384,0.69000,      -0.31408,3.29822,1
 15.98087,0.70000,      -0.31541,3.29821,1
 16.12797,0.71000,      -0.31666,3.29819,1
 16.27530,0.72000,      -0.31775,3.29818,1
 16.42270,0.73000,      -0.31898,3.29816,1
 16.57025,0.74000,      -0.32028,3.29815,1
 16.71787,0.75000,      -0.32148,3.29813,1
 16.86556,0.76000,      -0.32247,3.29812,1
 17.01343,0.77000,      -0.32351,3.29810,1
 17.16131,0.78000,      -0.32458,3.29809,1
 17.30923,0.79000,      -0.32562,3.29807,1
 17.45721,0.80000,      -0.32661,3.29806,1
 17.60523,0.81000,      -0.32755,3.29804,1
 17.75315,0.82000,      -0.32841,3.29802,1
 17.90120,0.83000,      -0.32926,3.29800,1
 18.04926,0.84000,      -0.33012,3.29799,1
 18.19730,0.85000,      -0.33095,3.29797,1
 18.34531,0.86000,      -0.33178,3.29795,1
 18.49330,0.87000,      -0.33264,3.29793,1
 18.64125,0.88000,      -0.33316,3.29792,1
 18.78915,0.89000,      -0.33401,3.29790,1
 18.93705,0.90000,      -0.33479,3.29788,1
 19.08492,0.91000,      -0.33552,3.29786,1
 19.23272,0.92000,      -0.33624,3.29784,1
 19.38038,0.93000,      -0.33689,3.29782,1
 19.52798,0.94000,      -0.33762,3.29780,1
 19.67552,0.95000,      -0.33821,3.29778,1
 19.82302,0.96000,      -0.33883,3.29776,1
 19.97030,0.97000,      -0.33924,3.29774,1
 20.11748,0.98000,      -0.33994,3.29772,1
 20.26456,0.99000,      -0.34056,3.29770,1
 20.41154,1.00000,      -0.34111,3.29768,1
 20.55846,1.01000,      -0.34165,3.29766,1
 20.70533,1.02000,      -0.34224,3.29763,1
 20.85208,1.03000,      -0.34270,3.29761,1
 20.99866,1.04000,      -0.34322,3.29759,1
 21.14520,1.05000,      -0.34345,3.29757,1
 21.29161,1.06000,      -0.34380,3.29755,1
 21.43782,1.07000,      -0.34440,3.29752,1
 21.58384,1.08000,      -0.34486,3.29750,1
 21.72975,1.09000,      -0.34540,3.29748,1
 21.87556,1.10000,      -0.34584,3.29745,1
 22.02121,1.11000,      -0.34614,3.29743,1
 22.16677,1.12000,      -0.34642,3.29741,1
 22.31216,1.13000,      -0.34691,3.29738,1
 22.45730,1.14000,      -0.34745,3.29736,1
 22.60239,1.15000,      -0.34773,3.29734,1
 22.74733,1.16000,      -0.34804,3.29731,1
 22.89208,1.17000,      -0.34850,3.29729,1
 23.03672,1.18000,      -0.34894,3.29726,1
 23.18133,1.19000,      -0.34927,3.29724,1
 23.32570,1.20000,      -0.34965,3.29721,1
 23.46989,1.21000,      -0.34996,3.29719,1
 23.61392,1.22000,      -0.35037,3.29716,1
 23.75780,1.23000,      -0.35075,3.29713,1
 23.90152,1.24000,      -0.35116,3.29711,1
 24.04502,1.25000,      -0.35149,3.29708,1
 24.18831,1.26000,      -0.35174,3.29705,1
 24.33143,1.27000,      -0.35205,3.29703,1
 24.47451,1.28000,      -0.35240,3.29700,1
 24.61739,1.29000,      -0.35281,3.29697,1
 24.76010,1.30000,      -0.35312,3.29695,1
 24.90259,1.31000,      -0.35358,3.29692,1
 25.04489,1.32000,      -0.35402,3.29689,1
 25.18707,1.33000,      -0.35422,3.29686,1
 25.32908,1.34000,      -0.35431,3.29684,1
 25.47084,1.35000,      -0.35467,3.29681,1
 25.61243,1.36000,      -0.35505,3.29678,1
 25.75389,1.37000,      -0.35543,3.29675,1
 25.89513,1.38000,      -0.35582,3.29672,1
 26.03618,1.39000,      -0.35607,3.29669,1
 26.17700,1.40000,      -0.35640,3.29666,1
 26.31769,1.41000,      -0.35686,3.29664,1
 26.45825,1.42000,      -0.35732,3.29661,1
 26.59854,1.43000,      -0.35766,3.29658,1
 26.73866,1.44000,      -0.35793,3.29655,1
 26.87864,1.45000,      -0.35818,3.29652,1
 27.01838,1.46000,      -0.35846,3.29649,1
 27.15802,1.47000,      -0.35877,3.29646,1
 27.29736,1.48000,      -0.35912,3.29643,1
 27.43659,1.49000,      -0.35948,3.29640,1
 27.57559,1.50000,      -0.35984,3.29636,1
 27.71438,1.51000,      -0.36017,3.29633,1
 27.85293,1.52000,      -0.36031,3.29630,1
 27.99126,1.53000,      -0.36064,3.29627,1
 28.12944,1.54000,      -0.36111,3.29624,1
 28.26751,1.55000,      -0.36123,3.29621,1
 28.40534,1.56000,      -0.36150,3.29618,1
 28.54295,1.57000,      -0.36189,3.29614,1
 28.68036,1.58000,      -0.36232,3.29611,1
 28.81759,1.59000,      -0.36273,3.29608,1
 28.95459,1.60000,      -0.36272,3.29605,1
 29.09134,1.61000,      -0.36300,3.29602,1
 29.22785,1.62000,      -0.36351,3.29598,1
 29.36421,1.63000,      -0.36387,3.29595,1
 29.50039,1.64000,      -0.36438,3.29592,1
 29.63633,1.65000,      -0.36479,3.29588,1
 29.77207,1.66000,      -0.36483,3.29585,1
 29.90762,1.67000,      -0.36505,3.29582,1
 30.04295,1.68000,      -0.36549,3.29578,1
 30.17805,1.69000,      -0.36574,3.29575,1
 30.31300,1.70000,      -0.36615,3.29572,1
 30.44774,1.71000,      -0.36651,3.29568,1
 30.58229,1.72000,      -0.36660,3.29565,1
 30.71674,1.73000,      -0.36703,3.29561,1
 30.85089,1.74000,      -0.36755,3.29558,1
 30.98489,1.75000,      -0.36780,3.29554,1
 31.11866,1.76000,      -0.36815,3.29551,1
 31.25223,1.77000,      -0.36880,3.29547,1
 31.38567,1.78000,      -0.36887,3.29544,1
 31.51893,1.79000,      -0.36909,3.29540,1
 31.65202,1.80000,      -0.36931,3.29537,1
 31.78495,1.81000,      -0.36985,3.29533,1
 31.91766,1.82000,      -0.37024,3.29530,1
 32.05020,1.83000,      -0.37067,3.29526,1
 32.18254,1.84000,      -0.37108,3.29523,1
 32.31466,1.85000,      -0.37130,3.29519,1
 32.44664,1.86000,      -0.37192,3.29515,1
 32.57841,1.87000,      -0.37238,3.29512,1
 32.71005,1.88000,      -0.37271,3.29508,1
 32.84152,1.89000,      -0.37304,3.29504,1
 32.97282,1.90000,      -0.37340,3.29501,1
 33.10393,1.91000,      -0.37391,3.29497,1
 33.23492,1.92000,      -0.37432,3.29493,1
 33.36566,1.93000,      -0.37462,3.29490,1
 33.49631,1.94000,      -0.37500,3.29486,1
 33.62680,1.95000,      -0.37544,3.29482,1
 33.75713,1.96000,      -0.37587,3.29478,1
 33.88728,1.97000,      -0.37633,3.29475,1
 34.01725,1.98000,      -0.37680,3.29471,1
 34.14697,1.99000,      -0.37731,3.29467,1
 34.27661,2.00000,      -0.37764,3.29463,1
 34.40607,2.01000,      -0.37818,3.29459,1
 34.53538,2.02000,      -0.37869,3.29455,1
 34.66454,2.03000,      -0.37915,3.29452,1
 34.79348,2.04000,      -0.37961,3.29448,1
 34.92231,2.05000,      -0.38005,3.29444,1
 35.05095,2.06000,      -0.38064,3.29440,1
 35.17948,2.07000,      -0.38094,3.29436,1
 35.30787,2.08000,      -0.38135,3.29432,1
 35.43610,2.09000,      -0.38189,3.29428,1
 35.56416,2.10000,      -0.38235,3.29424,1
 35.69203,2.11000,      -0.38278,3.29420,1
 35.81979,2.12000,      -0.38330,3.29416,1
 35.94741,2.13000,      -0.38384,3.29412,1
 36.07480,2.14000,      -0.38440,3.29408,1
 36.20202,2.15000,      -0.38494,3.29404,1
 36.32915,2.16000,      -0.38572,3.29400,1
 36.45610,2.17000,      -0.38629,3.29396,1
 36.58284,2.18000,      -0.38656,3.29392,1
 36.70948,2.19000,      -0.38721,3.29388,1
 36.83598,2.20000,      -0.38793,3.29384,1
 36.96225,2.21000,      -0.38810,3.29380,1
 37.08843,2.22000,      -0.38856,3.29376,1
 37.21449,2.23000,      -0.38902,3.29372,1
 37.34041,2.24000,      -0.38993,3.29368,1
 37.46618,2.25000,      -0.39065,3.29363,1
 37.59179,2.26000,      -0.39096,3.29359,1
 37.71731,2.27000,      -0.39139,3.29355,1
 37.84267,2.28000,      -0.39190,3.29351,1
 37.96785,2.29000,      -0.39265,3.29347,1
 38.09295,2.30000,      -0.39333,3.29343,1
 38.21793,2.31000,      -0.39400,3.29338,1
 38.34277,2.32000,      -0.39459,3.29334,1
 38.46743,2.33000,      -0.39521,3.29330,1
 38.59200,2.34000,      -0.39583,3.29326,1
 38.71651,2.35000,      -0.39600,3.29321,1
 38.84085,2.36000,      -0.39693,3.29317,1
 38.96502,2.37000,      -0.39773,3.29313,1
 39.08912,2.38000,      -0.39835,3.29308,1
 39.21308,2.39000,      -0.39887,3.29304,1
 39.33692,2.40000,      -0.39943,3.29300,1
 39.46057,2.41000,      -0.40016,3.29295,1
 39.58415,2.42000,      -0.40091,3.29291,1
 39.70757,2.43000,      -0.40145,3.29287,1
 39.83092,2.44000,      -0.40206,3.29282,1
 39.95415,2.45000,      -0.40276,3.29278,1
 40.07723,2.46000,      -0.40351,3.29274,1
 40.20021,2.47000,      -0.40413,3.29269,1
 40.32305,2.48000,      -0.40480,3.29265,1
 40.44575,2.49000,      -0.40550,3.29260,1
 40.56839,2.50000,      -0.40620,3.29256,1
 40.69085,2.51000,      -0.40700,3.29251,1
 40.81321,2.52000,      -0.40778,3.29247,1
 40.93543,2.53000,      -0.40810,3.29242,1
 41.05759,2.54000,      -0.40907,3.29238,1
 41.17959,2.55000,      -0.40982,3.29233,1
 41.30148,2.56000,      -0.41057,3.29229,1
 41.42325,2.57000,      -0.41126,3.29224,1
 41.54492,2.58000,      -0.41201,3.29220,1
 41.66648,2.59000,      -0.41287,3.29215,1
 41.78789,2.60000,      -0.41354,3.29211,1
 41.90926,2.61000,      -0.41448,3.29206,1
 42.03051,2.62000,      -0.41523,3.29202,1
 42.15162,2.63000,      -0.41584,3.29197,1
 42.27256,2.64000,      -0.41670,3.29192,1
 42.39338,2.65000,      -0.41732,3.29188,1
 42.51418,2.66000,      -0.41812,3.29183,1
 42.63480,2.67000,      -0.41895,3.29179,1
 42.75536,2.68000,      -0.41968,3.29174,1
 42.87587,2.69000,      -0.42043,3.29169,1
 42.99618,2.70000,      -0.42128,3.29165,1
 43.11643,2.71000,      -0.42201,3.29160,1
 43.23654,2.72000,      -0.42278,3.29155,1
 43.35656,2.73000,      -0.42356,3.29150,1
 43.47652,2.74000,      -0.42431,3.29146,1
 43.59634,2.75000,      -0.42509,3.29141,1
 43.71598,2.76000,      -0.42597,3.29136,1
 43.83554,2.77000,      -0.42688,3.29131,1
 43.95507,2.78000,      -0.42747,3.29127,1
 44.07448,2.79000,      -0.42830,3.29122,1
 44.19387,2.80000,      -0.42937,3.29117,1
 44.31313,2.81000,      -0.43030,3.29112,1
 44.43225,2.82000,      -0.43110,3.29107,1
 44.55125,2.83000,      -0.43199,3.29103,1
 44.67025,2.84000,      -0.43290,3.29098,1
 44.78911,2.85000,      -0.43362,3.29093,1
 44.90782,2.86000,      -0.43450,3.29088,1
 45.02649,2.87000,      -0.43538,3.29083,1
 45.14505,2.88000,      -0.43619,3.29078,1
 45.26344,2.89000,      -0.43707,3.29073,1
 45.38177,2.90000,      -0.43809,3.29068,1
 45.50008,2.91000,      -0.43899,3.29064,1
 45.61825,2.92000,      -0.43996,3.29059,1
 45.73631,2.93000,      -0.44089,3.29054,1
 45.85428,2.94000,      -0.44172,3.29049,1
 45.97211,2.95000,      -0.44252,3.29044,1
 46.08989,2.96000,      -0.44356,3.29039,1
 46.20764,2.97000,      -0.44450,3.29034,1
 46.32526,2.98000,      -0.44514,3.29029,1
 46.44274,2.99000,      -0.44613,3.29024,1
 46.56015,3.00000,      -0.44720,3.29019,1
 46.67741,3.01000,      -0.44814,3.29014,1
 46.79466,3.02000,      -0.44912,3.29009,1
 46.91184,3.03000,      -0.45006,3.29004,1
 47.02892,3.04000,      -0.45092,3.28999,1
 47.14593,3.05000,      -0.45188,3.28994,1
 47.26284,3.06000,      -0.45289,3.28988,1
 47.37961,3.07000,      -0.45393,3.28983,1
 47.49630,3.08000,      -0.45490,3.28978,1
 47.61297,3.09000,      -0.45583,3.28973,1
 47.72951,3.10000,      -0.45687,3.28968,1
 47.84595,3.11000,      -0.45789,3.28963,1
 47.96223,3.12000,      -0.45869,3.28958,1
 48.07852,3.13000,      -0.45971,3.28953,1
 48.19469,3.14000,      -0.46059,3.28947,1
 48.31080,3.15000,      -0.46158,3.28942,1
 48.42690,3.16000,      -0.46254,3.28937,1
 48.54285,3.17000,      -0.46358,3.28932,1
 48.65869,3.18000,      -0.46470,3.28927,1
 48.77446,3.19000,      -0.46577,3.28921,1
 48.89013,3.20000,      -0.46681,3.28916,1
 49.00574,3.21000,      -0.46780,3.28911,1
 49.12121,3.22000,      -0.46871,3.28906,1
 49.23659,3.23000,      -0.46986,3.28900,1
 49.35192,3.24000,      -0.47079,3.28895,1
 49.46718,3.25000,      -0.47183,3.28890,1
 49.58241,3.26000,      -0.47287,3.28885,1
 49.69757,3.27000,      -0.47389,3.28879,1
 49.81262,3.28000,      -0.47488,3.28874,1
 49.92749,3.29000,      -0.47592,3.28869,1
 50.04234,3.30000,      -0.47699,3.28863,1
 50.15715,3.31000,      -0.47800,3.28858,1
 50.27187,3.32000,      -0.47899,3.28853,1
 50.38652,3.33000,      -0.48006,3.28847,1
 50.50108,3.34000,      -0.48126,3.28842,1
 50.61552,3.35000,      -0.48199,3.28836,1
 50.72985,3.36000,      -0.48303,3.28831,1
 50.84415,3.37000,      -0.48436,3.28826,1
 50.95839,3.38000,      -0.48551,3.28820,1
 51.07261,3.39000,      -0.48665,3.28815,1
 51.18674,3.40000,      -0.48778,3.28809,1
 51.30080,3.41000,      -0.48869,3.28804,1
 51.41480,3.42000,      -0.48973,3.28798,1
 51.52877,3.43000,      -0.49082,3.28793,1
 51.64259,3.44000,      -0.49181,3.28787,1
 51.75633,3.45000,      -0.49291,3.28782,1
 51.87003,3.46000,      -0.49392,3.28776,1
 51.98364,3.47000,      -0.49488,3.28771,1
 52.09730,3.48000,      -0.49619,3.28765,1
 52.21092,3.49000,      -0.49745,3.28760,1
 52.32444,3.50000,      -0.49857,3.28754,1
 52.43792,3.51000,      -0.49966,3.28749,1
 52.55130,3.52000,      -0.50070,3.28743,1
 52.66462,3.53000,      -0.50180,3.28737,1
 52.77789,3.54000,      -0.50287,3.28732,1
 52.89108,3.55000,      -0.50380,3.28726,1
 53.00426,3.56000,      -0.50495,3.28721,1
 53.11739,3.57000,      -0.50605,3.28715,1
 53.23044,3.58000,      -0.50709,3.28709,1
 53.34338,3.59000,      -0.50829,3.28704,1
 53.45621,3.60000,      -0.50955,3.28698,1
 53.56900,3.61000,      -0.51075,3.28692,1
 53.68169,3.62000,      -0.51192,3.28687,1
 53.79430,3.63000,      -0.51307,3.28681,1
 53.90692,3.64000,      -0.51417,3.28675,1
 54.01949,3.65000,      -0.51526,3.28670,1
 54.13192,3.66000,      -0.51636,3.28664,1
 54.24429,3.67000,      -0.51751,3.28658,1
 54.35654,3.68000,      -0.51850,3.28652,1
 54.46870,3.69000,      -0.51941,3.28647,1
 54.58084,3.70000,      -0.52056,3.28641,1
 54.69290,3.71000,      -0.52160,3.28635,1
 54.80489,3.72000,      -0.52277,3.28629,1
 54.91684,3.73000,      -0.52395,3.28624,1
 55.02874,3.74000,      -0.52510,3.28618,1
 55.14054,3.75000,      -0.52627,3.28612,1
 55.25225,3.76000,      -0.52745,3.28606,1
 55.36387,3.77000,      -0.52849,3.28600,1
 55.47533,3.78000,      -0.52961,3.28594,1
 55.58682,3.79000,      -0.53071,3.28589,1
 55.69826,3.80000,      -0.53178,3.28583,1
 55.80966,3.81000,      -0.53290,3.28577,1
 55.92097,3.82000,      -0.53400,3.28571,1
 56.03221,3.83000,      -0.53509,3.28565,1
 56.14334,3.84000,      -0.53622,3.28559,1
 56.25441,3.85000,      -0.53731,3.28553,1
 56.36543,3.86000,      -0.53844,3.28547,1
 56.47638,3.87000,      -0.53935,3.28541,1
 56.58733,3.88000,      -0.54052,3.28536,1
 56.69826,3.89000,      -0.54167,3.28530,1
 56.80910,3.90000,      -0.54280,3.28524,1
 56.91984,3.91000,      -0.54387,3.28518,1
 57.03054,3.92000,      -0.54502,3.28512,1
 57.14125,3.93000,      -0.54611,3.28506,1
 57.25190,3.94000,      -0.54726,3.28500,1
 57.36256,3.95000,      -0.54825,3.28494,1
 57.47318,3.96000,      -0.54943,3.28488,1
 57.58379,3.97000,      -0.55074,3.28482,1
 57.69438,3.98000,      -0.55178,3.28476,1
 57.80495,3.99000,      -0.55283,3.28470,1
 57.91546,4.00000,      -0.55395,3.28463,1
 58.02600,4.01000,      -0.55510,3.28457,1
 58.13651,4.02000,      -0.55628,3.28451,1
 58.24702,4.03000,      -0.55743,3.28445,1
 58.35746,4.04000,      -0.55858,3.28439,1
 58.46790,4.05000,      -0.55967,3.28433,1
 58.57838,4.06000,      -0.56093,3.28427,1
 58.68880,4.07000,      -0.56208,3.28421,1
 58.79923,4.08000,      -0.56331,3.28414,1
 58.90959,4.09000,      -0.56462,3.28408,1
 59.01995,4.10000,      -0.56585,3.28402,1
 59.13025,4.11000,      -0.56703,3.28396,1
 59.24056,4.12000,      -0.56823,3.28390,1
 59.35082,4.13000,      -0.56938,3.28383,1
 59.46105,4.14000,      -0.57045,3.28377,1
 59.57123,4.15000,      -0.57168,3.28371,1
 59.68139,4.16000,      -0.57296,3.28365,1
 59.79157,4.17000,      -0.57433,3.28358,1
 59.90169,4.18000,      -0.57532,3.28352,1
 60.01169,4.19000,      -0.57655,3.28346,1
 60.12166,4.20000,      -0.57781,3.28340,1
 60.23161,4.21000,      -0.57872,3.28333,1
 60.34144,4.22000,      -0.58029,3.28327,1
 60.45131,4.23000,      -0.58134,3.28321,1
 60.56113,4.24000,      -0.58257,3.28314,1
 60.67093,4.25000,      -0.58383,3.28308,1
 60.78064,4.26000,      -0.58503,3.28302,1
 60.89025,4.27000,      -0.58605,3.28295,1
 60.99982,4.28000,      -0.58710,3.28289,1
 61.10930,4.29000,      -0.58843,3.28282,1
 61.21874,4.30000,      -0.58956,3.28276,1
 61.32818,4.31000,      -0.59029,3.28270,1
 61.43757,4.32000,      -0.59178,3.28263,1
 61.54689,4.33000,      -0.59296,3.28257,1
 61.65611,4.34000,      -0.59422,3.28250,1
 61.76526,4.35000,      -0.59540,3.28244,1
 61.87426,4.36000,      -0.59649,3.28237,1
 61.98325,4.37000,      -0.59767,3.28231,1
 62.09218,4.38000,      -0.59882,3.28224,1
 62.20111,4.39000,      -0.59992,3.28218,1
 62.30993,4.40000,      -0.60102,3.28211,1
 62.41871,4.41000,      -0.60212,3.28205,1
 62.52749,4.42000,      -0.60322,3.28198,1
 62.63620,4.43000,      -0.60429,3.28192,1
 62.74480,4.44000,      -0.60537,3.28185,1
 62.85336,4.45000,      -0.60649,3.28179,1
 62.96189,4.46000,      -0.60764,3.28172,1
 63.07031,4.47000,      -0.60888,3.28166,1
 63.17871,4.48000,      -0.60979,3.28159,1
 63.28707,4.49000,      -0.61081,3.28153,1
 63.39534,4.50000,      -0.61188,3.28146,1
 63.50351,4.51000,      -0.61306,3.28140,1
 63.61166,4.52000,      -0.61419,3.28133,1
 63.71982,4.53000,      -0.61537,3.28126,1
 63.82789,4.54000,      -0.61633,3.28120,1
 63.93590,4.55000,      -0.61741,3.28113,1
 64.04392,4.56000,      -0.61864,3.28106,1
 64.15189,4.57000,      -0.61966,3.28100,1
 64.25974,4.58000,      -0.62071,3.28093,1
 64.36761,4.59000,      -0.62170,3.28086,1
 64.47541,4.60000,      -0.62283,3.28080,1
 64.58316,4.61000,      -0.62382,3.28073,1
 64.69085,4.62000,      -0.62482,3.28066,1
 64.79849,4.63000,      -0.62594,3.28060,1
 64.90603,4.64000,      -0.62712,3.28053,1
 65.01356,4.65000,      -0.62830,3.28046,1
 65.12100,4.66000,      -0.62917,3.28040,1
 65.22848,4.67000,      -0.63037,3.28033,1
 65.33585,4.68000,      -0.63145,3.28026,1
 65.44328,4.69000,      -0.63268,3.28019,1
 65.55064,4.70000,      -0.63357,3.28013,1
 65.65792,4.71000,      -0.63469,3.28006,1
 65.76520,4.72000,      -0.63577,3.27999,1
 65.87233,4.73000,      -0.63674,3.27992,1
 65.97948,4.74000,      -0.63776,3.27985,1
 66.08664,4.75000,      -0.63875,3.27979,1
 66.19375,4.76000,      -0.63985,3.27972,1
 66.30077,4.77000,      -0.64109,3.27965,1
 66.40777,4.78000,      -0.64224,3.27958,1
 66.51477,4.79000,      -0.64329,3.27951,1
 66.62166,4.80000,      -0.64415,3.27944,1
 66.72857,4.81000,      -0.64512,3.27937,1
 66.83541,4.82000,      -0.64633,3.27931,1
 66.94220,4.83000,      -0.64740,3.27924,1
 67.04905,4.84000,      -0.64832,3.27917,1
 67.15584,4.85000,      -0.64921,3.27910,1
 67.26259,4.86000,      -0.65031,3.27903,1
 67.36926,4.87000,      -0.65168,3.27896,1
 67.47593,4.88000,      -0.65243,3.27889,1
 67.58248,4.89000,      -0.65338,3.27882,1
 67.68898,4.90000,      -0.65469,3.27875,1
 67.79552,4.91000,      -0.65569,3.27868,1
 67.90198,4.92000,      -0.65665,3.27861,1
 68.00836,4.93000,      -0.65778,3.27854,1
 68.11474,4.94000,      -0.65881,3.27847,1
 68.22107,4.95000,      -0.65983,3.27840,1
 68.32733,4.96000,      -0.66096,3.27833,1
 68.43357,4.97000,      -0.66182,3.27826,1
 68.53985,4.98000,      -0.66282,3.27819,1
 68.64598,4.99000,      -0.66397,3.27812,1
 68.75210,5.00000,      -0.66499,3.27805,1
 68.85821,5.01000,      -0.66610,3.27798,1
 68.96426,5.02000,      -0.66704,3.27791,1
 69.07031,5.03000,      -0.66801,3.27784,1
 69.17625,5.04000,      -0.66903,3.27777,1
 69.28223,5.05000,      -0.67000,3.27770,1
 69.38811,5.06000,      -0.67097,3.27762,1
 69.49403,5.07000,      -0.67205,3.27755,1
 69.59987,5.08000,      -0.67304,3.27748,1
 69.70572,5.09000,      -0.67401,3.27741,1
 69.81154,5.10000,      -0.67504,3.27734,1
 69.91733,5.11000,      -0.67606,3.27727,1
 70.02316,5.12000,      -0.67714,3.27720,1
 70.12895,5.13000,      -0.67819,3.27712,1
 70.23472,5.14000,      -0.67910,3.27705,1
 70.34046,5.15000,      -0.67976,3.27698,1
 70.44618,5.16000,      -0.68105,3.27691,1
 70.55190,5.17000,      -0.68207,3.27684,1
 70.65756,5.18000,      -0.68291,3.27676,1
 70.76321,5.19000,      -0.68385,3.27669,1
 70.86885,5.20000,      -0.68482,3.27662,1
 70.97444,5.21000,      -0.68569,3.27655,1
 71.08008,5.22000,      -0.68655,3.27647,1
 71.18567,5.23000,      -0.68755,3.27640,1
 71.29130,5.24000,      -0.68863,3.27633,1
 71.39692,5.25000,      -0.68968,3.27625,1
 71.50251,5.26000,      -0.69073,3.27618,1
 71.60808,5.27000,      -0.69173,3.27611,1
 71.71362,5.28000,      -0.69275,3.27603,1
 71.81913,5.29000,      -0.69343,3.27596,1
 71.92464,5.30000,      -0.69432,3.27589,1
 72.03010,5.31000,      -0.69545,3.27581,1
 72.13554,5.32000,      -0.69645,3.27574,1
 72.24095,5.33000,      -0.69748,3.27567,1
 72.34634,5.34000,      -0.69842,3.27559,1
 72.45177,5.35000,      -0.69939,3.27552,1
 72.55707,5.36000,      -0.70031,3.27544,1
 72.66241,5.37000,      -0.70126,3.27537,1
 72.76764,5.38000,      -0.70228,3.27529,1
 72.87297,5.39000,      -0.70323,3.27522,1
 72.97831,5.40000,      -0.70425,3.27514,1
 73.08361,5.41000,      -0.70499,3.27507,1
 73.18882,5.42000,      -0.70607,3.27499,1
 73.29400,5.43000,      -0.70699,3.27492,1
 73.39918,5.44000,      -0.70801,3.27484,1
 73.50436,5.45000,      -0.70901,3.27477,1
 73.60948,5.46000,      -0.70972,3.27469,1
 73.71454,5.47000,      -0.71056,3.27462,1
 73.81961,5.48000,      -0.71148,3.27454,1
 73.92471,5.49000,      -0.71261,3.27447,1
 74.02972,5.50000,      -0.71363,3.27439,1
 74.13470,5.51000,      -0.71450,3.27432,1
 74.23972,5.52000,      -0.71542,3.27424,1
 74.34466,5.53000,      -0.71613,3.27416,1
 74.44961,5.54000,      -0.71700,3.27409,1
 74.55451,5.55000,      -0.71784,3.27401,1
 74.65938,5.56000,      -0.71876,3.27394,1
 74.76426,5.57000,      -0.71973,3.27386,1
 74.86910,5.58000,      -0.72073,3.27378,1
 74.97387,5.59000,      -0.72130,3.27371,1
 75.07859,5.60000,      -0.72214,3.27363,1
 75.18328,5.61000,      -0.72299,3.27355,1
 75.28800,5.62000,      -0.72391,3.27348,1
 75.39262,5.63000,      -0.72469,3.27340,1
 75.49720,5.64000,      -0.72553,3.27332,1
 75.60172,5.65000,      -0.72646,3.27325,1
 75.70623,5.66000,      -0.72730,3.27317,1
 75.81074,5.67000,      -0.72806,3.27309,1
 75.91520,5.68000,      -0.72890,3.27301,1
 76.01957,5.69000,      -0.72969,3.27294,1
 76.12402,5.70000,      -0.73050,3.27286,1
 76.22843,5.71000,      -0.73129,3.27278,1
 76.33275,5.72000,      -0.73205,3.27270,1
 76.43706,5.73000,      -0.73281,3.27263,1
 76.54133,5.74000,      -0.73347,3.27255,1
 76.64562,5.75000,      -0.73415,3.27247,1
 76.74984,5.76000,      -0.73502,3.27239,1
 76.85405,5.77000,      -0.73589,3.27231,1
 76.95828,5.78000,      -0.73630,3.27224,1
 77.06247,5.79000,      -0.73733,3.27216,1
 77.16664,5.80000,      -0.73804,3.27208,1
 77.27080,5.81000,      -0.73878,3.27200,1
 77.37490,5.82000,      -0.73951,3.27192,1
 77.47902,5.83000,      -0.74017,3.27184,1
 77.58316,5.84000,      -0.74093,3.27176,1
 77.68723,5.85000,      -0.74161,3.27169,1
 77.79126,5.86000,      -0.74222,3.27161,1
 77.89525,5.87000,      -0.74290,3.27153,1
 77.99926,5.88000,      -0.74364,3.27145,1
 78.10326,5.89000,      -0.74442,3.27137,1
 78.20721,5.90000,      -0.74511,3.27129,1
 78.31118,5.91000,      -0.74571,3.27121,1
 78.41508,5.92000,      -0.74634,3.27113,1
 78.51893,5.93000,      -0.74697,3.27105,1
 78.62285,5.94000,      -0.74765,3.27097,1
 78.72669,5.95000,      -0.74831,3.27089,1
 78.83052,5.96000,      -0.74862,3.27081,1
 78.93433,5.97000,      -0.74957,3.27073,1
 79.03815,5.98000,      -0.75034,3.27065,1
 79.14192,5.99000,      -0.75097,3.27057,1
 79.24570,6.00000,      -0.75157,3.27049,1
 79.34946,6.01000,      -0.75223,3.27041,1
 79.45318,6.02000,      -0.75275,3.27033,1
 79.55685,6.03000,      -0.75343,3.27025,1
 79.66054,6.04000,      -0.75391,3.27017,1
 79.76421,6.05000,      -0.75446,3.27009,1
 79.86790,6.06000,      -0.75498,3.27000,1
 79.97161,6.07000,      -0.75561,3.26992,1
 80.07526,6.08000,      -0.75624,3.26984,1
 80.17892,6.09000,      -0.75690,3.26976,1
 80.28252,6.10000,      -0.75761,3.26968,1
 80.38613,6.11000,      -0.75816,3.26960,1
 80.48962,6.12000,      -0.75882,3.26952,1
 80.59323,6.13000,      -0.75903,3.26943,1
 80.69677,6.14000,      -0.75947,3.26935,1
 80.80031,6.15000,      -0.76016,3.26927,1
 80.90389,6.16000,      -0.76063,3.26919,1
 81.00744,6.17000,      -0.76129,3.26911,1
 81.11095,6.18000,      -0.76192,3.26902,1
 81.21443,6.19000,      -0.76242,3.26894,1
 81.31787,6.20000,      -0.76286,3.26886,1
 81.42128,6.21000,      -0.76331,3.26878,1
 81.52467,6.22000,      -0.76362,3.26869,1
 81.62805,6.23000,      -0.76401,3.26861,1
 81.73143,6.24000,      -0.76449,3.26853,1
 81.83475,6.25000,      -0.76496,3.26845,1
 81.93810,6.26000,      -0.76546,3.26836,1
 82.04139,6.27000,      -0.76590,3.26828,1
 82.14466,6.28000,      -0.76632,3.26820,1
 82.24795,6.29000,      -0.76677,3.26811,1
 82.35116,6.30000,      -0.76721,3.26803,1
 82.45434,6.31000,      -0.76758,3.26795,1
 82.55761,6.32000,      -0.76800,3.26786,1
 82.66084,6.33000,      -0.76839,3.26778,1
 82.76398,6.34000,      -0.76876,3.26769,1
 82.86711,6.35000,      -0.76913,3.26761,1
 82.97021,6.36000,      -0.76925,3.26753,1
 83.07338,6.37000,      -0.76970,3.26744,1
 83.17643,6.38000,      -0.76996,3.26736,1
 83.27948,6.39000,      -0.77025,3.26727,1
 83.38254,6.40000,      -0.77075,3.26719,1
 83.48556,6.41000,      -0.77109,3.26711,1
 83.58864,6.42000,      -0.77159,3.26702,1
 83.69169,6.43000,      -0.77198,3.26694,1
 83.79472,6.44000,      -0.77240,3.26685,1
 83.89777,6.45000,      -0.77277,3.26677,1
 84.00075,6.46000,      -0.77321,3.26668,1
 84.10375,6.47000,      -0.77355,3.26660,1
 84.20677,6.48000,      -0.77355,3.26651,1
 84.30969,6.49000,      -0.77381,3.26643,1
 84.41270,6.50000,      -0.77410,3.26634,1
 84.51569,6.51000,      -0.77446,3.26626,1
 84.61866,6.52000,      -0.77483,3.26617,1
 84.72159,6.53000,      -0.77509,3.26608,1
 84.82457,6.54000,      -0.77543,3.26600,1
 84.92751,6.55000,      -0.77585,3.26591,1
 85.03046,6.56000,      -0.77609,3.26583,1
 85.13331,6.57000,      -0.77619,3.26574,1
 85.23620,6.58000,      -0.77634,3.26565,1
 85.33907,6.59000,      -0.77666,3.26557,1
 85.44193,6.60000,      -0.77687,3.26548,1
 85.54482,6.61000,      -0.77705,3.26540,1
 85.64769,6.62000,      -0.77763,3.26531,1
 85.75052,6.63000,      -0.77784,3.26522,1
 85.85329,6.64000,      -0.77802,3.26513,1
 85.95605,6.65000,      -0.77820,3.26505,1
 86.05879,6.66000,      -0.77846,3.26496,1
 86.16157,6.67000,      -0.77864,3.26487,1
 86.26428,6.68000,      -0.77880,3.26479,1
 86.36703,6.69000,      -0.77890,3.26470,1
 86.46969,6.70000,      -0.77900,3.26461,1
 86.57236,6.71000,      -0.77916,3.26452,1
 86.67503,6.72000,      -0.77947,3.26444,1
 86.77774,6.73000,      -0.77965,3.26435,1
 86.88041,6.74000,      -0.77975,3.26426,1
 86.98305,6.75000,      -0.77983,3.26417,1
 87.08566,6.76000,      -0.78009,3.26409,1
 87.18833,6.77000,      -0.78019,3.26400,1
 87.29098,6.78000,      -0.78027,3.26391,1
 87.39359,6.79000,      -0.78045,3.26382,1
 87.49621,6.80000,      -0.78055,3.26373,1
 87.59880,6.81000,      -0.78060,3.26364,1
 87.70139,6.82000,      -0.78073,3.26356,1
 87.80392,6.83000,      -0.78083,3.26347,1
 87.90646,6.84000,      -0.78094,3.26338,1
 88.00903,6.85000,      -0.78104,3.26329,1
 88.11159,6.86000,      -0.78114,3.26320,1
 88.21411,6.87000,      -0.78114,3.26311,1
 88.31662,6.88000,      -0.78124,3.26302,1
 88.41910,6.89000,      -0.78121,3.26293,1
 88.52162,6.90000,      -0.78123,3.26284,1
 88.62415,6.91000,      -0.78123,3.26275,1
 88.72666,6.92000,      -0.78130,3.26266,1
 88.82913,6.93000,      -0.78135,3.26257,1
 88.93154,6.94000,      -0.78132,3.26248,1
 89.03400,6.95000,      -0.78140,3.26240,1
 89.13646,6.96000,      -0.78145,3.26231,1
 89.23890,6.97000,      -0.78144,3.26221,1
 89.34131,6.98000,      -0.78155,3.26212,1
 89.44375,6.99000,      -0.78160,3.26203,1
 89.54613,7.00000,      -0.78157,3.26194,1
 89.64846,7.01000,      -0.78162,3.26185,1
 89.75077,7.02000,      -0.78164,3.26176,1
 89.85315,7.03000,      -0.78161,3.26167,1
 89.95552,7.04000,      -0.78155,3.26158,1
 90.05789,7.05000,      -0.78155,3.26149,1
 90.16016,7.06000,      -0.78149,3.26140,1
 90.26251,7.07000,      -0.78141,3.26131,1
 90.36487,7.08000,      -0.78130,3.26122,1
 90.46716,7.09000,      -0.78124,3.26113,1
 90.56944,7.10000,      -0.78129,3.26103,1
 90.67172,7.11000,      -0.78134,3.26094,1
 90.77393,7.12000,      -0.78139,3.26085,1
 90.87618,7.13000,      -0.78133,3.26076,1
 90.97841,7.14000,      -0.78125,3.26067,1
 91.08067,7.15000,      -0.78111,3.26058,1
 91.18282,7.16000,      -0.78095,3.26048,1
 91.28502,7.17000,      -0.78065,3.26039,1
 91.38716,7.18000,      -0.78054,3.26030,1
 91.48931,7.19000,      -0.78057,3.26021,1
 91.59149,7.20000,      -0.78048,3.26012,1
 91.69366,7.21000,      -0.78032,3.26002,1
 91.79585,7.22000,      -0.78037,3.25993,1
 91.89798,7.23000,      -0.78013,3.25984,1
 92.00013,7.24000,      -0.78004,3.25975,1
 92.10228,7.25000,      -0.77980,3.25965,1
 92.20441,7.26000,      -0.77972,3.25956,1
 92.30661,7.27000,      -0.77953,3.25947,1
 92.40874,7.28000,      -0.77929,3.25937,1
 92.51085,7.29000,      -0.77907,3.25928,1
 92.61297,7.30000,      -0.77893,3.25919,1
 92.71511,7.31000,      -0.77901,3.25909,1
 92.81726,7.32000,      -0.77874,3.25900,1
 92.91939,7.33000,      -0.77842,3.25891,1
 93.02152,7.34000,      -0.77836,3.25881,1
 93.12369,7.35000,      -0.77820,3.25872,1
 93.22584,7.36000,      -0.77801,3.25862,1
 93.32798,7.37000,      -0.77787,3.25853,1
 93.43015,7.38000,      -0.77750,3.25844,1
 93.53228,7.39000,      -0.77755,3.25834,1
 93.63438,7.40000,      -0.77720,3.25825,1
 93.73654,7.41000,      -0.77693,3.25815,1
 93.83866,7.42000,      -0.77674,3.25806,1
 93.94077,7.43000,      -0.77642,3.25796,1
 94.04290,7.44000,      -0.77620,3.25787,1
 94.14498,7.45000,      -0.77599,3.25777,1
 94.24710,7.46000,      -0.77577,3.25768,1
 94.34915,7.47000,      -0.77550,3.25758,1
 94.45123,7.48000,      -0.77521,3.25749,1
 94.55326,7.49000,      -0.77496,3.25739,1
 94.65536,7.50000,      -0.77472,3.25730,1
 94.75741,7.51000,      -0.77437,3.25720,1
 94.85941,7.52000,      -0.77413,3.25711,1
 94.96143,7.53000,      -0.77391,3.25701,1
 95.06348,7.54000,      -0.77394,3.25691,1
 95.16549,7.55000,      -0.77335,3.25682,1
 95.26749,7.56000,      -0.77297,3.25672,1
 95.36946,7.57000,      -0.77268,3.25663,1
 95.47138,7.58000,      -0.77233,3.25653,1
 95.57336,7.59000,      -0.77198,3.25643,1
 95.67525,7.60000,      -0.77157,3.25634,1
 95.77723,7.61000,      -0.77120,3.25624,1
 95.87920,7.62000,      -0.77088,3.25614,1
 95.98113,7.63000,      -0.77047,3.25605,1
 96.08300,7.64000,      -0.77015,3.25595,1
 96.18490,7.65000,      -0.77002,3.25585,1
 96.28674,7.66000,      -0.76945,3.25576,1
 96.38859,7.67000,      -0.76908,3.25566,1
 96.49039,7.68000,      -0.76859,3.25556,1
 96.59223,7.69000,      -0.76830,3.25546,1
 96.69402,7.70000,      -0.76782,3.25537,1
 96.79582,7.71000,      -0.76733,3.25527,1
 96.89762,7.72000,      -0.76688,3.25517,1
 96.99934,7.73000,      -0.76642,3.25507,1
 97.10110,7.74000,      -0.76594,3.25498,1
 97.20279,7.75000,      -0.76559,3.25488,1
 97.30448,7.76000,      -0.76537,3.25478,1
 97.40611,7.77000,      -0.76446,3.25468,1
 97.50779,7.78000,      -0.76396,3.25458,1
 97.60946,7.79000,      -0.76334,3.25449,1
 97.71115,7.80000,      -0.76278,3.25439,1
 97.81279,7.81000,      -0.76253,3.25429,1
 97.91438,7.82000,      -0.76213,3.25419,1
 98.01598,7.83000,      -0.76168,3.25409,1
 98.11752,7.84000,      -0.76087,3.25399,1
 98.21908,7.85000,      -0.76026,3.25390,1
 98.32070,7.86000,      -0.75991,3.25380,1
 98.42234,7.87000,      -0.75948,3.25370,1
 98.52395,7.88000,      -0.75892,3.25360,1
 98.62551,7.89000,      -0.75830,3.25350,1
 98.72705,7.90000,      -0.75782,3.25340,1
 98.82854,7.91000,      -0.75739,3.25330,1
 98.93003,7.92000,      -0.75722,3.25320,1
 99.03159,7.93000,      -0.75682,3.25310,1
 99.13308,7.94000,      -0.75634,3.25300,1
 99.23459,7.95000,      -0.75594,3.25290,1
 99.33603,7.96000,      -0.75577,3.25280,1
 99.43759,7.97000,      -0.75516,3.25270,1
 99.53911,7.98000,      -0.75491,3.25260,1
 99.64062,7.99000,      -0.75459,3.25250,1
 99.74207,8.00000,      -0.75422,3.25240,1
 99.84354,8.01000,      -0.75379,3.25230,1
 99.94498,8.02000,      -0.75336,3.25220,1
100.04649,8.03000,      -0.75287,3.25210,1
100.14798,8.04000,      -0.75239,3.25200,1
100.24952,8.05000,      -0.75178,3.25190,1
100.35102,8.06000,      -0.75121,3.25180,1
100.45246,8.07000,      -0.75068,3.25170,1
100.55397,8.08000,      -0.75009,3.25160,1
100.65539,8.09000,      -0.74939,3.25150,1
100.75685,8.10000,      -0.74851,3.25139,1
100.85833,8.11000,      -0.74781,3.25129,1
100.95980,8.12000,      -0.74701,3.25119,1
101.06123,8.13000,      -0.74620,3.25109,1
101.16266,8.14000,      -0.74551,3.25099,1
101.26407,8.15000,      -0.74444,3.25089,1
101.36554,8.16000,      -0.74371,3.25078,1
101.46695,8.17000,      -0.74294,3.25068,1
101.56839,8.18000,      -0.74205,3.25058,1
101.66980,8.19000,      -0.74138,3.25048,1
101.77121,8.20000,      -0.74074,3.25038,1
101.87259,8.21000,      -0.73980,3.25027,1
101.97397,8.22000,      -0.73897,3.25017,1
102.07529,8.23000,      -0.73814,3.25007,1
102.17670,8.24000,      -0.73729,3.24997,1
102.27798,8.25000,      -0.73654,3.24986,1
102.37929,8.26000,      -0.73581,3.24976,1
102.48059,8.27000,      -0.73517,3.24966,1
102.58182,8.28000,      -0.73420,3.24955,1
102.68313,8.29000,      -0.73324,3.24945,1
102.78443,8.30000,      -0.73241,3.24935,1
102.88570,8.31000,      -0.73193,3.24924,1
102.98695,8.32000,      -0.73126,3.24914,1
103.08825,8.33000,      -0.73035,3.24904,1
103.18952,8.34000,      -0.72949,3.24893,1
103.29079,8.35000,      -0.72860,3.24883,1
103.39198,8.36000,      -0.72777,3.24873,1
103.49320,8.37000,      -0.72702,3.24862,1
103.59434,8.38000,      -0.72614,3.24852,1
103.69549,8.39000,      -0.72536,3.24841,1
103.79664,8.40000,      -0.72456,3.24831,1
103.89779,8.41000,      -0.72378,3.24821,1
103.99895,8.42000,      -0.72300,3.24810,1
104.10007,8.43000,      -0.72225,3.24800,1
104.20118,8.44000,      -0.72142,3.24789,1
104.30228,8.45000,      -0.72054,3.24779,1
104.40339,8.46000,      -0.71976,3.24768,1
104.50452,8.47000,      -0.71893,3.24758,1
104.60562,8.48000,      -0.71818,3.24747,1
104.70670,8.49000,      -0.71737,3.24737,1
104.80779,8.50000,      -0.71654,3.24726,1
104.90887,8.51000,      -0.71558,3.24716,1
105.00990,8.52000,      -0.71493,3.24705,1
105.11093,8.53000,      -0.71413,3.24695,1
105.21198,8.54000,      -0.71329,3.24684,1
105.31300,8.55000,      -0.71244,3.24674,1
105.41402,8.56000,      -0.71158,3.24663,1
105.51503,8.57000,      -0.71075,3.24653,1
105.61603,8.58000,      -0.70986,3.24642,1
105.71708,8.59000,      -0.70906,3.24631,1
105.81810,8.60000,      -0.70823,3.24621,1
105.91916,8.61000,      -0.70739,3.24610,1
106.02008,8.62000,      -0.70656,3.24600,1
106.12113,8.63000,      -0.70573,3.24589,1
106.22215,8.64000,      -0.70485,3.24578,1
106.32316,8.65000,      -0.70396,3.24568,1
106.42420,8.66000,      -0.70310,3.24557,1
106.52520,8.67000,      -0.70224,3.24546,1
106.62625,8.68000,      -0.70122,3.24536,1
106.72721,8.69000,      -0.70029,3.24525,1
106.82821,8.70000,      -0.69969,3.24514,1
106.92918,8.71000,      -0.69889,3.24503,1
107.03016,8.72000,      -0.69800,3.24493,1
107.13116,8.73000,      -0.69701,3.24482,1
107.23215,8.74000,      -0.69618,3.24471,1
107.33316,8.75000,      -0.69537,3.24460,1
107.43420,8.76000,      -0.69465,3.24450,1
107.53521,8.77000,      -0.69360,3.24439,1
107.63618,8.78000,      -0.69248,3.24428,1
107.73716,8.79000,      -0.69175,3.24417,1
107.83810,8.80000,      -0.69089,3.24407,1
107.93907,8.81000,      -0.69001,3.24396,1
108.04008,8.82000,      -0.68912,3.24385,1
108.14103,8.83000,      -0.68813,3.24374,1
108.24200,8.84000,      -0.68716,3.24363,1
108.34293,8.85000,      -0.68630,3.24352,1
108.44380,8.86000,      -0.68547,3.24341,1
108.54469,8.87000,      -0.68469,3.24331,1
108.64561,8.88000,      -0.68375,3.24320,1
108.74649,8.89000,      -0.68278,3.24309,1
108.84738,8.90000,      -0.68176,3.24298,1
108.94823,8.91000,      -0.68072,3.24287,1
109.04916,8.92000,      -0.67996,3.24276,1
109.15013,8.93000,      -0.67911,3.24265,1
109.25097,8.94000,      -0.67819,3.24254,1
109.35184,8.95000,      -0.67696,3.24243,1
109.45266,8.96000,      -0.67629,3.24232,1
109.55349,8.97000,      -0.67567,3.24221,1
109.65436,8.98000,      -0.67459,3.24210,1
109.75523,8.99000,      -0.67363,3.24199,1
109.85613,9.00000,      -0.67263,3.24188,1
109.95703,9.01000,      -0.67172,3.24177,1
110.05797,9.02000,      -0.67078,3.24166,1
110.15885,9.03000,      -0.66981,3.24155,1
110.25975,9.04000,      -0.66874,3.24144,1
110.36064,9.05000,      -0.66777,3.24133,1
110.46154,9.06000,      -0.66688,3.24122,1
110.56248,9.07000,      -0.66600,3.24111,1
110.66334,9.08000,      -0.66498,3.24100,1
110.76425,9.09000,      -0.66406,3.24089,1
110.86515,9.10000,      -0.66309,3.24078,1
110.96611,9.11000,      -0.66210,3.24067,1
111.06708,9.12000,      -0.66137,3.24055,1
111.16800,9.13000,      -0.66049,3.24044,1
111.26889,9.14000,      -0.65952,3.24033,1
111.36987,9.15000,      -0.65861,3.24022,1
111.47080,9.16000,      -0.65764,3.24011,1
111.57172,9.17000,      -0.65670,3.24000,1
111.67264,9.18000,      -0.65570,3.23988,1
111.77356,9.19000,      -0.65468,3.23977,1
111.87448,9.20000,      -0.65358,3.23966,1
111.97534,9.21000,      -0.65283,3.23955,1
112.07621,9.22000,      -0.65205,3.23944,1
112.17700,9.23000,      -0.65097,3.23932,1
112.27780,9.24000,      -0.64987,3.23921,1
112.37861,9.25000,      -0.64898,3.23910,1
112.47941,9.26000,      -0.64780,3.23899,1
112.58018,9.27000,      -0.64707,3.23887,1
112.68098,9.28000,      -0.64605,3.23876,1
112.78179,9.29000,      -0.64514,3.23865,1
112.88257,9.30000,      -0.64409,3.23853,1
112.98330,9.31000,      -0.64309,3.23842,1
113.08397,9.32000,      -0.64223,3.23831,1
113.18474,9.33000,      -0.64105,3.23819,1
113.28544,9.34000,      -0.64002,3.23808,1
113.38613,9.35000,      -0.63900,3.23797,1
113.48685,9.36000,      -0.63795,3.23785,1
113.58751,9.37000,      -0.63696,3.23774,1
113.68821,9.38000,      -0.63596,3.23763,1
113.78889,9.39000,      -0.63497,3.23751,1
113.88959,9.40000,      -0.63386,3.23740,1
113.99023,9.41000,      -0.63295,3.23728,1
114.09095,9.42000,      -0.63214,3.23717,1
114.19162,9.43000,      -0.63123,3.23706,1
114.29233,9.44000,      -0.63023,3.23694,1
114.39305,9.45000,      -0.62902,3.23683,1
114.49377,9.46000,      -0.62805,3.23671,1
114.59451,9.47000,      -0.62703,3.23660,1
114.69530,9.48000,      -0.62600,3.23648,1
114.79598,9.49000,      -0.62512,3.23637,1
114.89672,9.50000,      -0.62409,3.23625,1
114.99746,9.51000,      -0.62272,3.23614,1
115.09823,9.52000,      -0.62213,3.23602,1
115.19893,9.53000,      -0.62140,3.23591,1
115.29967,9.54000,      -0.62008,3.23579,1
115.40043,9.55000,      -0.61900,3.23568,1
115.50112,9.56000,      -0.61803,3.23556,1
115.60187,9.57000,      -0.61739,3.23545,1
115.70254,9.58000,      -0.61634,3.23533,1
115.80328,9.59000,      -0.61534,3.23521,1
115.90393,9.60000,      -0.61445,3.23510,1
116.00461,9.61000,      -0.61332,3.23498,1
116.10526,9.62000,      -0.61211,3.23487,1
116.20595,9.63000,      -0.61103,3.23475,1
116.30667,9.64000,      -0.61038,3.23463,1
116.40731,9.65000,      -0.60931,3.23452,1
116.50797,9.66000,      -0.60799,3.23440,1
116.60859,9.67000,      -0.60694,3.23428,1
116.70915,9.68000,      -0.60602,3.23417,1
116.80975,9.69000,      -0.60499,3.23405,1
116.91038,9.70000,      -0.60394,3.23393,1
117.01092,9.71000,      -0.60295,3.23382,1
117.11146,9.72000,      -0.60203,3.23370,1
117.21198,9.73000,      -0.60103,3.23358,1
117.31251,9.74000,      -0.60001,3.23346,1
117.41300,9.75000,      -0.59890,3.23335,1
117.51351,9.76000,      -0.59799,3.23323,1
117.61400,9.77000,      -0.59701,3.23311,1
117.71452,9.78000,      -0.59599,3.23299,1
117.81493,9.79000,      -0.59480,3.23288,1
117.91541,9.80000,      -0.59357,3.23276,1
118.01595,9.81000,      -0.59259,3.23264,1
118.11643,9.82000,      -0.59168,3.23252,1
118.21690,9.83000,      -0.59068,3.23241,1
118.31736,9.84000,      -0.58947,3.23229,1
118.41784,9.85000,      -0.58836,3.23217,1
118.51831,9.86000,      -0.58755,3.23205,1
118.61879,9.87000,      -0.58669,3.23193,1
118.71931,9.88000,      -0.58547,3.23181,1
118.81979,9.89000,      -0.58447,3.23169,1
118.91966,9.90000,      -0.58331,3.23158,1
119.02004,9.91000,      -0.58224,3.23146,1
119.12049,9.92000,      -0.58137,3.23134,1
119.22081,9.93000,      -0.58032,3.23122,1
119.32119,9.94000,      -0.57935,3.23110,1
119.42168,9.95000,      -0.57824,3.23098,1
119.52188,9.96000,      -0.57716,3.23086,1
119.62200,9.97000,      -0.57627,3.23074,1
119.72185,9.98000,      -0.57530,3.23062,1
119.82000,9.99000,      -0.57449,3.23051,1
119.89200,9.99917,      -0.57363,3.23042,1