File: DSC图/ExpAll_冷榨1.csv
#EXPORTTYPE:                 ,ALL
#FILE:                       ,¿‰’•1.ngb-sd7
#FORMAT:                     ,NETZSCH5
#FTYPE:                      ,ANSI
#IDENTITY:                   ,1
#DECIMAL:                    ,POINT
#SEPARATOR:                  ,COMMA
#MTYPE:                      ,DSC
#INSTRUMENT:                 ,NETZSCH DSC 204F1 Phoenix
#PROJECT:                    ,1
#DATE/TIME:                  ,2023/4/24 16:00:36 (UTC+8)
#CORR. FILE:                 ,
#TEMPCAL:                    ,applied
#SENSITIVITY:                ,applied
#LABORATORY:                 ,
#OPERATOR:                   ,0
#REMARK:                     ,
#SAMPLE:                     ,¿‰’•
#SAMPLE MASS /mg:            ,8.70
#MATERIAL:                   ,
#REFERENCE:                  ,
#REFERENCE MASS /mg:         ,0
#TYPE OF CRUCIBLE:           ,Concavus Pan Al, open
#SAMPLE CRUCIBLE MASS /mg:   ,0
#REFERENCE CRUCIBLE MASS /mg:,0
#M.RANGE /¶ÃV:                ,5000
#TAU-R:                      ,---
#CORR. CODE:                 ,000
#EXO:                        ,+1
#RANGE:                      ,20°„C/10.0(K/min)/120°„C
#SEGMENT:                    ,S1/1
#SEG. 1:                     ,20°„C/10.0(K/min)/120°„C

#*RESULTS:     ,File,Segment,Result,Unit,Y_value,Unit ,Range_Xmin,Unit,Range_Xmax,Unit,Range_Ymin,Unit ,Range_Ymax,Unit
#*Area (DSC)(o),¿‰’•1 ,1      ,-64.2 ,J/g ,-      ,-    ,40.9      ,°„C  ,115.5     ,°„C  ,-0.4018   ,mW/mg,-0.5886   ,mW/mg
#*Onset (DSC)  ,¿‰’•1 ,1      ,40.9  ,°„C  ,-0.3843,mW/mg,27.1      ,°„C  ,86.9      ,°„C  ,-0.3427   ,mW/mg,-0.7623   ,mW/mg
#*Peak (DSC)   ,¿‰’•1 ,1      ,88.1  ,°„C  ,-0.7629,mW/mg,27.1      ,°„C  ,102.1     ,°„C  ,-0.3427   ,mW/mg,-0.7099   ,mW/mg
#*End (DSC)    ,¿‰’•1 ,1      ,115.5 ,°„C  ,-0.5887,mW/mg,88.8      ,°„C  ,119.8     ,°„C  ,-0.7628   ,mW/mg,-0.5461   ,mW/mg

##Temp./°„C,Time/min,DSC/(mW/mg),Sensit./(uV/mW),Segment
  9.38500,0.00000, 2.105691e-002,3.29860,1
  9.41943,0.01000, 1.246063e-002,3.29860,1
  9.45492,0.02000, 4.262572e-003,3.29860,1
  9.49395,0.03000,-3.377194e-003,3.29860,1
  9.54140,0.04000,-1.013965e-002,3.29860,1
  9.60023,0.05000,-1.661158e-002,3.29859,1
  9.67114,0.06000,-2.268636e-002,3.29859,1
  9.75365,0.07000,-2.873729e-002,3.29859,1
  9.84643,0.08000,-3.511024e-002,3.29859,1
  9.94785,0.09000,-4.193816e-002,3.29858,1
 10.05659,0.10000,-4.951319e-002,3.29858,1
 10.14856,0.11000,-5.751551e-002,3.29858,1
 10.24584,0.12000,-6.573325e-002,3.29858,1
 10.34851,0.13000,-7.429852e-002,3.29857,1
 10.45661,0.14000,-8.323818e-002,3.29857,1
 10.56997,0.15000,-9.273673e-002,3.29856,1
 10.68826,0.16000,      -0.10213,3.29856,1
 10.81111,0.17000,      -0.11153,3.29856,1
 10.93816,0.18000,      -0.12113,3.29855,1
 11.06875,0.19000,      -0.13058,3.29855,1
 11.20243,0.20000,      -0.14009,3.29854,1
 11.33864,0.21000,      -0.14943,3.29853,1
 11.47710,0.22000,      -0.15843,3.29853,1
 11.61730,0.23000,      -0.16722,3.29852,1
 11.75895,0.24000,      -0.17558,3.29851,1
 11.90169,0.25000,      -0.18375,3.29851,1
 12.04538,0.26000,      -0.19150,3.29850,1
 12.18975,0.27000,      -0.19901,3.29849,1
 12.33477,0.28000,      -0.20652,3.29848,1
 12.48011,0.29000,      -0.21350,3.29848,1
 12.62584,0.30000,      -0.21992,3.29847,1
 12.77175,0.31000,      -0.22621,3.29846,1
 12.91785,0.32000,      -0.23186,3.29845,1
 13.06402,0.33000,      -0.23746,3.29844,1
 13.21018,0.34000,      -0.24258,3.29843,1
 13.35636,0.35000,      -0.24759,3.29842,1
 13.50256,0.36000,      -0.25220,3.29841,1
 13.64875,0.37000,      -0.25634,3.29840,1
 13.79493,0.38000,      -0.26050,3.29839,1
 13.94107,0.39000,      -0.26442,3.29838,1
 14.08725,0.40000,      -0.26784,3.29837,1
 14.23348,0.41000,      -0.27104,3.29836,1
 14.37962,0.42000,      -0.27420,3.29835,1
 14.52574,0.43000,      -0.27732,3.29834,1
 14.67193,0.44000,      -0.28007,3.29832,1
 14.81810,0.45000,      -0.28251,3.29831,1
 14.96418,0.46000,      -0.28478,3.29830,1
 15.11025,0.47000,      -0.28724,3.29829,1
 15.25629,0.48000,      -0.28946,3.29827,1
 15.40239,0.49000,      -0.29142,3.29826,1
 15.54836,0.50000,      -0.29340,3.29825,1
 15.69428,0.51000,      -0.29485,3.29823,1
 15.84023,0.52000,      -0.29662,3.29822,1
 15.98610,0.53000,      -0.29833,3.29821,1
 16.13197,0.54000,      -0.29989,3.29819,1
 16.27785,0.55000,      -0.30134,3.29818,1
 16.42364,0.56000,      -0.30271,3.29816,1
 16.56939,0.57000,      -0.30403,3.29815,1
 16.71507,0.58000,      -0.30527,3.29813,1
 16.86070,0.59000,      -0.30650,3.29812,1
 17.00620,0.60000,      -0.30771,3.29810,1
 17.15162,0.61000,      -0.30879,3.29809,1
 17.29697,0.62000,      -0.31000,3.29807,1
 17.44225,0.63000,      -0.31050,3.29806,1
 17.58741,0.64000,      -0.31168,3.29804,1
 17.73241,0.65000,      -0.31268,3.29802,1
 17.87739,0.66000,      -0.31349,3.29801,1
 18.02225,0.67000,      -0.31438,3.29799,1
 18.16693,0.68000,      -0.31512,3.29797,1
 18.31152,0.69000,      -0.31614,3.29796,1
 18.45602,0.70000,      -0.31706,3.29794,1
 18.60038,0.71000,      -0.31755,3.29792,1
 18.74459,0.72000,      -0.31831,3.29790,1
 18.88864,0.73000,      -0.31888,3.29788,1
 19.03261,0.74000,      -0.31962,3.29787,1
 19.17636,0.75000,      -0.32045,3.29785,1
 19.31997,0.76000,      -0.32084,3.29783,1
 19.46351,0.77000,      -0.32141,3.29781,1
 19.60685,0.78000,      -0.32215,3.29779,1
 19.75008,0.79000,      -0.32269,3.29777,1
 19.89320,0.80000,      -0.32321,3.29775,1
 20.03613,0.81000,      -0.32376,3.29773,1
 20.17885,0.82000,      -0.32430,3.29771,1
 20.32136,0.83000,      -0.32482,3.29769,1
 20.46377,0.84000,      -0.32545,3.29767,1
 20.60600,0.85000,      -0.32573,3.29765,1
 20.74810,0.86000,      -0.32614,3.29763,1
 20.89002,0.87000,      -0.32656,3.29761,1
 21.03184,0.88000,      -0.32726,3.29759,1
 21.17344,0.89000,      -0.32767,3.29756,1
 21.31482,0.90000,      -0.32806,3.29754,1
 21.45607,0.91000,      -0.32847,3.29752,1
 21.59718,0.92000,      -0.32894,3.29750,1
 21.73811,0.93000,      -0.32940,3.29748,1
 21.87890,0.94000,      -0.32984,3.29745,1
 22.01946,0.95000,      -0.33028,3.29743,1
 22.15980,0.96000,      -0.33067,3.29741,1
 22.30003,0.97000,      -0.33095,3.29739,1
 22.44005,0.98000,      -0.33142,3.29736,1
 22.57985,0.99000,      -0.33185,3.29734,1
 22.71948,1.00000,      -0.33219,3.29732,1
 22.85893,1.01000,      -0.33260,3.29729,1
 22.99825,1.02000,      -0.33291,3.29727,1
 23.13743,1.03000,      -0.33337,3.29724,1
 23.27643,1.04000,      -0.33373,3.29722,1
 23.41518,1.05000,      -0.33420,3.29719,1
 23.55372,1.06000,      -0.33448,3.29717,1
 23.69213,1.07000,      -0.33481,3.29715,1
 23.83030,1.08000,      -0.33530,3.29712,1
 23.96825,1.09000,      -0.33566,3.29710,1
 24.10603,1.10000,      -0.33591,3.29707,1
 24.24354,1.11000,      -0.33635,3.29704,1
 24.38085,1.12000,      -0.33674,3.29702,1
 24.51795,1.13000,      -0.33712,3.29699,1
 24.65487,1.14000,      -0.33740,3.29697,1
 24.79148,1.15000,      -0.33766,3.29694,1
 24.92800,1.16000,      -0.33796,3.29692,1
 25.06428,1.17000,      -0.33827,3.29689,1
 25.20036,1.18000,      -0.33876,3.29686,1
 25.33616,1.19000,      -0.33904,3.29684,1
 25.47179,1.20000,      -0.33921,3.29681,1
 25.60718,1.21000,      -0.33960,3.29678,1
 25.74234,1.22000,      -0.33982,3.29675,1
 25.87723,1.23000,      -0.34008,3.29673,1
 26.01190,1.24000,      -0.34043,3.29670,1
 26.14641,1.25000,      -0.34074,3.29667,1
 26.28067,1.26000,      -0.34112,3.29664,1
 26.41470,1.27000,      -0.34148,3.29662,1
 26.54859,1.28000,      -0.34174,3.29659,1
 26.68223,1.29000,      -0.34212,3.29656,1
 26.81569,1.30000,      -0.34245,3.29653,1
 26.94897,1.31000,      -0.34249,3.29650,1
 27.08202,1.32000,      -0.34269,3.29647,1
 27.21492,1.33000,      -0.34310,3.29644,1
 27.34764,1.34000,      -0.34343,3.29641,1
 27.48011,1.35000,      -0.34382,3.29639,1
 27.61243,1.36000,      -0.34412,3.29636,1
 27.74449,1.37000,      -0.34448,3.29633,1
 27.87639,1.38000,      -0.34497,3.29630,1
 28.00811,1.39000,      -0.34520,3.29627,1
 28.13966,1.40000,      -0.34558,3.29624,1
 28.27100,1.41000,      -0.34597,3.29621,1
 28.40218,1.42000,      -0.34609,3.29618,1
 28.53320,1.43000,      -0.34650,3.29615,1
 28.66403,1.44000,      -0.34680,3.29612,1
 28.79464,1.45000,      -0.34708,3.29609,1
 28.92508,1.46000,      -0.34749,3.29605,1
 29.05531,1.47000,      -0.34785,3.29602,1
 29.18536,1.48000,      -0.34829,3.29599,1
 29.31526,1.49000,      -0.34865,3.29596,1
 29.44502,1.50000,      -0.34908,3.29593,1
 29.57456,1.51000,      -0.34947,3.29590,1
 29.70397,1.52000,      -0.34991,3.29587,1
 29.83320,1.53000,      -0.35032,3.29584,1
 29.96223,1.54000,      -0.35065,3.29580,1
 30.09110,1.55000,      -0.35093,3.29577,1
 30.21989,1.56000,      -0.35134,3.29574,1
 30.34843,1.57000,      -0.35177,3.29571,1
 30.47675,1.58000,      -0.35237,3.29567,1
 30.60497,1.59000,      -0.35273,3.29564,1
 30.73297,1.60000,      -0.35298,3.29561,1
 30.86082,1.61000,      -0.35320,3.29558,1
 30.98852,1.62000,      -0.35383,3.29554,1
 31.11607,1.63000,      -0.35435,3.29551,1
 31.24343,1.64000,      -0.35473,3.29548,1
 31.37067,1.65000,      -0.35514,3.29544,1
 31.49775,1.66000,      -0.35552,3.29541,1
 31.62469,1.67000,      -0.35604,3.29538,1
 31.75149,1.68000,      -0.35656,3.29534,1
 31.87813,1.69000,      -0.35702,3.29531,1
 32.00454,1.70000,      -0.35741,3.29527,1
 32.13084,1.71000,      -0.35787,3.29524,1
 32.25695,1.72000,      -0.35836,3.29520,1
 32.38290,1.73000,      -0.35885,3.29517,1
 32.50864,1.74000,      -0.35918,3.29514,1
 32.63423,1.75000,      -0.35949,3.29510,1
 32.75966,1.76000,      -0.36006,3.29507,1
 32.88498,1.77000,      -0.36084,3.29503,1
 33.01015,1.78000,      -0.36138,3.29500,1
 33.13516,1.79000,      -0.36185,3.29496,1
 33.26008,1.80000,      -0.36228,3.29493,1
 33.38475,1.81000,      -0.36275,3.29489,1
 33.50933,1.82000,      -0.36308,3.29485,1
 33.63367,1.83000,      -0.36368,3.29482,1
 33.75789,1.84000,      -0.36417,3.29478,1
 33.88200,1.85000,      -0.36463,3.29475,1
 34.00589,1.86000,      -0.36515,3.29471,1
 34.12967,1.87000,      -0.36564,3.29467,1
 34.25328,1.88000,      -0.36610,3.29464,1
 34.37670,1.89000,      -0.36662,3.29460,1
 34.50005,1.90000,      -0.36700,3.29456,1
 34.62328,1.91000,      -0.36752,3.29453,1
 34.74633,1.92000,      -0.36806,3.29449,1
 34.86920,1.93000,      -0.36887,3.29445,1
 34.99198,1.94000,      -0.36933,3.29442,1
 35.11464,1.95000,      -0.36972,3.29438,1
 35.23721,1.96000,      -0.37045,3.29434,1
 35.35961,1.97000,      -0.37078,3.29430,1
 35.48189,1.98000,      -0.37129,3.29427,1
 35.60403,1.99000,      -0.37221,3.29423,1
 35.72608,2.00000,      -0.37281,3.29419,1
 35.84795,2.01000,      -0.37303,3.29415,1
 35.96972,2.02000,      -0.37373,3.29412,1
 36.09138,2.03000,      -0.37428,3.29408,1
 36.21295,2.04000,      -0.37501,3.29404,1
 36.33438,2.05000,      -0.37560,3.29400,1
 36.45580,2.06000,      -0.37625,3.29396,1
 36.57707,2.07000,      -0.37685,3.29392,1
 36.69831,2.08000,      -0.37739,3.29388,1
 36.81936,2.09000,      -0.37804,3.29385,1
 36.94028,2.10000,      -0.37869,3.29381,1
 37.06110,2.11000,      -0.37923,3.29377,1
 37.18185,2.12000,      -0.37978,3.29373,1
 37.30249,2.13000,      -0.38059,3.29369,1
 37.42305,2.14000,      -0.38129,3.29365,1
 37.54351,2.15000,      -0.38199,3.29361,1
 37.66377,2.16000,      -0.38232,3.29357,1
 37.78393,2.17000,      -0.38313,3.29353,1
 37.90395,2.18000,      -0.38394,3.29349,1
 38.02395,2.19000,      -0.38427,3.29345,1
 38.14374,2.20000,      -0.38492,3.29341,1
 38.26352,2.21000,      -0.38581,3.29337,1
 38.38315,2.22000,      -0.38654,3.29333,1
 38.50272,2.23000,      -0.38730,3.29329,1
 38.62211,2.24000,      -0.38776,3.29325,1
 38.74136,2.25000,      -0.38849,3.29320,1
 38.86052,2.26000,      -0.38917,3.29316,1
 38.97956,2.27000,      -0.38992,3.29312,1
 39.09844,2.28000,      -0.39079,3.29308,1
 39.21720,2.29000,      -0.39149,3.29304,1
 39.33589,2.30000,      -0.39195,3.29300,1
 39.45443,2.31000,      -0.39244,3.29296,1
 39.57284,2.32000,      -0.39317,3.29292,1
 39.69111,2.33000,      -0.39414,3.29287,1
 39.80933,2.34000,      -0.39490,3.29283,1
 39.92746,2.35000,      -0.39547,3.29279,1
 40.04552,2.36000,      -0.39612,3.29275,1
 40.16344,2.37000,      -0.39687,3.29271,1
 40.28131,2.38000,      -0.39766,3.29266,1
 40.39908,2.39000,      -0.39844,3.29262,1
 40.51679,2.40000,      -0.39909,3.29258,1
 40.63430,2.41000,      -0.39982,3.29254,1
 40.75172,2.42000,      -0.40089,3.29249,1
 40.86903,2.43000,      -0.40176,3.29245,1
 40.98626,2.44000,      -0.40201,3.29241,1
 41.10341,2.45000,      -0.40268,3.29236,1
 41.22051,2.46000,      -0.40355,3.29232,1
 41.33746,2.47000,      -0.40460,3.29228,1
 41.45438,2.48000,      -0.40549,3.29223,1
 41.57123,2.49000,      -0.40627,3.29219,1
 41.68795,2.50000,      -0.40703,3.29215,1
 41.80467,2.51000,      -0.40760,3.29210,1
 41.92126,2.52000,      -0.40832,3.29206,1
 42.03777,2.53000,      -0.40916,3.29201,1
 42.15416,2.54000,      -0.40989,3.29197,1
 42.27041,2.55000,      -0.41070,3.29192,1
 42.38657,2.56000,      -0.41146,3.29188,1
 42.50269,2.57000,      -0.41229,3.29184,1
 42.61869,2.58000,      -0.41316,3.29179,1
 42.73451,2.59000,      -0.41399,3.29175,1
 42.85025,2.60000,      -0.41507,3.29170,1
 42.96593,2.61000,      -0.41588,3.29166,1
 43.08157,2.62000,      -0.41669,3.29161,1
 43.19721,2.63000,      -0.41755,3.29157,1
 43.31272,2.64000,      -0.41834,3.29152,1
 43.42811,2.65000,      -0.41914,3.29148,1
 43.54344,2.66000,      -0.41998,3.29143,1
 43.65864,2.67000,      -0.42087,3.29138,1
 43.77377,2.68000,      -0.42181,3.29134,1
 43.88879,2.69000,      -0.42241,3.29129,1
 44.00377,2.70000,      -0.42338,3.29125,1
 44.11862,2.71000,      -0.42400,3.29120,1
 44.23343,2.72000,      -0.42487,3.29115,1
 44.34818,2.73000,      -0.42584,3.29111,1
 44.46287,2.74000,      -0.42673,3.29106,1
 44.57746,2.75000,      -0.42762,3.29102,1
 44.69197,2.76000,      -0.42843,3.29097,1
 44.80638,2.77000,      -0.42929,3.29092,1
 44.92075,2.78000,      -0.43023,3.29088,1
 45.03507,2.79000,      -0.43118,3.29083,1
 45.14930,2.80000,      -0.43220,3.29078,1
 45.26348,2.81000,      -0.43304,3.29073,1
 45.37756,2.82000,      -0.43385,3.29069,1
 45.49149,2.83000,      -0.43468,3.29064,1
 45.60538,2.84000,      -0.43576,3.29059,1
 45.71918,2.85000,      -0.43670,3.29054,1
 45.83293,2.86000,      -0.43735,3.29050,1
 45.94667,2.87000,      -0.43851,3.29045,1
 46.06026,2.88000,      -0.43951,3.29040,1
 46.17382,2.89000,      -0.44045,3.29035,1
 46.28728,2.90000,      -0.44137,3.29030,1
 46.40066,2.91000,      -0.44231,3.29026,1
 46.51397,2.92000,      -0.44315,3.29021,1
 46.62715,2.93000,      -0.44407,3.29016,1
 46.74021,2.94000,      -0.44512,3.29011,1
 46.85331,2.95000,      -0.44611,3.29006,1
 46.96631,2.96000,      -0.44706,3.29001,1
 47.07921,2.97000,      -0.44803,3.28996,1
 47.19203,2.98000,      -0.44886,3.28992,1
 47.30485,2.99000,      -0.44978,3.28987,1
 47.41757,3.00000,      -0.45070,3.28982,1
 47.53025,3.01000,      -0.45167,3.28977,1
 47.64289,3.02000,      -0.45259,3.28972,1
 47.75548,3.03000,      -0.45361,3.28967,1
 47.86803,3.04000,      -0.45495,3.28962,1
 47.98049,3.05000,      -0.45576,3.28957,1
 48.09280,3.06000,      -0.45652,3.28952,1
 48.20513,3.07000,      -0.45747,3.28947,1
 48.31741,3.08000,      -0.45852,3.28942,1
 48.42964,3.09000,      -0.45973,3.28937,1
 48.54180,3.10000,      -0.46083,3.28932,1
 48.65390,3.11000,      -0.46183,3.28927,1
 48.76597,3.12000,      -0.46275,3.28922,1
 48.87803,3.13000,      -0.46374,3.28917,1
 48.99008,3.14000,      -0.46485,3.28912,1
 49.10203,3.15000,      -0.46587,3.28907,1
 49.21395,3.16000,      -0.46682,3.28901,1
 49.32577,3.17000,      -0.46773,3.28896,1
 49.43752,3.18000,      -0.46876,3.28891,1
 49.54920,3.19000,      -0.47000,3.28886,1
 49.66089,3.20000,      -0.47102,3.28881,1
 49.77252,3.21000,      -0.47210,3.28876,1
 49.88408,3.22000,      -0.47326,3.28871,1
 49.99552,3.23000,      -0.47436,3.28865,1
 50.10695,3.24000,      -0.47544,3.28860,1
 50.21834,3.25000,      -0.47657,3.28855,1
 50.32974,3.26000,      -0.47749,3.28850,1
 50.44097,3.27000,      -0.47851,3.28845,1
 50.55216,3.28000,      -0.47946,3.28839,1
 50.66333,3.29000,      -0.48048,3.28834,1
 50.77434,3.30000,      -0.48183,3.28829,1
 50.88536,3.31000,      -0.48296,3.28824,1
 50.99631,3.32000,      -0.48409,3.28818,1
 51.10716,3.33000,      -0.48485,3.28813,1
 51.21795,3.34000,      -0.48574,3.28808,1
 51.32872,3.35000,      -0.48690,3.28802,1
 51.43944,3.36000,      -0.48797,3.28797,1
 51.55013,3.37000,      -0.48908,3.28792,1
 51.66080,3.38000,      -0.49018,3.28786,1
 51.77141,3.39000,      -0.49134,3.28781,1
 51.88190,3.40000,      -0.49250,3.28776,1
 51.99233,3.41000,      -0.49339,3.28770,1
 52.10267,3.42000,      -0.49434,3.28765,1
 52.21297,3.43000,      -0.49555,3.28760,1
 52.32320,3.44000,      -0.49679,3.28754,1
 52.43338,3.45000,      -0.49784,3.28749,1
 52.54352,3.46000,      -0.49895,3.28743,1
 52.65369,3.47000,      -0.49989,3.28738,1
 52.76375,3.48000,      -0.50100,3.28733,1
 52.87367,3.49000,      -0.50215,3.28727,1
 52.98361,3.50000,      -0.50318,3.28722,1
 53.09348,3.51000,      -0.50405,3.28716,1
 53.20336,3.52000,      -0.50528,3.28711,1
 53.31321,3.53000,      -0.50663,3.28705,1
 53.42298,3.54000,      -0.50776,3.28700,1
 53.53266,3.55000,      -0.50879,3.28694,1
 53.64233,3.56000,      -0.50981,3.28689,1
 53.75195,3.57000,      -0.51068,3.28683,1
 53.86151,3.58000,      -0.51178,3.28678,1
 53.97098,3.59000,      -0.51294,3.28672,1
 54.08043,3.60000,      -0.51408,3.28666,1
 54.18980,3.61000,      -0.51500,3.28661,1
 54.29916,3.62000,      -0.51623,3.28655,1
 54.40852,3.63000,      -0.51734,3.28650,1
 54.51787,3.64000,      -0.51853,3.28644,1
 54.62713,3.65000,      -0.51966,3.28639,1
 54.73638,3.66000,      -0.52077,3.28633,1
 54.84556,3.67000,      -0.52198,3.28627,1
 54.95472,3.68000,      -0.52287,3.28622,1
 55.06387,3.69000,      -0.52403,3.28616,1
 55.17298,3.70000,      -0.52511,3.28610,1
 55.28207,3.71000,      -0.52624,3.28605,1
 55.39102,3.72000,      -0.52743,3.28599,1
 55.49998,3.73000,      -0.52864,3.28593,1
 55.60890,3.74000,      -0.52967,3.28587,1
 55.71779,3.75000,      -0.53072,3.28582,1
 55.82667,3.76000,      -0.53172,3.28576,1
 55.93543,3.77000,      -0.53294,3.28570,1
 56.04423,3.78000,      -0.53404,3.28564,1
 56.15302,3.79000,      -0.53520,3.28559,1
 56.26172,3.80000,      -0.53623,3.28553,1
 56.37041,3.81000,      -0.53734,3.28547,1
 56.47908,3.82000,      -0.53850,3.28541,1
 56.58766,3.83000,      -0.53968,3.28536,1
 56.69613,3.84000,      -0.54082,3.28530,1
 56.80461,3.85000,      -0.54182,3.28524,1
 56.91308,3.86000,      -0.54274,3.28518,1
 57.02146,3.87000,      -0.54379,3.28512,1
 57.12987,3.88000,      -0.54503,3.28506,1
 57.23828,3.89000,      -0.54627,3.28500,1
 57.34666,3.90000,      -0.54727,3.28495,1
 57.45495,3.91000,      -0.54822,3.28489,1
 57.56321,3.92000,      -0.54927,3.28483,1
 57.67144,3.93000,      -0.55054,3.28477,1
 57.77964,3.94000,      -0.55175,3.28471,1
 57.88780,3.95000,      -0.55275,3.28465,1
 57.99590,3.96000,      -0.55397,3.28459,1
 58.10400,3.97000,      -0.55513,3.28453,1
 58.21210,3.98000,      -0.55586,3.28447,1
 58.32010,3.99000,      -0.55713,3.28441,1
 58.42810,4.00000,      -0.55837,3.28435,1
 58.53600,4.01000,      -0.55951,3.28429,1
 58.64387,4.02000,      -0.56067,3.28423,1
 58.75174,4.03000,      -0.56180,3.28417,1
 58.85956,4.04000,      -0.56291,3.28411,1
 58.96739,4.05000,      -0.56405,3.28405,1
 59.07521,4.06000,      -0.56521,3.28399,1
 59.18290,4.07000,      -0.56618,3.28393,1
 59.29056,4.08000,      -0.56710,3.28387,1
 59.39818,4.09000,      -0.56837,3.28381,1
 59.50577,4.10000,      -0.56956,3.28375,1
 59.61338,4.11000,      -0.57077,3.28369,1
 59.72093,4.12000,      -0.57178,3.28362,1
 59.82851,4.13000,      -0.57262,3.28356,1
 59.93600,4.14000,      -0.57394,3.28350,1
 60.04348,4.15000,      -0.57513,3.28344,1
 60.15089,4.16000,      -0.57602,3.28338,1
 60.25823,4.17000,      -0.57716,3.28332,1
 60.36551,4.18000,      -0.57845,3.28326,1
 60.47269,4.19000,      -0.57951,3.28319,1
 60.57989,4.20000,      -0.58062,3.28313,1
 60.68703,4.21000,      -0.58178,3.28307,1
 60.79426,4.22000,      -0.58283,3.28301,1
 60.90143,4.23000,      -0.58389,3.28294,1
 61.00856,4.24000,      -0.58484,3.28288,1
 61.11559,4.25000,      -0.58587,3.28282,1
 61.22251,4.26000,      -0.58700,3.28276,1
 61.32944,4.27000,      -0.58806,3.28270,1
 61.43636,4.28000,      -0.58925,3.28263,1
 61.54321,4.29000,      -0.59033,3.28257,1
 61.65002,4.30000,      -0.59146,3.28251,1
 61.75670,4.31000,      -0.59233,3.28244,1
 61.86339,4.32000,      -0.59323,3.28238,1
 61.97002,4.33000,      -0.59442,3.28232,1
 62.07659,4.34000,      -0.59563,3.28225,1
 62.18311,4.35000,      -0.59672,3.28219,1
 62.28964,4.36000,      -0.59775,3.28213,1
 62.39610,4.37000,      -0.59880,3.28206,1
 62.50261,4.38000,      -0.59989,3.28200,1
 62.60911,4.39000,      -0.60097,3.28194,1
 62.71554,4.40000,      -0.60200,3.28187,1
 62.82197,4.41000,      -0.60292,3.28181,1
 62.92833,4.42000,      -0.60384,3.28174,1
 63.03461,4.43000,      -0.60493,3.28168,1
 63.14092,4.44000,      -0.60606,3.28162,1
 63.24720,4.45000,      -0.60715,3.28155,1
 63.35352,4.46000,      -0.60804,3.28149,1
 63.45979,4.47000,      -0.60907,3.28142,1
 63.56600,4.48000,      -0.61018,3.28136,1
 63.67230,4.49000,      -0.61132,3.28129,1
 63.77848,4.50000,      -0.61227,3.28123,1
 63.88464,4.51000,      -0.61322,3.28116,1
 63.99080,4.52000,      -0.61433,3.28110,1
 64.09695,4.53000,      -0.61544,3.28103,1
 64.20310,4.54000,      -0.61652,3.28097,1
 64.30915,4.55000,      -0.61763,3.28090,1
 64.41521,4.56000,      -0.61869,3.28084,1
 64.52120,4.57000,      -0.61972,3.28077,1
 64.62721,4.58000,      -0.62080,3.28070,1
 64.73316,4.59000,      -0.62181,3.28064,1
 64.83910,4.60000,      -0.62311,3.28057,1
 64.94508,4.61000,      -0.62408,3.28051,1
 65.05095,4.62000,      -0.62501,3.28044,1
 65.15687,4.63000,      -0.62604,3.28037,1
 65.26270,4.64000,      -0.62712,3.28031,1
 65.36849,4.65000,      -0.62821,3.28024,1
 65.47434,4.66000,      -0.62918,3.28017,1
 65.58013,4.67000,      -0.63013,3.28011,1
 65.68589,4.68000,      -0.63119,3.28004,1
 65.79156,4.69000,      -0.63233,3.27997,1
 65.89725,4.70000,      -0.63333,3.27991,1
 66.00295,4.71000,      -0.63431,3.27984,1
 66.10859,4.72000,      -0.63548,3.27977,1
 66.21423,4.73000,      -0.63656,3.27970,1
 66.31979,4.74000,      -0.63751,3.27964,1
 66.42539,4.75000,      -0.63860,3.27957,1
 66.53097,4.76000,      -0.63966,3.27950,1
 66.63651,4.77000,      -0.64074,3.27943,1
 66.74200,4.78000,      -0.64174,3.27937,1
 66.84746,4.79000,      -0.64251,3.27930,1
 66.95288,4.80000,      -0.64359,3.27923,1
 67.05825,4.81000,      -0.64479,3.27916,1
 67.16361,4.82000,      -0.64593,3.27909,1
 67.26889,4.83000,      -0.64696,3.27902,1
 67.37411,4.84000,      -0.64794,3.27896,1
 67.47938,4.85000,      -0.64886,3.27889,1
 67.58457,4.86000,      -0.64984,3.27882,1
 67.68970,4.87000,      -0.65082,3.27875,1
 67.79484,4.88000,      -0.65180,3.27868,1
 67.89997,4.89000,      -0.65275,3.27861,1
 68.00497,4.90000,      -0.65349,3.27854,1
 68.11002,4.91000,      -0.65441,3.27847,1
 68.21498,4.92000,      -0.65544,3.27841,1
 68.32000,4.93000,      -0.65642,3.27834,1
 68.42500,4.94000,      -0.65729,3.27827,1
 68.52998,4.95000,      -0.65835,3.27820,1
 68.63487,4.96000,      -0.65936,3.27813,1
 68.73979,4.97000,      -0.66042,3.27806,1
 68.84466,4.98000,      -0.66137,3.27799,1
 68.94954,4.99000,      -0.66238,3.27792,1
 69.05438,5.00000,      -0.66338,3.27785,1
 69.15923,5.01000,      -0.66439,3.27778,1
 69.26400,5.02000,      -0.66542,3.27771,1
 69.36884,5.03000,      -0.66624,3.27764,1
 69.47362,5.04000,      -0.66714,3.27757,1
 69.57836,5.05000,      -0.66812,3.27750,1
 69.68307,5.06000,      -0.66899,3.27743,1
 69.78775,5.07000,      -0.66994,3.27736,1
 69.89248,5.08000,      -0.67090,3.27728,1
 69.99716,5.09000,      -0.67201,3.27721,1
 70.10189,5.10000,      -0.67302,3.27714,1
 70.20656,5.11000,      -0.67357,3.27707,1
 70.31125,5.12000,      -0.67484,3.27700,1
 70.41584,5.13000,      -0.67590,3.27693,1
 70.52043,5.14000,      -0.67678,3.27686,1
 70.62495,5.15000,      -0.67770,3.27679,1
 70.72954,5.16000,      -0.67868,3.27671,1
 70.83407,5.17000,      -0.67961,3.27664,1
 70.93862,5.18000,      -0.68054,3.27657,1
 71.04311,5.19000,      -0.68144,3.27650,1
 71.14761,5.20000,      -0.68239,3.27643,1
 71.25211,5.21000,      -0.68324,3.27635,1
 71.35661,5.22000,      -0.68403,3.27628,1
 71.46108,5.23000,      -0.68490,3.27621,1
 71.56556,5.24000,      -0.68599,3.27614,1
 71.67008,5.25000,      -0.68697,3.27606,1
 71.77459,5.26000,      -0.68787,3.27599,1
 71.87911,5.27000,      -0.68877,3.27592,1
 71.98352,5.28000,      -0.68970,3.27585,1
 72.08790,5.29000,      -0.69047,3.27577,1
 72.19228,5.30000,      -0.69139,3.27570,1
 72.29666,5.31000,      -0.69248,3.27563,1
 72.40100,5.32000,      -0.69328,3.27555,1
 72.50526,5.33000,      -0.69423,3.27548,1
 72.60956,5.34000,      -0.69510,3.27541,1
 72.71384,5.35000,      -0.69590,3.27533,1
 72.81811,5.36000,      -0.69675,3.27526,1
 72.92234,5.37000,      -0.69762,3.27518,1
 73.02659,5.38000,      -0.69857,3.27511,1
 73.13079,5.39000,      -0.69953,3.27504,1
 73.23495,5.40000,      -0.70048,3.27496,1
 73.33903,5.41000,      -0.70130,3.27489,1
 73.44313,5.42000,      -0.70213,3.27481,1
 73.54718,5.43000,      -0.70292,3.27474,1
 73.65120,5.44000,      -0.70374,3.27466,1
 73.75511,5.45000,      -0.70451,3.27459,1
 73.85897,5.46000,      -0.70541,3.27452,1
 73.96284,5.47000,      -0.70634,3.27444,1
 74.06667,5.48000,      -0.70724,3.27437,1
 74.17051,5.49000,      -0.70790,3.27429,1
 74.27429,5.50000,      -0.70851,3.27422,1
 74.37802,5.51000,      -0.70925,3.27414,1
 74.48172,5.52000,      -0.70994,3.27407,1
 74.58539,5.53000,      -0.71103,3.27399,1
 74.68911,5.54000,      -0.71161,3.27391,1
 74.79272,5.55000,      -0.71221,3.27384,1
 74.89630,5.56000,      -0.71298,3.27376,1
 74.99987,5.57000,      -0.71378,3.27369,1
 75.10334,5.58000,      -0.71444,3.27361,1
 75.20675,5.59000,      -0.71521,3.27354,1
 75.31020,5.60000,      -0.71600,3.27346,1
 75.41366,5.61000,      -0.71674,3.27338,1
 75.51705,5.62000,      -0.71740,3.27331,1
 75.62039,5.63000,      -0.71809,3.27323,1
 75.72372,5.64000,      -0.71881,3.27316,1
 75.82702,5.65000,      -0.71955,3.27308,1
 75.93038,5.66000,      -0.72026,3.27300,1
 76.03366,5.67000,      -0.72092,3.27293,1
 76.13692,5.68000,      -0.72167,3.27285,1
 76.24013,5.69000,      -0.72222,3.27277,1
 76.34334,5.70000,      -0.72285,3.27270,1
 76.44651,5.71000,      -0.72349,3.27262,1
 76.54969,5.72000,      -0.72407,3.27254,1
 76.65289,5.73000,      -0.72471,3.27246,1
 76.75603,5.74000,      -0.72545,3.27239,1
 76.85915,5.75000,      -0.72590,3.27231,1
 76.96225,5.76000,      -0.72650,3.27223,1
 77.06534,5.77000,      -0.72749,3.27216,1
 77.16841,5.78000,      -0.72812,3.27208,1
 77.27149,5.79000,      -0.72884,3.27200,1
 77.37454,5.80000,      -0.72937,3.27192,1
 77.47757,5.81000,      -0.72987,3.27184,1
 77.58057,5.82000,      -0.73058,3.27177,1
 77.68356,5.83000,      -0.73119,3.27169,1
 77.78652,5.84000,      -0.73177,3.27161,1
 77.88952,5.85000,      -0.73236,3.27153,1
 77.99244,5.86000,      -0.73288,3.27145,1
 78.09539,5.87000,      -0.73333,3.27137,1
 78.19838,5.88000,      -0.73394,3.27130,1
 78.30133,5.89000,      -0.73460,3.27122,1
 78.40426,5.90000,      -0.73524,3.27114,1
 78.50721,5.91000,      -0.73585,3.27106,1
 78.61013,5.92000,      -0.73638,3.27098,1
 78.71305,5.93000,      -0.73698,3.27090,1
 78.81595,5.94000,      -0.73746,3.27082,1
 78.91884,5.95000,      -0.73799,3.27074,1
 79.02172,5.96000,      -0.73860,3.27066,1
 79.12457,5.97000,      -0.73907,3.27058,1
 79.22746,5.98000,      -0.73949,3.27050,1
 79.33030,5.99000,      -0.74037,3.27042,1
 79.43321,6.00000,      -0.74087,3.27034,1
 79.53610,6.01000,      -0.74103,3.27026,1
 79.63895,6.02000,      -0.74182,3.27018,1
 79.74185,6.03000,      -0.74252,3.27010,1
 79.84475,6.04000,      -0.74294,3.27002,1
 79.94759,6.05000,      -0.74349,3.26994,1
 80.05046,6.06000,      -0.74370,3.26986,1
 80.15330,6.07000,      -0.74418,3.26978,1
 80.25611,6.08000,      -0.74471,3.26970,1
 80.35893,6.09000,      -0.74518,3.26962,1
 80.46172,6.10000,      -0.74576,3.26954,1
 80.56456,6.11000,      -0.74635,3.26946,1
 80.66736,6.12000,      -0.74685,3.26938,1
 80.77015,6.13000,      -0.74733,3.26929,1
 80.87285,6.14000,      -0.74775,3.26921,1
 80.97562,6.15000,      -0.74785,3.26913,1
 81.07836,6.16000,      -0.74843,3.26905,1
 81.18111,6.17000,      -0.74910,3.26897,1
 81.28390,6.18000,      -0.74941,3.26889,1
 81.38667,6.19000,      -0.74989,3.26880,1
 81.48941,6.20000,      -0.75026,3.26872,1
 81.59216,6.21000,      -0.75057,3.26864,1
 81.69490,6.22000,      -0.75102,3.26856,1
 81.79761,6.23000,      -0.75147,3.26848,1
 81.90030,6.24000,      -0.75184,3.26839,1
 82.00302,6.25000,      -0.75221,3.26831,1
 82.10572,6.26000,      -0.75260,3.26823,1
 82.20846,6.27000,      -0.75303,3.26814,1
 82.31113,6.28000,      -0.75342,3.26806,1
 82.41384,6.29000,      -0.75363,3.26798,1
 82.51649,6.30000,      -0.75387,3.26790,1
 82.61916,6.31000,      -0.75416,3.26781,1
 82.72182,6.32000,      -0.75461,3.26773,1
 82.82446,6.33000,      -0.75519,3.26765,1
 82.92708,6.34000,      -0.75532,3.26756,1
 83.02970,6.35000,      -0.75550,3.26748,1
 83.13229,6.36000,      -0.75598,3.26739,1
 83.23487,6.37000,      -0.75648,3.26731,1
 83.33743,6.38000,      -0.75682,3.26723,1
 83.43990,6.39000,      -0.75682,3.26714,1
 83.54244,6.40000,      -0.75692,3.26706,1
 83.64489,6.41000,      -0.75748,3.26697,1
 83.74726,6.42000,      -0.75769,3.26689,1
 83.84969,6.43000,      -0.75781,3.26681,1
 83.95207,6.44000,      -0.75813,3.26672,1
 84.05444,6.45000,      -0.75831,3.26664,1
 84.15682,6.46000,      -0.75868,3.26655,1
 84.25913,6.47000,      -0.75892,3.26647,1
 84.36143,6.48000,      -0.75913,3.26638,1
 84.46364,6.49000,      -0.75936,3.26630,1
 84.56584,6.50000,      -0.75946,3.26621,1
 84.66802,6.51000,      -0.75954,3.26613,1
 84.77025,6.52000,      -0.75991,3.26604,1
 84.87238,6.53000,      -0.75998,3.26596,1
 84.97449,6.54000,      -0.76008,3.26587,1
 85.07667,6.55000,      -0.76024,3.26579,1
 85.17874,6.56000,      -0.76045,3.26570,1
 85.28084,6.57000,      -0.76060,3.26562,1
 85.38292,6.58000,      -0.76084,3.26553,1
 85.48500,6.59000,      -0.76083,3.26545,1
 85.58698,6.60000,      -0.76091,3.26536,1
 85.68903,6.61000,      -0.76101,3.26527,1
 85.79110,6.62000,      -0.76119,3.26519,1
 85.89313,6.63000,      -0.76138,3.26510,1
 85.99508,6.64000,      -0.76148,3.26502,1
 86.09708,6.65000,      -0.76163,3.26493,1
 86.19905,6.66000,      -0.76168,3.26484,1
 86.30095,6.67000,      -0.76186,3.26476,1
 86.40290,6.68000,      -0.76202,3.26467,1
 86.50487,6.69000,      -0.76207,3.26458,1
 86.60682,6.70000,      -0.76206,3.26450,1
 86.70879,6.71000,      -0.76216,3.26441,1
 86.81072,6.72000,      -0.76221,3.26432,1
 86.91267,6.73000,      -0.76234,3.26423,1
 87.01471,6.74000,      -0.76247,3.26415,1
 87.11662,6.75000,      -0.76249,3.26406,1
 87.21854,6.76000,      -0.76259,3.26397,1
 87.32044,6.77000,      -0.76267,3.26388,1
 87.42236,6.78000,      -0.76264,3.26380,1
 87.52423,6.79000,      -0.76266,3.26371,1
 87.62615,6.80000,      -0.76268,3.26362,1
 87.72807,6.81000,      -0.76278,3.26353,1
 87.82997,6.82000,      -0.76272,3.26344,1
 87.93190,6.83000,      -0.76277,3.26336,1
 88.03385,6.84000,      -0.76282,3.26327,1
 88.13574,6.85000,      -0.76290,3.26318,1
 88.23757,6.86000,      -0.76278,3.26309,1
 88.33946,6.87000,      -0.76281,3.26300,1
 88.44134,6.88000,      -0.76277,3.26291,1
 88.54323,6.89000,      -0.76277,3.26282,1
 88.64511,6.90000,      -0.76276,3.26274,1
 88.74698,6.91000,      -0.76281,3.26265,1
 88.84882,6.92000,      -0.76278,3.26256,1
 88.95067,6.93000,      -0.76280,3.26247,1
 89.05248,6.94000,      -0.76280,3.26238,1
 89.15426,6.95000,      -0.76274,3.26229,1
 89.25610,6.96000,      -0.76265,3.26220,1
 89.35797,6.97000,      -0.76262,3.26211,1
 89.45977,6.98000,      -0.76264,3.26202,1
 89.56164,6.99000,      -0.76251,3.26193,1
 89.66346,7.00000,      -0.76226,3.26184,1
 89.76531,7.01000,      -0.76225,3.26175,1
 89.86715,7.02000,      -0.76217,3.26166,1
 89.96892,7.03000,      -0.76206,3.26157,1
 90.07066,7.04000,      -0.76200,3.26148,1
 90.17248,7.05000,      -0.76172,3.26139,1
 90.27431,7.06000,      -0.76172,3.26130,1
 90.37615,7.07000,      -0.76172,3.26121,1
 90.47797,7.08000,      -0.76160,3.26112,1
 90.57974,7.09000,      -0.76154,3.26103,1
 90.68154,7.10000,      -0.76141,3.26093,1
 90.78336,7.11000,      -0.76113,3.26084,1
 90.88515,7.12000,      -0.76102,3.26075,1
 90.98698,7.13000,      -0.76083,3.26066,1
 91.08880,7.14000,      -0.76069,3.26057,1
 91.19059,7.15000,      -0.76071,3.26048,1
 91.29238,7.16000,      -0.76065,3.26039,1
 91.39421,7.17000,      -0.76046,3.26029,1
 91.49597,7.18000,      -0.76029,3.26020,1
 91.59771,7.19000,      -0.76029,3.26011,1
 91.69946,7.20000,      -0.76023,3.26002,1
 91.80113,7.21000,      -0.75974,3.25993,1
 91.90275,7.22000,      -0.75947,3.25983,1
 92.00443,7.23000,      -0.75936,3.25974,1
 92.10607,7.24000,      -0.75884,3.25965,1
 92.20772,7.25000,      -0.75868,3.25956,1
 92.30934,7.26000,      -0.75857,3.25946,1
 92.41098,7.27000,      -0.75824,3.25937,1
 92.51257,7.28000,      -0.75796,3.25928,1
 92.61415,7.29000,      -0.75777,3.25919,1
 92.71572,7.30000,      -0.75774,3.25909,1
 92.81726,7.31000,      -0.75741,3.25900,1
 92.91877,7.32000,      -0.75717,3.25891,1
 93.02021,7.33000,      -0.75692,3.25881,1
 93.12162,7.34000,      -0.75654,3.25872,1
 93.22315,7.35000,      -0.75610,3.25863,1
 93.32459,7.36000,      -0.75572,3.25853,1
 93.42598,7.37000,      -0.75542,3.25844,1
 93.52741,7.38000,      -0.75523,3.25835,1
 93.62882,7.39000,      -0.75517,3.25825,1
 93.73018,7.40000,      -0.75468,3.25816,1
 93.83154,7.41000,      -0.75436,3.25806,1
 93.93297,7.42000,      -0.75414,3.25797,1
 94.03438,7.43000,      -0.75370,3.25788,1
 94.13579,7.44000,      -0.75335,3.25778,1
 94.23720,7.45000,      -0.75297,3.25769,1
 94.33859,7.46000,      -0.75253,3.25759,1
 94.43989,7.47000,      -0.75215,3.25750,1
 94.54123,7.48000,      -0.75212,3.25740,1
 94.64254,7.49000,      -0.75142,3.25731,1
 94.74384,7.50000,      -0.75120,3.25721,1
 94.84513,7.51000,      -0.75068,3.25712,1
 94.94644,7.52000,      -0.75017,3.25702,1
 95.04770,7.53000,      -0.74984,3.25693,1
 95.14900,7.54000,      -0.74962,3.25683,1
 95.25025,7.55000,      -0.74894,3.25674,1
 95.35152,7.56000,      -0.74853,3.25664,1
 95.45275,7.57000,      -0.74834,3.25655,1
 95.55402,7.58000,      -0.74804,3.25645,1
 95.65520,7.59000,      -0.74761,3.25636,1
 95.75643,7.60000,      -0.74693,3.25626,1
 95.85762,7.61000,      -0.74652,3.25616,1
 95.95882,7.62000,      -0.74622,3.25607,1
 96.05995,7.63000,      -0.74554,3.25597,1
 96.16116,7.64000,      -0.74495,3.25588,1
 96.26231,7.65000,      -0.74457,3.25578,1
 96.36339,7.66000,      -0.74413,3.25568,1
 96.46452,7.67000,      -0.74362,3.25559,1
 96.56562,7.68000,      -0.74310,3.25549,1
 96.66674,7.69000,      -0.74258,3.25539,1
 96.76790,7.70000,      -0.74204,3.25530,1
 96.86903,7.71000,      -0.74161,3.25520,1
 96.97010,7.72000,      -0.74106,3.25510,1
 97.07115,7.73000,      -0.74052,3.25501,1
 97.17225,7.74000,      -0.73995,3.25491,1
 97.27328,7.75000,      -0.73933,3.25481,1
 97.37433,7.76000,      -0.73868,3.25471,1
 97.47536,7.77000,      -0.73808,3.25462,1
 97.57639,7.78000,      -0.73748,3.25452,1
 97.67746,7.79000,      -0.73691,3.25442,1
 97.77852,7.80000,      -0.73659,3.25432,1
 97.87964,7.81000,      -0.73575,3.25423,1
 97.98069,7.82000,      -0.73518,3.25413,1
 98.08177,7.83000,      -0.73463,3.25403,1
 98.18284,7.84000,      -0.73404,3.25393,1
 98.28393,7.85000,      -0.73352,3.25383,1
 98.38502,7.86000,      -0.73282,3.25373,1
 98.48610,7.87000,      -0.73260,3.25364,1
 98.58721,7.88000,      -0.73195,3.25354,1
 98.68825,7.89000,      -0.73122,3.25344,1
 98.78931,7.90000,      -0.73070,3.25334,1
 98.89034,7.91000,      -0.73026,3.25324,1
 98.99141,7.92000,      -0.72999,3.25314,1
 99.09252,7.93000,      -0.72980,3.25304,1
 99.19370,7.94000,      -0.72893,3.25294,1
 99.29482,7.95000,      -0.72850,3.25284,1
 99.39597,7.96000,      -0.72817,3.25274,1
 99.49715,7.97000,      -0.72790,3.25264,1
 99.59830,7.98000,      -0.72738,3.25254,1
 99.69939,7.99000,      -0.72695,3.25244,1
 99.80052,8.00000,      -0.72654,3.25234,1
 99.90166,8.01000,      -0.72610,3.25224,1
100.00280,8.02000,      -0.72561,3.25214,1
100.10392,8.03000,      -0.72510,3.25204,1
100.20502,8.04000,      -0.72455,3.25194,1
100.30611,8.05000,      -0.72396,3.25184,1
100.40725,8.06000,      -0.72325,3.25174,1
100.50836,8.07000,      -0.72271,3.25164,1
100.60952,8.08000,      -0.72200,3.25154,1
100.71074,8.09000,      -0.72133,3.25144,1
100.81190,8.10000,      -0.72078,3.25134,1
100.91315,8.11000,      -0.71989,3.25124,1
101.01436,8.12000,      -0.71908,3.25114,1
101.11554,8.13000,      -0.71824,3.25103,1
101.21667,8.14000,      -0.71740,3.25093,1
101.31784,8.15000,      -0.71650,3.25083,1
101.41905,8.16000,      -0.71561,3.25073,1
101.52021,8.17000,      -0.71458,3.25063,1
101.62126,8.18000,      -0.71366,3.25053,1
101.72246,8.19000,      -0.71274,3.25042,1
101.82352,8.20000,      -0.71193,3.25032,1
101.92466,8.21000,      -0.71114,3.25022,1
102.02569,8.22000,      -0.71043,3.25012,1
102.12677,8.23000,      -0.70976,3.25002,1
102.22787,8.24000,      -0.70894,3.24991,1
102.32895,8.25000,      -0.70794,3.24981,1
102.43005,8.26000,      -0.70691,3.24971,1
102.53115,8.27000,      -0.70621,3.24961,1
102.63221,8.28000,      -0.70539,3.24950,1
102.73326,8.29000,      -0.70466,3.24940,1
102.83431,8.30000,      -0.70401,3.24930,1
102.93531,8.31000,      -0.70336,3.24919,1
103.03634,8.32000,      -0.70260,3.24909,1
103.13734,8.33000,      -0.70178,3.24899,1
103.23836,8.34000,      -0.70094,3.24888,1
103.33936,8.35000,      -0.70013,3.24878,1
103.44029,8.36000,      -0.69915,3.24868,1
103.54126,8.37000,      -0.69823,3.24857,1
103.64229,8.38000,      -0.69755,3.24847,1
103.74328,8.39000,      -0.69661,3.24837,1
103.84426,8.40000,      -0.69574,3.24826,1
103.94525,8.41000,      -0.69487,3.24816,1
104.04626,8.42000,      -0.69406,3.24805,1
104.14728,8.43000,      -0.69324,3.24795,1
104.24828,8.44000,      -0.69254,3.24784,1
104.34925,8.45000,      -0.69183,3.24774,1
104.45020,8.46000,      -0.69088,3.24764,1
104.55116,8.47000,      -0.69012,3.24753,1
104.65215,8.48000,      -0.68939,3.24743,1
104.75310,8.49000,      -0.68871,3.24732,1
104.85405,8.50000,      -0.68792,3.24722,1
104.95495,8.51000,      -0.68684,3.24711,1
105.05584,8.52000,      -0.68575,3.24701,1
105.15677,8.53000,      -0.68486,3.24690,1
105.25766,8.54000,      -0.68432,3.24680,1
105.35851,8.55000,      -0.68347,3.24669,1
105.45943,8.56000,      -0.68250,3.24658,1
105.56021,8.57000,      -0.68171,3.24648,1
105.66105,8.58000,      -0.68109,3.24637,1
105.76192,8.59000,      -0.68000,3.24627,1
105.86279,8.60000,      -0.67921,3.24616,1
105.96362,8.61000,      -0.67816,3.24606,1
106.06443,8.62000,      -0.67737,3.24595,1
106.16521,8.63000,      -0.67682,3.24584,1
106.26598,8.64000,      -0.67585,3.24574,1
106.36674,8.65000,      -0.67484,3.24563,1
106.46749,8.66000,      -0.67379,3.24552,1
106.56825,8.67000,      -0.67294,3.24542,1
106.66892,8.68000,      -0.67224,3.24531,1
106.76964,8.69000,      -0.67110,3.24520,1
106.87033,8.70000,      -0.67028,3.24510,1
106.97103,8.71000,      -0.66939,3.24499,1
107.07172,8.72000,      -0.66860,3.24488,1
107.17236,8.73000,      -0.66765,3.24478,1
107.27298,8.74000,      -0.66654,3.24467,1
107.37367,8.75000,      -0.66564,3.24456,1
107.47436,8.76000,      -0.66491,3.24445,1
107.57503,8.77000,      -0.66387,3.24435,1
107.67574,8.78000,      -0.66279,3.24424,1
107.77639,8.79000,      -0.66189,3.24413,1
107.87703,8.80000,      -0.66148,3.24402,1
107.97766,8.81000,      -0.66026,3.24392,1
108.07828,8.82000,      -0.65931,3.24381,1
108.17890,8.83000,      -0.65842,3.24370,1
108.27952,8.84000,      -0.65747,3.24359,1
108.38023,8.85000,      -0.65651,3.24348,1
108.48093,8.86000,      -0.65556,3.24337,1
108.58161,8.87000,      -0.65464,3.24327,1
108.68236,8.88000,      -0.65377,3.24316,1
108.78308,8.89000,      -0.65271,3.24305,1
108.88379,8.90000,      -0.65184,3.24294,1
108.98454,8.91000,      -0.65105,3.24283,1
109.08531,8.92000,      -0.65024,3.24272,1
109.18611,8.93000,      -0.64939,3.24261,1
109.28693,8.94000,      -0.64839,3.24250,1
109.38774,8.95000,      -0.64774,3.24239,1
109.48852,8.96000,      -0.64687,3.24228,1
109.58930,8.97000,      -0.64581,3.24217,1
109.69010,8.98000,      -0.64478,3.24206,1
109.79090,8.99000,      -0.64366,3.24195,1
109.89169,9.00000,      -0.64268,3.24184,1
109.99254,9.01000,      -0.64195,3.24173,1
110.09336,9.02000,      -0.64130,3.24162,1
110.19423,9.03000,      -0.64002,3.24151,1
110.29507,9.04000,      -0.63910,3.24140,1
110.39587,9.05000,      -0.63820,3.24129,1
110.49667,9.06000,      -0.63714,3.24118,1
110.59744,9.07000,      -0.63624,3.24107,1
110.69820,9.08000,      -0.63534,3.24096,1
110.79893,9.09000,      -0.63445,3.24085,1
110.89970,9.10000,      -0.63358,3.24074,1
111.00043,9.11000,      -0.63268,3.24063,1
111.10111,9.12000,      -0.63162,3.24052,1
111.20175,9.13000,      -0.63067,3.24041,1
111.30246,9.14000,      -0.62977,3.24029,1
111.40313,9.15000,      -0.62890,3.24018,1
111.50379,9.16000,      -0.62787,3.24007,1
111.60443,9.17000,      -0.62681,3.23996,1
111.70511,9.18000,      -0.62591,3.23985,1
111.80574,9.19000,      -0.62501,3.23974,1
111.90634,9.20000,      -0.62422,3.23962,1
112.00693,9.21000,      -0.62327,3.23951,1
112.10751,9.22000,      -0.62226,3.23940,1
112.20810,9.23000,      -0.62128,3.23929,1
112.30867,9.24000,      -0.62019,3.23918,1
112.40921,9.25000,      -0.61919,3.23906,1
112.50972,9.26000,      -0.61802,3.23895,1
112.61023,9.27000,      -0.61698,3.23884,1
112.71075,9.28000,      -0.61622,3.23873,1
112.81126,9.29000,      -0.61519,3.23861,1
112.91174,9.30000,      -0.61423,3.23850,1
113.01226,9.31000,      -0.61320,3.23839,1
113.11280,9.32000,      -0.61219,3.23828,1
113.21333,9.33000,      -0.61119,3.23816,1
113.31384,9.34000,      -0.61013,3.23805,1
113.41438,9.35000,      -0.60909,3.23794,1
113.51488,9.36000,      -0.60833,3.23782,1
113.61541,9.37000,      -0.60737,3.23771,1
113.71592,9.38000,      -0.60629,3.23760,1
113.81646,9.39000,      -0.60533,3.23748,1
113.91695,9.40000,      -0.60438,3.23737,1
114.01748,9.41000,      -0.60335,3.23725,1
114.11803,9.42000,      -0.60234,3.23714,1
114.21857,9.43000,      -0.60136,3.23703,1
114.31913,9.44000,      -0.60030,3.23691,1
114.41966,9.45000,      -0.59926,3.23680,1
114.52023,9.46000,      -0.59828,3.23668,1
114.62072,9.47000,      -0.59749,3.23657,1
114.72128,9.48000,      -0.59656,3.23645,1
114.82182,9.49000,      -0.59553,3.23634,1
114.92234,9.50000,      -0.59452,3.23622,1
115.02290,9.51000,      -0.59349,3.23611,1
115.12339,9.52000,      -0.59242,3.23599,1
115.22390,9.53000,      -0.59147,3.23588,1
115.32439,9.54000,      -0.59049,3.23576,1
115.42487,9.55000,      -0.58940,3.23565,1
115.52533,9.56000,      -0.58836,3.23553,1
115.62579,9.57000,      -0.58744,3.23542,1
115.72628,9.58000,      -0.58654,3.23530,1
115.82677,9.59000,      -0.58558,3.23519,1
115.92723,9.60000,      -0.58463,3.23507,1
116.02762,9.61000,      -0.58365,3.23496,1
116.12805,9.62000,      -0.58267,3.23484,1
116.22846,9.63000,      -0.58171,3.23472,1
116.32884,9.64000,      -0.58070,3.23461,1
116.42930,9.65000,      -0.57937,3.23449,1
116.52969,9.66000,      -0.57885,3.23437,1
116.63020,9.67000,      -0.57792,3.23426,1
116.73066,9.68000,      -0.57645,3.23414,1
116.83110,9.69000,      -0.57550,3.23402,1
116.93154,9.70000,      -0.57473,3.23391,1
117.03198,9.71000,      -0.57372,3.23379,1
117.13239,9.72000,      -0.57266,3.23367,1
117.23284,9.73000,      -0.57168,3.23356,1
117.33330,9.74000,      -0.57070,3.23344,1
117.43374,9.75000,      -0.56963,3.23332,1
117.53421,9.76000,      -0.56870,3.23321,1
117.63467,9.77000,      -0.56764,3.23309,1
117.73511,9.78000,      -0.56666,3.23297,1
117.83552,9.79000,      -0.56579,3.23285,1
117.93598,9.80000,      -0.56494,3.23274,1
118.03644,9.81000,      -0.56398,3.23262,1
118.13692,9.82000,      -0.56286,3.23250,1
118.23738,9.83000,      -0.56177,3.23238,1
118.33779,9.84000,      -0.56063,3.23226,1
118.43825,9.85000,      -0.55992,3.23214,1
118.53867,9.86000,      -0.55869,3.23203,1
118.63908,9.87000,      -0.55768,3.23191,1
118.73954,9.88000,      -0.55694,3.23179,1
118.83997,9.89000,      -0.55574,3.23167,1
118.94042,9.90000,      -0.55500,3.23155,1
119.04087,9.91000,      -0.55383,3.23143,1
119.14129,9.92000,      -0.55271,3.23131,1
119.24169,9.93000,      -0.55178,3.23120,1
119.34210,9.94000,      -0.55080,3.23108,1
119.44256,9.95000,      -0.54993,3.23096,1
119.54288,9.96000,      -0.54891,3.23084,1
119.64354,9.97000,      -0.54785,3.23072,1
119.74440,9.98000,      -0.54673,3.23060,1
119.81000,9.98667,      -0.54608,3.23052,1