File: DSC图/ExpAll_常规1.csv
#EXPORTTYPE:                 ,ALL
#FILE:                       ,常规1.ngb-sd7
#FORMAT:                     ,NETZSCH5
#FTYPE:                      ,ANSI
#IDENTITY:                   ,1
#DECIMAL:                    ,POINT
#SEPARATOR:                  ,COMMA
#MTYPE:                      ,DSC
#INSTRUMENT:                 ,NETZSCH DSC 204F1 Phoenix
#PROJECT:                    ,1
#DATE/TIME:                  ,2023/4/24 14:46:10 (UTC+8)
#CORR. FILE:                 ,
#TEMPCAL:                    ,applied
#SENSITIVITY:                ,applied
#LABORATORY:                 ,
#OPERATOR:                   ,0
#REMARK:                     ,
#SAMPLE:                     ,常规
#SAMPLE MASS /mg:            ,8.97
#MATERIAL:                   ,
#REFERENCE:                  ,
#REFERENCE MASS /mg:         ,0
#TYPE OF CRUCIBLE:           ,Concavus Pan Al, open
#SAMPLE CRUCIBLE MASS /mg:   ,0
#REFERENCE CRUCIBLE MASS /mg:,0
#M.RANGE /μV:                ,5000
#TAU-R:                      ,---
#CORR. CODE:                 ,000
#EXO:                        ,+1
#RANGE:                      ,20°C/10.0(K/min)/120°C
#SEGMENT:                    ,S1/1
#SEG. 1:                     ,20°C/10.0(K/min)/120°C

#*RESULTS:     ,File,Segment,Result,Unit,Y_value,Unit ,Range_Xmin,Unit,Range_Xmax,Unit,Range_Ymin,Unit ,Range_Ymax,Unit
#*Area (DSC)(o),常规1 ,1      ,-47.42,J/g ,-      ,-    ,45.1      ,°C  ,103.7     ,°C  ,-0.3838   ,mW/mg,-0.6255   ,mW/mg
#*Onset (DSC)  ,常规1 ,1      ,45.1  ,°C  ,-0.3585,mW/mg,24.3      ,°C  ,79.7      ,°C  ,-0.2849   ,mW/mg,-0.7252   ,mW/mg
#*Peak (DSC)   ,常规1 ,1      ,81.1  ,°C  ,-0.7263,mW/mg,35.9      ,°C  ,104.0     ,°C  ,-0.3274   ,mW/mg,-0.6231   ,mW/mg
#*End (DSC)    ,常规1 ,1      ,103.7 ,°C  ,-0.6343,mW/mg,81.6      ,°C  ,119.9     ,°C  ,-0.7262   ,mW/mg,-0.4883   ,mW/mg

##Temp./°C,Time/min,DSC/(mW/mg),Sensit./(uV/mW),Segment
 19.88900,0.00000,-4.455096e-002,3.29775,1
 19.89000,0.01000,-4.455123e-002,3.29775,1
 19.89046,0.02000,-4.447359e-002,3.29775,1
 19.89405,0.03000,-4.442254e-002,3.29775,1
 19.90528,0.04000,-4.439704e-002,3.29775,1
 19.92739,0.05000,-4.579168e-002,3.29775,1
 19.96122,0.06000,-4.932891e-002,3.29774,1
 20.00616,0.07000,-5.629859e-002,3.29773,1
 20.06106,0.08000,-6.654628e-002,3.29773,1
 20.12455,0.09000,-7.942825e-002,3.29772,1
 20.19518,0.10000,-9.393732e-002,3.29771,1
 20.24967,0.11000,      -0.10987,3.29770,1
 20.30926,0.12000,      -0.12621,3.29769,1
 20.37410,0.13000,      -0.14271,3.29768,1
 20.44411,0.14000,      -0.15832,3.29767,1
 20.51920,0.15000,      -0.17319,3.29766,1
 20.59920,0.16000,      -0.18702,3.29765,1
 20.68367,0.17000,      -0.19930,3.29764,1
 20.77218,0.18000,      -0.21028,3.29762,1
 20.86423,0.19000,      -0.22027,3.29761,1
 20.95926,0.20000,      -0.22889,3.29760,1
 21.05684,0.21000,      -0.23645,3.29758,1
 21.15652,0.22000,      -0.24282,3.29757,1
 21.25798,0.23000,      -0.24839,3.29755,1
 21.36089,0.24000,      -0.25309,3.29754,1
 21.46489,0.25000,      -0.25725,3.29752,1
 21.56984,0.26000,      -0.26050,3.29750,1
 21.67546,0.27000,      -0.26345,3.29749,1
 21.78154,0.28000,      -0.26582,3.29747,1
 21.88807,0.29000,      -0.26787,3.29745,1
 21.99480,0.30000,      -0.26967,3.29744,1
 22.10172,0.31000,      -0.27133,3.29742,1
 22.20880,0.32000,      -0.27244,3.29740,1
 22.31595,0.33000,      -0.27363,3.29738,1
 22.42311,0.34000,      -0.27472,3.29737,1
 22.53026,0.35000,      -0.27532,3.29735,1
 22.63736,0.36000,      -0.27638,3.29733,1
 22.74443,0.37000,      -0.27736,3.29731,1
 22.85136,0.38000,      -0.27783,3.29729,1
 22.95834,0.39000,      -0.27833,3.29727,1
 23.06528,0.40000,      -0.27879,3.29726,1
 23.17220,0.41000,      -0.27952,3.29724,1
 23.27913,0.42000,      -0.28012,3.29722,1
 23.38595,0.43000,      -0.28071,3.29720,1
 23.49274,0.44000,      -0.28118,3.29718,1
 23.59949,0.45000,      -0.28163,3.29716,1
 23.70616,0.46000,      -0.28217,3.29714,1
 23.81280,0.47000,      -0.28272,3.29712,1
 23.91941,0.48000,      -0.28306,3.29710,1
 24.02605,0.49000,      -0.28345,3.29709,1
 24.13267,0.50000,      -0.28404,3.29707,1
 24.23933,0.51000,      -0.28456,3.29705,1
 24.34589,0.52000,      -0.28511,3.29703,1
 24.45241,0.53000,      -0.28558,3.29701,1
 24.55892,0.54000,      -0.28605,3.29699,1
 24.66548,0.55000,      -0.28646,3.29697,1
 24.77198,0.56000,      -0.28701,3.29695,1
 24.87851,0.57000,      -0.28753,3.29692,1
 24.98500,0.58000,      -0.28784,3.29690,1
 25.09156,0.59000,      -0.28834,3.29688,1
 25.19795,0.60000,      -0.28878,3.29686,1
 25.30436,0.61000,      -0.28927,3.29684,1
 25.41077,0.62000,      -0.28974,3.29682,1
 25.51715,0.63000,      -0.29024,3.29680,1
 25.62356,0.64000,      -0.29065,3.29678,1
 25.72997,0.65000,      -0.29079,3.29676,1
 25.83633,0.66000,      -0.29123,3.29673,1
 25.94272,0.67000,      -0.29165,3.29671,1
 26.04908,0.68000,      -0.29237,3.29669,1
 26.15539,0.69000,      -0.29274,3.29667,1
 26.26169,0.70000,      -0.29287,3.29665,1
 26.36789,0.71000,      -0.29313,3.29663,1
 26.47411,0.72000,      -0.29360,3.29660,1
 26.58028,0.73000,      -0.29423,3.29658,1
 26.68641,0.74000,      -0.29457,3.29656,1
 26.79249,0.75000,      -0.29473,3.29654,1
 26.89862,0.76000,      -0.29506,3.29651,1
 27.00469,0.77000,      -0.29556,3.29649,1
 27.11082,0.78000,      -0.29613,3.29647,1
 27.21680,0.79000,      -0.29647,3.29644,1
 27.32270,0.80000,      -0.29686,3.29642,1
 27.42864,0.81000,      -0.29707,3.29640,1
 27.53449,0.82000,      -0.29752,3.29637,1
 27.64034,0.83000,      -0.29796,3.29635,1
 27.74616,0.84000,      -0.29838,3.29633,1
 27.85190,0.85000,      -0.29877,3.29630,1
 27.95767,0.86000,      -0.29913,3.29628,1
 28.06343,0.87000,      -0.29958,3.29625,1
 28.16913,0.88000,      -0.29999,3.29623,1
 28.27479,0.89000,      -0.30041,3.29621,1
 28.38043,0.90000,      -0.30067,3.29618,1
 28.48597,0.91000,      -0.30111,3.29616,1
 28.59149,0.92000,      -0.30145,3.29613,1
 28.69693,0.93000,      -0.30195,3.29611,1
 28.80234,0.94000,      -0.30242,3.29608,1
 28.90775,0.95000,      -0.30289,3.29606,1
 29.01307,0.96000,      -0.30328,3.29603,1
 29.11833,0.97000,      -0.30351,3.29601,1
 29.22352,0.98000,      -0.30375,3.29598,1
 29.32862,0.99000,      -0.30404,3.29596,1
 29.43382,1.00000,      -0.30461,3.29593,1
 29.53897,1.01000,      -0.30487,3.29591,1
 29.64410,1.02000,      -0.30516,3.29588,1
 29.74911,1.03000,      -0.30579,3.29586,1
 29.85410,1.04000,      -0.30600,3.29583,1
 29.95898,1.05000,      -0.30626,3.29580,1
 30.06382,1.06000,      -0.30678,3.29578,1
 30.16857,1.07000,      -0.30712,3.29575,1
 30.27330,1.08000,      -0.30754,3.29573,1
 30.37803,1.09000,      -0.30775,3.29570,1
 30.48261,1.10000,      -0.30804,3.29567,1
 30.58723,1.11000,      -0.30837,3.29565,1
 30.69177,1.12000,      -0.30871,3.29562,1
 30.79628,1.13000,      -0.30913,3.29559,1
 30.90074,1.14000,      -0.30945,3.29557,1
 31.00515,1.15000,      -0.30989,3.29554,1
 31.10946,1.16000,      -0.31020,3.29551,1
 31.21369,1.17000,      -0.31054,3.29548,1
 31.31784,1.18000,      -0.31075,3.29546,1
 31.42200,1.19000,      -0.31076,3.29543,1
 31.52605,1.20000,      -0.31120,3.29540,1
 31.62998,1.21000,      -0.31167,3.29537,1
 31.73390,1.22000,      -0.31180,3.29535,1
 31.83769,1.23000,      -0.31214,3.29532,1
 31.94146,1.24000,      -0.31259,3.29529,1
 32.04523,1.25000,      -0.31290,3.29526,1
 32.14892,1.26000,      -0.31339,3.29523,1
 32.25259,1.27000,      -0.31371,3.29521,1
 32.35615,1.28000,      -0.31397,3.29518,1
 32.45961,1.29000,      -0.31423,3.29515,1
 32.56303,1.30000,      -0.31457,3.29512,1
 32.66638,1.31000,      -0.31494,3.29509,1
 32.76977,1.32000,      -0.31497,3.29506,1
 32.87310,1.33000,      -0.31536,3.29503,1
 32.97631,1.34000,      -0.31578,3.29501,1
 33.07954,1.35000,      -0.31601,3.29498,1
 33.18267,1.36000,      -0.31635,3.29495,1
 33.28589,1.37000,      -0.31680,3.29492,1
 33.38895,1.38000,      -0.31721,3.29489,1
 33.49203,1.39000,      -0.31768,3.29486,1
 33.59507,1.40000,      -0.31815,3.29483,1
 33.69803,1.41000,      -0.31849,3.29480,1
 33.80103,1.42000,      -0.31893,3.29477,1
 33.90400,1.43000,      -0.31933,3.29474,1
 34.00693,1.44000,      -0.31956,3.29471,1
 34.10974,1.45000,      -0.31988,3.29468,1
 34.21249,1.46000,      -0.32016,3.29465,1
 34.31525,1.47000,      -0.32061,3.29462,1
 34.41798,1.48000,      -0.32115,3.29459,1
 34.52072,1.49000,      -0.32155,3.29456,1
 34.62341,1.50000,      -0.32209,3.29453,1
 34.72608,1.51000,      -0.32248,3.29450,1
 34.82872,1.52000,      -0.32288,3.29447,1
 34.93126,1.53000,      -0.32332,3.29444,1
 35.03385,1.54000,      -0.32368,3.29440,1
 35.13638,1.55000,      -0.32413,3.29437,1
 35.23889,1.56000,      -0.32465,3.29434,1
 35.34141,1.57000,      -0.32488,3.29431,1
 35.44387,1.58000,      -0.32548,3.29428,1
 35.54628,1.59000,      -0.32577,3.29425,1
 35.64864,1.60000,      -0.32629,3.29422,1
 35.75100,1.61000,      -0.32689,3.29418,1
 35.85331,1.62000,      -0.32723,3.29415,1
 35.95561,1.63000,      -0.32767,3.29412,1
 36.05795,1.64000,      -0.32812,3.29409,1
 36.16025,1.65000,      -0.32864,3.29406,1
 36.26252,1.66000,      -0.32916,3.29402,1
 36.36475,1.67000,      -0.32960,3.29399,1
 36.46697,1.68000,      -0.32999,3.29396,1
 36.56916,1.69000,      -0.33038,3.29393,1
 36.67134,1.70000,      -0.33098,3.29389,1
 36.77341,1.71000,      -0.33143,3.29386,1
 36.87549,1.72000,      -0.33190,3.29383,1
 36.97759,1.73000,      -0.33244,3.29379,1
 37.07966,1.74000,      -0.33302,3.29376,1
 37.18164,1.75000,      -0.33354,3.29373,1
 37.28369,1.76000,      -0.33416,3.29369,1
 37.38564,1.77000,      -0.33450,3.29366,1
 37.48762,1.78000,      -0.33500,3.29363,1
 37.58957,1.79000,      -0.33547,3.29359,1
 37.69148,1.80000,      -0.33612,3.29356,1
 37.79339,1.81000,      -0.33656,3.29353,1
 37.89536,1.82000,      -0.33700,3.29349,1
 37.99726,1.83000,      -0.33750,3.29346,1
 38.09913,1.84000,      -0.33799,3.29342,1
 38.20093,1.85000,      -0.33854,3.29339,1
 38.30275,1.86000,      -0.33911,3.29335,1
 38.40457,1.87000,      -0.33969,3.29332,1
 38.50636,1.88000,      -0.34031,3.29329,1
 38.60808,1.89000,      -0.34091,3.29325,1
 38.70977,1.90000,      -0.34133,3.29322,1
 38.81154,1.91000,      -0.34182,3.29318,1
 38.91331,1.92000,      -0.34250,3.29315,1
 39.01495,1.93000,      -0.34312,3.29311,1
 39.11662,1.94000,      -0.34370,3.29307,1
 39.21829,1.95000,      -0.34419,3.29304,1
 39.31990,1.96000,      -0.34482,3.29300,1
 39.42151,1.97000,      -0.34544,3.29297,1
 39.52307,1.98000,      -0.34601,3.29293,1
 39.62467,1.99000,      -0.34656,3.29290,1
 39.72626,2.00000,      -0.34708,3.29286,1
 39.82787,2.01000,      -0.34773,3.29283,1
 39.92939,2.02000,      -0.34807,3.29279,1
 40.03082,2.03000,      -0.34859,3.29275,1
 40.13231,2.04000,      -0.34935,3.29272,1
 40.23380,2.05000,      -0.35000,3.29268,1
 40.33526,2.06000,      -0.35065,3.29264,1
 40.43672,2.07000,      -0.35130,3.29261,1
 40.53818,2.08000,      -0.35195,3.29257,1
 40.63970,2.09000,      -0.35250,3.29253,1
 40.74125,2.10000,      -0.35310,3.29250,1
 40.84279,2.11000,      -0.35375,3.29246,1
 40.94430,2.12000,      -0.35455,3.29242,1
 41.04580,2.13000,      -0.35526,3.29238,1
 41.14734,2.14000,      -0.35567,3.29235,1
 41.24882,2.15000,      -0.35640,3.29231,1
 41.35038,2.16000,      -0.35723,3.29227,1
 41.45193,2.17000,      -0.35773,3.29223,1
 41.55349,2.18000,      -0.35843,3.29220,1
 41.65502,2.19000,      -0.35937,3.29216,1
 41.75649,2.20000,      -0.36010,3.29212,1
 41.85808,2.21000,      -0.36072,3.29208,1
 41.95962,2.22000,      -0.36143,3.29204,1
 42.06120,2.23000,      -0.36192,3.29200,1
 42.16272,2.24000,      -0.36252,3.29197,1
 42.26425,2.25000,      -0.36343,3.29193,1
 42.36579,2.26000,      -0.36416,3.29189,1
 42.46733,2.27000,      -0.36494,3.29185,1
 42.56879,2.28000,      -0.36562,3.29181,1
 42.67025,2.29000,      -0.36627,3.29177,1
 42.77167,2.30000,      -0.36702,3.29173,1
 42.87307,2.31000,      -0.36778,3.29169,1
 42.97446,2.32000,      -0.36845,3.29165,1
 43.07585,2.33000,      -0.36918,3.29161,1
 43.17726,2.34000,      -0.36986,3.29157,1
 43.27866,2.35000,      -0.37054,3.29153,1
 43.38003,2.36000,      -0.37114,3.29149,1
 43.48138,2.37000,      -0.37179,3.29145,1
 43.58272,2.38000,      -0.37265,3.29141,1
 43.68407,2.39000,      -0.37322,3.29137,1
 43.78541,2.40000,      -0.37395,3.29133,1
 43.88674,2.41000,      -0.37476,3.29129,1
 43.98800,2.42000,      -0.37546,3.29125,1
 44.08925,2.43000,      -0.37616,3.29121,1
 44.19057,2.44000,      -0.37687,3.29117,1
 44.29185,2.45000,      -0.37760,3.29113,1
 44.39318,2.46000,      -0.37835,3.29109,1
 44.49449,2.47000,      -0.37900,3.29105,1
 44.59572,2.48000,      -0.37978,3.29101,1
 44.69698,2.49000,      -0.38056,3.29097,1
 44.79823,2.50000,      -0.38135,3.29093,1
 44.89948,2.51000,      -0.38215,3.29088,1
 45.00067,2.52000,      -0.38293,3.29084,1
 45.10193,2.53000,      -0.38382,3.29080,1
 45.20315,2.54000,      -0.38468,3.29076,1
 45.30434,2.55000,      -0.38202,3.29072,1
 45.40557,2.56000,      -0.37936,3.29067,1
 45.50677,2.57000,      -0.38193,3.29063,1
 45.60803,2.58000,      -0.38749,3.29059,1
 45.70925,2.59000,      -0.39342,3.29055,1
 45.81052,2.60000,      -0.39916,3.29051,1
 45.91179,2.61000,      -0.40467,3.29046,1
 46.01303,2.62000,      -0.41000,3.29042,1
 46.11426,2.63000,      -0.41515,3.29038,1
 46.21551,2.64000,      -0.41968,3.29033,1
 46.31671,2.65000,      -0.42406,3.29029,1
 46.41789,2.66000,      -0.42823,3.29025,1
 46.51910,2.67000,      -0.43170,3.29021,1
 46.62041,2.68000,      -0.43538,3.29016,1
 46.72175,2.69000,      -0.43849,3.29012,1
 46.82308,2.70000,      -0.44167,3.29008,1
 46.92434,2.71000,      -0.44483,3.29003,1
 47.02561,2.72000,      -0.44748,3.28999,1
 47.12690,2.73000,      -0.44994,3.28994,1
 47.22815,2.74000,      -0.45225,3.28990,1
 47.32949,2.75000,      -0.45440,3.28986,1
 47.43077,2.76000,      -0.45642,3.28981,1
 47.53200,2.77000,      -0.45840,3.28977,1
 47.63323,2.78000,      -0.46052,3.28972,1
 47.73444,2.79000,      -0.46237,3.28968,1
 47.83557,2.80000,      -0.46390,3.28963,1
 47.93666,2.81000,      -0.46564,3.28959,1
 48.03784,2.82000,      -0.46712,3.28954,1
 48.13897,2.83000,      -0.46865,3.28950,1
 48.24011,2.84000,      -0.47026,3.28945,1
 48.34123,2.85000,      -0.47187,3.28941,1
 48.44241,2.86000,      -0.47328,3.28936,1
 48.54356,2.87000,      -0.47424,3.28932,1
 48.64459,2.88000,      -0.47559,3.28927,1
 48.74556,2.89000,      -0.47687,3.28923,1
 48.84654,2.90000,      -0.47817,3.28918,1
 48.94759,2.91000,      -0.47926,3.28914,1
 49.04861,2.92000,      -0.48022,3.28909,1
 49.14961,2.93000,      -0.48145,3.28904,1
 49.25062,2.94000,      -0.48262,3.28900,1
 49.35161,2.95000,      -0.48389,3.28895,1
 49.45257,2.96000,      -0.48488,3.28890,1
 49.55352,2.97000,      -0.48595,3.28886,1
 49.65451,2.98000,      -0.48710,3.28881,1
 49.75541,2.99000,      -0.48809,3.28877,1
 49.85638,3.00000,      -0.48887,3.28872,1
 49.95733,3.01000,      -0.48994,3.28867,1
 50.05825,3.02000,      -0.49103,3.28862,1
 50.15921,3.03000,      -0.49233,3.28858,1
 50.26010,3.04000,      -0.49343,3.28853,1
 50.36098,3.05000,      -0.49437,3.28848,1
 50.46187,3.06000,      -0.49536,3.28844,1
 50.56272,3.07000,      -0.49635,3.28839,1
 50.66362,3.08000,      -0.49742,3.28834,1
 50.76456,3.09000,      -0.49864,3.28829,1
 50.86546,3.10000,      -0.49979,3.28825,1
 50.96633,3.11000,      -0.50055,3.28820,1
 51.06720,3.12000,      -0.50149,3.28815,1
 51.16803,3.13000,      -0.50250,3.28810,1
 51.26892,3.14000,      -0.50360,3.28805,1
 51.36974,3.15000,      -0.50469,3.28800,1
 51.47057,3.16000,      -0.50574,3.28796,1
 51.57143,3.17000,      -0.50673,3.28791,1
 51.67226,3.18000,      -0.50774,3.28786,1
 51.77310,3.19000,      -0.50881,3.28781,1
 51.87397,3.20000,      -0.50988,3.28776,1
 51.97480,3.21000,      -0.51090,3.28771,1
 52.07564,3.22000,      -0.51184,3.28766,1
 52.17648,3.23000,      -0.51301,3.28761,1
 52.27733,3.24000,      -0.51408,3.28756,1
 52.37820,3.25000,      -0.51499,3.28752,1
 52.47911,3.26000,      -0.51599,3.28747,1
 52.58002,3.27000,      -0.51698,3.28742,1
 52.68087,3.28000,      -0.51805,3.28737,1
 52.78174,3.29000,      -0.51914,3.28732,1
 52.88264,3.30000,      -0.52013,3.28727,1
 52.98351,3.31000,      -0.52123,3.28722,1
 53.08443,3.32000,      -0.52225,3.28717,1
 53.18528,3.33000,      -0.52332,3.28712,1
 53.28610,3.34000,      -0.52444,3.28707,1
 53.38692,3.35000,      -0.52533,3.28702,1
 53.48777,3.36000,      -0.52653,3.28696,1
 53.58867,3.37000,      -0.52768,3.28691,1
 53.68952,3.38000,      -0.52874,3.28686,1
 53.79046,3.39000,      -0.52982,3.28681,1
 53.89131,3.40000,      -0.53052,3.28676,1
 53.99225,3.41000,      -0.53144,3.28671,1
 54.09308,3.42000,      -0.53264,3.28666,1
 54.19390,3.43000,      -0.53386,3.28661,1
 54.29475,3.44000,      -0.53488,3.28656,1
 54.39559,3.45000,      -0.53598,3.28650,1
 54.49636,3.46000,      -0.53707,3.28645,1
 54.59710,3.47000,      -0.53801,3.28640,1
 54.69784,3.48000,      -0.53893,3.28635,1
 54.79864,3.49000,      -0.53995,3.28630,1
 54.89936,3.50000,      -0.54107,3.28624,1
 55.00011,3.51000,      -0.54214,3.28619,1
 55.10087,3.52000,      -0.54316,3.28614,1
 55.20161,3.53000,      -0.54420,3.28609,1
 55.30234,3.54000,      -0.54540,3.28603,1
 55.40310,3.55000,      -0.54609,3.28598,1
 55.50385,3.56000,      -0.54708,3.28593,1
 55.60452,3.57000,      -0.54831,3.28588,1
 55.70516,3.58000,      -0.54930,3.28582,1
 55.80577,3.59000,      -0.55042,3.28577,1
 55.90636,3.60000,      -0.55139,3.28572,1
 56.00695,3.61000,      -0.55264,3.28566,1
 56.10761,3.62000,      -0.55364,3.28561,1
 56.20823,3.63000,      -0.55468,3.28556,1
 56.30887,3.64000,      -0.55570,3.28550,1
 56.40946,3.65000,      -0.55667,3.28545,1
 56.51008,3.66000,      -0.55753,3.28540,1
 56.61067,3.67000,      -0.55853,3.28534,1
 56.71121,3.68000,      -0.55960,3.28529,1
 56.81177,3.69000,      -0.56062,3.28523,1
 56.91233,3.70000,      -0.56171,3.28518,1
 57.01284,3.71000,      -0.56273,3.28513,1
 57.11341,3.72000,      -0.56368,3.28507,1
 57.21393,3.73000,      -0.56459,3.28502,1
 57.31452,3.74000,      -0.56548,3.28496,1
 57.41507,3.75000,      -0.56645,3.28491,1
 57.51562,3.76000,      -0.56744,3.28485,1
 57.61618,3.77000,      -0.56854,3.28480,1
 57.71679,3.78000,      -0.56967,3.28474,1
 57.81741,3.79000,      -0.57084,3.28469,1
 57.91808,3.80000,      -0.57189,3.28463,1
 58.01867,3.81000,      -0.57299,3.28458,1
 58.11928,3.82000,      -0.57408,3.28452,1
 58.21984,3.83000,      -0.57508,3.28447,1
 58.32036,3.84000,      -0.57607,3.28441,1
 58.42098,3.85000,      -0.57717,3.28436,1
 58.52156,3.86000,      -0.57827,3.28430,1
 58.62216,3.87000,      -0.57921,3.28424,1
 58.72280,3.88000,      -0.58018,3.28419,1
 58.82343,3.89000,      -0.58128,3.28413,1
 58.92403,3.90000,      -0.58253,3.28407,1
 59.02467,3.91000,      -0.58332,3.28402,1
 59.12526,3.92000,      -0.58414,3.28396,1
 59.22590,3.93000,      -0.58570,3.28390,1
 59.32649,3.94000,      -0.58631,3.28385,1
 59.42711,3.95000,      -0.58769,3.28379,1
 59.52775,3.96000,      -0.58853,3.28373,1
 59.62836,3.97000,      -0.58942,3.28368,1
 59.72897,3.98000,      -0.59081,3.28362,1
 59.82957,3.99000,      -0.59154,3.28356,1
 59.93015,4.00000,      -0.59261,3.28350,1
 60.03077,4.01000,      -0.59377,3.28345,1
 60.13141,4.02000,      -0.59489,3.28339,1
 60.23205,4.03000,      -0.59591,3.28333,1
 60.33267,4.04000,      -0.59683,3.28327,1
 60.43334,4.05000,      -0.59780,3.28322,1
 60.53395,4.06000,      -0.59882,3.28316,1
 60.63454,4.07000,      -0.59974,3.28310,1
 60.73510,4.08000,      -0.60092,3.28304,1
 60.83567,4.09000,      -0.60207,3.28298,1
 60.93631,4.10000,      -0.60312,3.28292,1
 61.03690,4.11000,      -0.60393,3.28287,1
 61.13751,4.12000,      -0.60490,3.28281,1
 61.23808,4.13000,      -0.60582,3.28275,1
 61.33869,4.14000,      -0.60687,3.28269,1
 61.43926,4.15000,      -0.60802,3.28263,1
 61.53980,4.16000,      -0.60902,3.28257,1
 61.64034,4.17000,      -0.60996,3.28251,1
 61.74089,4.18000,      -0.61090,3.28245,1
 61.84144,4.19000,      -0.61169,3.28239,1
 61.94198,4.20000,      -0.61274,3.28233,1
 62.04248,4.21000,      -0.61387,3.28227,1
 62.14295,4.22000,      -0.61492,3.28221,1
 62.24339,4.23000,      -0.61581,3.28215,1
 62.34390,4.24000,      -0.61681,3.28209,1
 62.44438,4.25000,      -0.61754,3.28203,1
 62.54490,4.26000,      -0.61854,3.28197,1
 62.64539,4.27000,      -0.61956,3.28191,1
 62.74590,4.28000,      -0.62046,3.28185,1
 62.84638,4.29000,      -0.62140,3.28179,1
 62.94690,4.30000,      -0.62245,3.28173,1
 63.04744,4.31000,      -0.62337,3.28167,1
 63.14798,4.32000,      -0.62429,3.28161,1
 63.24852,4.33000,      -0.62521,3.28155,1
 63.34902,4.34000,      -0.62639,3.28149,1
 63.44952,4.35000,      -0.62707,3.28143,1
 63.55000,4.36000,      -0.62807,3.28137,1
 63.65049,4.37000,      -0.63018,3.28131,1
 63.75098,4.38000,      -0.63331,3.28124,1
 63.85148,4.39000,      -0.63441,3.28118,1
 63.95198,4.40000,      -0.63577,3.28112,1
 64.05246,4.41000,      -0.63687,3.28106,1
 64.15297,4.42000,      -0.63758,3.28100,1
 64.25349,4.43000,      -0.63817,3.28094,1
 64.35402,4.44000,      -0.63878,3.28087,1
 64.45454,4.45000,      -0.63944,3.28081,1
 64.55507,4.46000,      -0.64015,3.28075,1
 64.65557,4.47000,      -0.64084,3.28069,1
 64.75615,4.48000,      -0.64147,3.28062,1
 64.85666,4.49000,      -0.64226,3.28056,1
 64.95713,4.50000,      -0.64305,3.28050,1
 65.05759,4.51000,      -0.64387,3.28044,1
 65.15808,4.52000,      -0.64453,3.28037,1
 65.25854,4.53000,      -0.64548,3.28031,1
 65.35903,4.54000,      -0.64637,3.28025,1
 65.45949,4.55000,      -0.64729,3.28018,1
 65.55997,4.56000,      -0.64808,3.28012,1
 65.66052,4.57000,      -0.64890,3.28006,1
 65.76105,4.58000,      -0.64961,3.27999,1
 65.86154,4.59000,      -0.65051,3.27993,1
 65.96202,4.60000,      -0.65146,3.27986,1
 66.06252,4.61000,      -0.65230,3.27980,1
 66.16307,4.62000,      -0.65312,3.27974,1
 66.26357,4.63000,      -0.65396,3.27967,1
 66.36405,4.64000,      -0.65478,3.27961,1
 66.46457,4.65000,      -0.65560,3.27954,1
 66.56508,4.66000,      -0.65641,3.27948,1
 66.66561,4.67000,      -0.65723,3.27941,1
 66.76616,4.68000,      -0.65805,3.27935,1
 66.86667,4.69000,      -0.65889,3.27929,1
 66.96726,4.70000,      -0.65979,3.27922,1
 67.06777,4.71000,      -0.66063,3.27916,1
 67.16831,4.72000,      -0.66150,3.27909,1
 67.26882,4.73000,      -0.66240,3.27903,1
 67.36939,4.74000,      -0.66332,3.27896,1
 67.47002,4.75000,      -0.66416,3.27889,1
 67.57057,4.76000,      -0.66501,3.27883,1
 67.67110,4.77000,      -0.66580,3.27876,1
 67.77161,4.78000,      -0.66659,3.27870,1
 67.87215,4.79000,      -0.66738,3.27863,1
 67.97270,4.80000,      -0.66833,3.27857,1
 68.07330,4.81000,      -0.66920,3.27850,1
 68.17382,4.82000,      -0.67002,3.27843,1
 68.27439,4.83000,      -0.67055,3.27837,1
 68.37502,4.84000,      -0.67153,3.27830,1
 68.47556,4.85000,      -0.67253,3.27823,1
 68.57611,4.86000,      -0.67309,3.27817,1
 68.67664,4.87000,      -0.67383,3.27810,1
 68.77718,4.88000,      -0.67465,3.27803,1
 68.87780,4.89000,      -0.67552,3.27797,1
 68.97839,4.90000,      -0.67639,3.27790,1
 69.07898,4.91000,      -0.67713,3.27783,1
 69.17957,4.92000,      -0.67785,3.27776,1
 69.28020,4.93000,      -0.67853,3.27770,1
 69.38080,4.94000,      -0.67917,3.27763,1
 69.48136,4.95000,      -0.68015,3.27756,1
 69.58193,4.96000,      -0.68089,3.27749,1
 69.68249,4.97000,      -0.68160,3.27743,1
 69.78307,4.98000,      -0.68240,3.27736,1
 69.88367,4.99000,      -0.68322,3.27729,1
 69.98425,5.00000,      -0.68427,3.27722,1
 70.08484,5.01000,      -0.68475,3.27715,1
 70.18539,5.02000,      -0.68536,3.27709,1
 70.28598,5.03000,      -0.68613,3.27702,1
 70.38651,5.04000,      -0.68690,3.27695,1
 70.48707,5.05000,      -0.68754,3.27688,1
 70.58759,5.06000,      -0.68825,3.27681,1
 70.68811,5.07000,      -0.68900,3.27674,1
 70.78866,5.08000,      -0.68966,3.27667,1
 70.88913,5.09000,      -0.69030,3.27660,1
 70.98959,5.10000,      -0.69096,3.27654,1
 71.09002,5.11000,      -0.69163,3.27647,1
 71.19048,5.12000,      -0.69208,3.27640,1
 71.29090,5.13000,      -0.69272,3.27633,1
 71.39131,5.14000,      -0.69362,3.27626,1
 71.49170,5.15000,      -0.69434,3.27619,1
 71.59218,5.16000,      -0.69487,3.27612,1
 71.69264,5.17000,      -0.69525,3.27605,1
 71.79300,5.18000,      -0.69612,3.27598,1
 71.89341,5.19000,      -0.69668,3.27591,1
 71.99380,5.20000,      -0.69730,3.27584,1
 72.09411,5.21000,      -0.69806,3.27577,1
 72.19446,5.22000,      -0.69870,3.27570,1
 72.29479,5.23000,      -0.69911,3.27563,1
 72.39507,5.24000,      -0.69949,3.27556,1
 72.49536,5.25000,      -0.70010,3.27549,1
 72.59569,5.26000,      -0.70066,3.27542,1
 72.69598,5.27000,      -0.70115,3.27534,1
 72.79631,5.28000,      -0.70189,3.27527,1
 72.89664,5.29000,      -0.70258,3.27520,1
 72.99690,5.30000,      -0.70319,3.27513,1
 73.09720,5.31000,      -0.70375,3.27506,1
 73.19754,5.32000,      -0.70385,3.27499,1
 73.29784,5.33000,      -0.70428,3.27492,1
 73.39813,5.34000,      -0.70487,3.27485,1
 73.49843,5.35000,      -0.70577,3.27477,1
 73.59866,5.36000,      -0.70615,3.27470,1
 73.69892,5.37000,      -0.70655,3.27463,1
 73.79920,5.38000,      -0.70717,3.27456,1
 73.89946,5.39000,      -0.70788,3.27449,1
 73.99970,5.40000,      -0.70842,3.27441,1
 74.10000,5.41000,      -0.70895,3.27434,1
 74.20033,5.42000,      -0.70905,3.27427,1
 74.30061,5.43000,      -0.70948,3.27420,1
 74.40093,5.44000,      -0.71002,3.27412,1
 74.50129,5.45000,      -0.71047,3.27405,1
 74.60164,5.46000,      -0.71085,3.27398,1
 74.70190,5.47000,      -0.71144,3.27391,1
 74.80216,5.48000,      -0.71188,3.27383,1
 74.90238,5.49000,      -0.71228,3.27376,1
 75.00264,5.50000,      -0.71264,3.27369,1
 75.10287,5.51000,      -0.71315,3.27361,1
 75.20303,5.52000,      -0.71358,3.27354,1
 75.30323,5.53000,      -0.71419,3.27347,1
 75.40344,5.54000,      -0.71434,3.27339,1
 75.50362,5.55000,      -0.71456,3.27332,1
 75.60384,5.56000,      -0.71492,3.27324,1
 75.70403,5.57000,      -0.71538,3.27317,1
 75.80420,5.58000,      -0.71584,3.27310,1
 75.90431,5.59000,      -0.71624,3.27302,1
 76.00444,5.60000,      -0.71667,3.27295,1
 76.10461,5.61000,      -0.71706,3.27287,1
 76.20471,5.62000,      -0.71746,3.27280,1
 76.30485,5.63000,      -0.71782,3.27272,1
 76.40493,5.64000,      -0.71791,3.27265,1
 76.50497,5.65000,      -0.71824,3.27258,1
 76.60502,5.66000,      -0.71852,3.27250,1
 76.70510,5.67000,      -0.71866,3.27243,1
 76.80518,5.68000,      -0.71902,3.27235,1
 76.90526,5.69000,      -0.71927,3.27228,1
 77.00539,5.70000,      -0.71965,3.27220,1
 77.10548,5.71000,      -0.72001,3.27213,1
 77.20562,5.72000,      -0.72031,3.27205,1
 77.30577,5.73000,      -0.72059,3.27197,1
 77.40587,5.74000,      -0.72084,3.27190,1
 77.50598,5.75000,      -0.72101,3.27182,1
 77.60611,5.76000,      -0.72121,3.27175,1
 77.70621,5.77000,      -0.72146,3.27167,1
 77.80634,5.78000,      -0.72171,3.27159,1
 77.90651,5.79000,      -0.72199,3.27152,1
 78.00669,5.80000,      -0.72216,3.27144,1
 78.10680,5.81000,      -0.72247,3.27137,1
 78.20685,5.82000,      -0.72262,3.27129,1
 78.30695,5.83000,      -0.72292,3.27121,1
 78.40708,5.84000,      -0.72299,3.27114,1
 78.50718,5.85000,      -0.72314,3.27106,1
 78.60726,5.86000,      -0.72328,3.27098,1
 78.70741,5.87000,      -0.72346,3.27091,1
 78.80751,5.88000,      -0.72363,3.27083,1
 78.90762,5.89000,      -0.72378,3.27075,1
 79.00766,5.90000,      -0.72408,3.27067,1
 79.10774,5.91000,      -0.72420,3.27060,1
 79.20780,5.92000,      -0.72430,3.27052,1
 79.30787,5.93000,      -0.72458,3.27044,1
 79.40792,5.94000,      -0.72470,3.27036,1
 79.50803,5.95000,      -0.72487,3.27028,1
 79.60811,5.96000,      -0.72510,3.27021,1
 79.70818,5.97000,      -0.72525,3.27013,1
 79.80826,5.98000,      -0.72527,3.27005,1
 79.90831,5.99000,      -0.72534,3.26997,1
 80.00838,6.00000,      -0.72548,3.26989,1
 80.10846,6.01000,      -0.72558,3.26982,1
 80.20857,6.02000,      -0.72570,3.26974,1
 80.30870,6.03000,      -0.72580,3.26966,1
 80.40885,6.04000,      -0.72579,3.26958,1
 80.50900,6.05000,      -0.72586,3.26950,1
 80.60915,6.06000,      -0.72598,3.26942,1
 80.70926,6.07000,      -0.72600,3.26934,1
 80.80943,6.08000,      -0.72602,3.26926,1
 80.90957,6.09000,      -0.72609,3.26918,1
 81.00975,6.10000,      -0.72621,3.26910,1
 81.10997,6.11000,      -0.72631,3.26902,1
 81.21015,6.12000,      -0.72625,3.26894,1
 81.31029,6.13000,      -0.72619,3.26887,1
 81.41057,6.14000,      -0.72615,3.26879,1
 81.51082,6.15000,      -0.72615,3.26870,1
 81.61108,6.16000,      -0.72624,3.26862,1
 81.71133,6.17000,      -0.72626,3.26854,1
 81.81156,6.18000,      -0.72610,3.26846,1
 81.91184,6.19000,      -0.72612,3.26838,1
 82.01215,6.20000,      -0.72606,3.26830,1
 82.11244,6.21000,      -0.72605,3.26822,1
 82.21274,6.22000,      -0.72609,3.26814,1
 82.31307,6.23000,      -0.72601,3.26806,1
 82.41333,6.24000,      -0.72595,3.26798,1
 82.51362,6.25000,      -0.72597,3.26790,1
 82.61397,6.26000,      -0.72588,3.26782,1
 82.71428,6.27000,      -0.72582,3.26774,1
 82.81456,6.28000,      -0.72566,3.26765,1
 82.91489,6.29000,      -0.72563,3.26757,1
 83.01523,6.30000,      -0.72557,3.26749,1
 83.11557,6.31000,      -0.72548,3.26741,1
 83.21587,6.32000,      -0.72537,3.26733,1
 83.31625,6.33000,      -0.72526,3.26724,1
 83.41656,6.34000,      -0.72486,3.26716,1
 83.51682,6.35000,      -0.72465,3.26708,1
 83.61710,6.36000,      -0.72477,3.26700,1
 83.71736,6.37000,      -0.72474,3.26692,1
 83.81767,6.38000,      -0.72457,3.26683,1
 83.91797,6.39000,      -0.72438,3.26675,1
 84.01825,6.40000,      -0.72420,3.26667,1
 84.11852,6.41000,      -0.72398,3.26658,1
 84.21880,6.42000,      -0.72361,3.26650,1
 84.31911,6.43000,      -0.72350,3.26642,1
 84.41934,6.44000,      -0.72331,3.26634,1
 84.51957,6.45000,      -0.72330,3.26625,1
 84.61979,6.46000,      -0.72322,3.26617,1
 84.71998,6.47000,      -0.72303,3.26609,1
 84.82023,6.48000,      -0.72273,3.26600,1
 84.92043,6.49000,      -0.72257,3.26592,1
 85.02059,6.50000,      -0.72249,3.26583,1
 85.12074,6.51000,      -0.72230,3.26575,1
 85.22089,6.52000,      -0.72192,3.26567,1
 85.32097,6.53000,      -0.72166,3.26558,1
 85.42103,6.54000,      -0.72134,3.26550,1
 85.52111,6.55000,      -0.72125,3.26541,1
 85.62118,6.56000,      -0.72086,3.26533,1
 85.72121,6.57000,      -0.72056,3.26525,1
 85.82125,6.58000,      -0.72048,3.26516,1
 85.92126,6.59000,      -0.72031,3.26508,1
 86.02131,6.60000,      -0.71989,3.26499,1
 86.12134,6.61000,      -0.71941,3.26491,1
 86.22134,6.62000,      -0.71896,3.26482,1
 86.32131,6.63000,      -0.71880,3.26474,1
 86.42129,6.64000,      -0.71861,3.26465,1
 86.52128,6.65000,      -0.71842,3.26457,1
 86.62131,6.66000,      -0.71813,3.26448,1
 86.72133,6.67000,      -0.71771,3.26440,1
 86.82130,6.68000,      -0.71736,3.26431,1
 86.92128,6.69000,      -0.71696,3.26423,1
 87.02121,6.70000,      -0.71680,3.26414,1
 87.12126,6.71000,      -0.71659,3.26406,1
 87.22131,6.72000,      -0.71621,3.26397,1
 87.32134,6.73000,      -0.71576,3.26388,1
 87.42139,6.74000,      -0.71537,3.26380,1
 87.52139,6.75000,      -0.71526,3.26371,1
 87.62148,6.76000,      -0.71494,3.26362,1
 87.72149,6.77000,      -0.71451,3.26354,1
 87.82152,6.78000,      -0.71396,3.26345,1
 87.92156,6.79000,      -0.71341,3.26337,1
 88.02157,6.80000,      -0.71348,3.26328,1
 88.12161,6.81000,      -0.71329,3.26319,1
 88.22162,6.82000,      -0.71287,3.26310,1
 88.32167,6.83000,      -0.71244,3.26302,1
 88.42172,6.84000,      -0.71204,3.26293,1
 88.52172,6.85000,      -0.71154,3.26284,1
 88.62174,6.86000,      -0.71120,3.26276,1
 88.72179,6.87000,      -0.71106,3.26267,1
 88.82187,6.88000,      -0.71069,3.26258,1
 88.92195,6.89000,      -0.71021,3.26249,1
 89.02207,6.90000,      -0.70956,3.26241,1
 89.12210,6.91000,      -0.70942,3.26232,1
 89.22216,6.92000,      -0.70902,3.26223,1
 89.32221,6.93000,      -0.70834,3.26214,1
 89.42226,6.94000,      -0.70812,3.26205,1
 89.52233,6.95000,      -0.70772,3.26197,1
 89.62239,6.96000,      -0.70730,3.26188,1
 89.72244,6.97000,      -0.70672,3.26179,1
 89.82254,6.98000,      -0.70632,3.26170,1
 89.92266,6.99000,      -0.70593,3.26161,1
 90.02277,7.00000,      -0.70555,3.26152,1
 90.12289,7.01000,      -0.70516,3.26143,1
 90.22303,7.02000,      -0.70463,3.26134,1
 90.32320,7.03000,      -0.70423,3.26125,1
 90.42333,7.04000,      -0.70389,3.26117,1
 90.52349,7.05000,      -0.70344,3.26108,1
 90.62369,7.06000,      -0.70301,3.26099,1
 90.72392,7.07000,      -0.70259,3.26090,1
 90.82408,7.08000,      -0.70217,3.26081,1
 90.92425,7.09000,      -0.70169,3.26072,1
 91.02439,7.10000,      -0.70119,3.26063,1
 91.12457,7.11000,      -0.70082,3.26054,1
 91.22474,7.12000,      -0.70042,3.26045,1
 91.32498,7.13000,      -0.69987,3.26036,1
 91.42521,7.14000,      -0.69952,3.26027,1
 91.52543,7.15000,      -0.69918,3.26018,1
 91.62562,7.16000,      -0.69870,3.26009,1
 91.72587,7.17000,      -0.69830,3.25999,1
 91.82600,7.18000,      -0.69796,3.25990,1
 91.92618,7.19000,      -0.69733,3.25981,1
 92.02639,7.20000,      -0.69690,3.25972,1
 92.12654,7.21000,      -0.69640,3.25963,1
 92.22675,7.22000,      -0.69580,3.25954,1
 92.32689,7.23000,      -0.69527,3.25945,1
 92.42707,7.24000,      -0.69461,3.25936,1
 92.52723,7.25000,      -0.69403,3.25927,1
 92.62738,7.26000,      -0.69361,3.25917,1
 92.72751,7.27000,      -0.69321,3.25908,1
 92.82762,7.28000,      -0.69273,3.25899,1
 92.92775,7.29000,      -0.69226,3.25890,1
 93.02792,7.30000,      -0.69181,3.25881,1
 93.12803,7.31000,      -0.69123,3.25871,1
 93.22810,7.32000,      -0.69054,3.25862,1
 93.32811,7.33000,      -0.68988,3.25853,1
 93.42813,7.34000,      -0.68938,3.25844,1
 93.52810,7.35000,      -0.68893,3.25835,1
 93.62807,7.36000,      -0.68838,3.25825,1
 93.72803,7.37000,      -0.68793,3.25816,1
 93.82805,7.38000,      -0.68730,3.25807,1
 93.92802,7.39000,      -0.68677,3.25798,1
 94.02797,7.40000,      -0.68627,3.25788,1
 94.12789,7.41000,      -0.68574,3.25779,1
 94.22779,7.42000,      -0.68500,3.25770,1
 94.32770,7.43000,      -0.68437,3.25760,1
 94.42757,7.44000,      -0.68379,3.25751,1
 94.52743,7.45000,      -0.68342,3.25742,1
 94.62726,7.46000,      -0.68302,3.25732,1
 94.72711,7.47000,      -0.68236,3.25723,1
 94.82695,7.48000,      -0.68183,3.25714,1
 94.92680,7.49000,      -0.68112,3.25704,1
 95.02661,7.50000,      -0.68054,3.25695,1
 95.12634,7.51000,      -0.67999,3.25685,1
 95.22620,7.52000,      -0.67933,3.25676,1
 95.32602,7.53000,      -0.67875,3.25667,1
 95.42580,7.54000,      -0.67811,3.25657,1
 95.52566,7.55000,      -0.67751,3.25648,1
 95.62549,7.56000,      -0.67703,3.25638,1
 95.72529,7.57000,      -0.67650,3.25629,1
 95.82507,7.58000,      -0.67579,3.25619,1
 95.92487,7.59000,      -0.67495,3.25610,1
 96.02464,7.60000,      -0.67463,3.25601,1
 96.12443,7.61000,      -0.67415,3.25591,1
 96.22416,7.62000,      -0.67329,3.25582,1
 96.32398,7.63000,      -0.67257,3.25572,1
 96.42380,7.64000,      -0.67197,3.25563,1
 96.52361,7.65000,      -0.67133,3.25553,1
 96.62341,7.66000,      -0.67078,3.25543,1
 96.72320,7.67000,      -0.67015,3.25534,1
 96.82295,7.68000,      -0.66954,3.25524,1
 96.92269,7.69000,      -0.66883,3.25515,1
 97.02244,7.70000,      -0.66820,3.25505,1
 97.12221,7.71000,      -0.66764,3.25496,1
 97.22195,7.72000,      -0.66698,3.25486,1
 97.32170,7.73000,      -0.66661,3.25476,1
 97.42144,7.74000,      -0.66577,3.25467,1
 97.52123,7.75000,      -0.66506,3.25457,1
 97.62102,7.76000,      -0.66447,3.25448,1
 97.72079,7.77000,      -0.66384,3.25438,1
 97.82061,7.78000,      -0.66318,3.25428,1
 97.92043,7.79000,      -0.66252,3.25419,1
 98.02025,7.80000,      -0.66179,3.25409,1
 98.12005,7.81000,      -0.66110,3.25399,1
 98.21993,7.82000,      -0.66036,3.25389,1
 98.31974,7.83000,      -0.65965,3.25380,1
 98.41951,7.84000,      -0.65899,3.25370,1
 98.51936,7.85000,      -0.65836,3.25360,1
 98.61921,7.86000,      -0.65788,3.25351,1
 98.71910,7.87000,      -0.65733,3.25341,1
 98.81898,7.88000,      -0.65675,3.25331,1
 98.91890,7.89000,      -0.65635,3.25321,1
 99.01885,7.90000,      -0.65587,3.25311,1
 99.11880,7.91000,      -0.65542,3.25302,1
 99.21877,7.92000,      -0.65494,3.25292,1
 99.31875,7.93000,      -0.65447,3.25282,1
 99.41875,7.94000,      -0.65407,3.25272,1
 99.51880,7.95000,      -0.65367,3.25262,1
 99.61880,7.96000,      -0.65325,3.25252,1
 99.71887,7.97000,      -0.65285,3.25243,1
 99.81897,7.98000,      -0.65250,3.25233,1
 99.91902,7.99000,      -0.65203,3.25223,1
100.01910,8.00000,      -0.65155,3.25213,1
100.11921,8.01000,      -0.65100,3.25203,1
100.21930,8.02000,      -0.65044,3.25193,1
100.31938,8.03000,      -0.64999,3.25183,1
100.41951,8.04000,      -0.64944,3.25173,1
100.51964,8.05000,      -0.64896,3.25163,1
100.61977,8.06000,      -0.64846,3.25153,1
100.71989,8.07000,      -0.64788,3.25143,1
100.81993,8.08000,      -0.64729,3.25133,1
100.92007,8.09000,      -0.64658,3.25123,1
101.02018,8.10000,      -0.64590,3.25113,1
101.12028,8.11000,      -0.64511,3.25103,1
101.22039,8.12000,      -0.64439,3.25093,1
101.32057,8.13000,      -0.64368,3.25083,1
101.42079,8.14000,      -0.64258,3.25073,1
101.52093,8.15000,      -0.64202,3.25063,1
101.62110,8.16000,      -0.64118,3.25053,1
101.72123,8.17000,      -0.64015,3.25043,1
101.82136,8.18000,      -0.63928,3.25033,1
101.92154,8.19000,      -0.63847,3.25022,1
102.02174,8.20000,      -0.63765,3.25012,1
102.12192,8.21000,      -0.63678,3.25002,1
102.22213,8.22000,      -0.63591,3.24992,1
102.32238,8.23000,      -0.63504,3.24982,1
102.42257,8.24000,      -0.63462,3.24972,1
102.52275,8.25000,      -0.63377,3.24961,1
102.62297,8.26000,      -0.63288,3.24951,1
102.72316,8.27000,      -0.63180,3.24941,1
102.82338,8.28000,      -0.63096,3.24931,1
102.92364,8.29000,      -0.63014,3.24921,1
103.02384,8.30000,      -0.63037,3.24910,1
103.12407,8.31000,      -0.63042,3.24900,1
103.22438,8.32000,      -0.62923,3.24890,1
103.32459,8.33000,      -0.62839,3.24880,1
103.42482,8.34000,      -0.62757,3.24869,1
103.52503,8.35000,      -0.62670,3.24859,1
103.62529,8.36000,      -0.62599,3.24849,1
103.72557,8.37000,      -0.62528,3.24838,1
103.82589,8.38000,      -0.62446,3.24828,1
103.92615,8.39000,      -0.62375,3.24818,1
104.02641,8.40000,      -0.62288,3.24807,1
104.12670,8.41000,      -0.62214,3.24797,1
104.22700,8.42000,      -0.62137,3.24787,1
104.32726,8.43000,      -0.62066,3.24776,1
104.42754,8.44000,      -0.61982,3.24766,1
104.52787,8.45000,      -0.61910,3.24755,1
104.62815,8.46000,      -0.61837,3.24745,1
104.72848,8.47000,      -0.61763,3.24735,1
104.82879,8.48000,      -0.61725,3.24724,1
104.92913,8.49000,      -0.61701,3.24714,1
105.02946,8.50000,      -0.61591,3.24703,1
105.12982,8.51000,      -0.61498,3.24693,1
105.23016,8.52000,      -0.61419,3.24682,1
105.33048,8.53000,      -0.61366,3.24672,1
105.43079,8.54000,      -0.61295,3.24661,1
105.53111,8.55000,      -0.61218,3.24651,1
105.63139,8.56000,      -0.61139,3.24640,1
105.73167,8.57000,      -0.61060,3.24630,1
105.83197,8.58000,      -0.60991,3.24619,1
105.93228,8.59000,      -0.60910,3.24609,1
106.03257,8.60000,      -0.60836,3.24598,1
106.13285,8.61000,      -0.60767,3.24588,1
106.23308,8.62000,      -0.60693,3.24577,1
106.33333,8.63000,      -0.60603,3.24567,1
106.43361,8.64000,      -0.60522,3.24556,1
106.53389,8.65000,      -0.60450,3.24545,1
106.63411,8.66000,      -0.60402,3.24535,1
106.73439,8.67000,      -0.60308,3.24524,1
106.83464,8.68000,      -0.60215,3.24514,1
106.93487,8.69000,      -0.60136,3.24503,1
107.03502,8.70000,      -0.60054,3.24492,1
107.13515,8.71000,      -0.59980,3.24482,1
107.23533,8.72000,      -0.59893,3.24471,1
107.33546,8.73000,      -0.59816,3.24460,1
107.43564,8.74000,      -0.59737,3.24450,1
107.53580,8.75000,      -0.59653,3.24439,1
107.63597,8.76000,      -0.59574,3.24428,1
107.73611,8.77000,      -0.59484,3.24417,1
107.83621,8.78000,      -0.59391,3.24407,1
107.93634,8.79000,      -0.59299,3.24396,1
108.03643,8.80000,      -0.59217,3.24385,1
108.13652,8.81000,      -0.59138,3.24375,1
108.23661,8.82000,      -0.59053,3.24364,1
108.33664,8.83000,      -0.58977,3.24353,1
108.43664,8.84000,      -0.58905,3.24342,1
108.53666,8.85000,      -0.58826,3.24331,1
108.63667,8.86000,      -0.58736,3.24321,1
108.73666,8.87000,      -0.58652,3.24310,1
108.83664,8.88000,      -0.58572,3.24299,1
108.93662,8.89000,      -0.58496,3.24288,1
109.03674,8.90000,      -0.58416,3.24277,1
109.13679,8.91000,      -0.58329,3.24267,1
109.23682,8.92000,      -0.58242,3.24256,1
109.33684,8.93000,      -0.58158,3.24245,1
109.43687,8.94000,      -0.58083,3.24234,1
109.53685,8.95000,      -0.58007,3.24223,1
109.63684,8.96000,      -0.57925,3.24212,1
109.73682,8.97000,      -0.57848,3.24201,1
109.83679,8.98000,      -0.57761,3.24190,1
109.93674,8.99000,      -0.57669,3.24180,1
110.03677,9.00000,      -0.57595,3.24169,1
110.13679,9.01000,      -0.57515,3.24158,1
110.23679,9.02000,      -0.57444,3.24147,1
110.33677,9.03000,      -0.57362,3.24136,1
110.43677,9.04000,      -0.57269,3.24125,1
110.53674,9.05000,      -0.57166,3.24114,1
110.63675,9.06000,      -0.57129,3.24103,1
110.73680,9.07000,      -0.57031,3.24092,1
110.83679,9.08000,      -0.56936,3.24081,1
110.93684,9.09000,      -0.56825,3.24070,1
111.03684,9.10000,      -0.56762,3.24059,1
111.13684,9.11000,      -0.56719,3.24048,1
111.23687,9.12000,      -0.56600,3.24037,1
111.33688,9.13000,      -0.56516,3.24026,1
111.43689,9.14000,      -0.56428,3.24015,1
111.53684,9.15000,      -0.56338,3.24003,1
111.63682,9.16000,      -0.56254,3.23992,1
111.73684,9.17000,      -0.56161,3.23981,1
111.83684,9.18000,      -0.56071,3.23970,1
111.93685,9.19000,      -0.56000,3.23959,1
112.03680,9.20000,      -0.55905,3.23948,1
112.13675,9.21000,      -0.55823,3.23937,1
112.23669,9.22000,      -0.55738,3.23926,1
112.33664,9.23000,      -0.55658,3.23914,1
112.43657,9.24000,      -0.55571,3.23903,1
112.53659,9.25000,      -0.55481,3.23892,1
112.63654,9.26000,      -0.55391,3.23881,1
112.73644,9.27000,      -0.55304,3.23870,1
112.83638,9.28000,      -0.55217,3.23859,1
112.93633,9.29000,      -0.55121,3.23847,1
113.03620,9.30000,      -0.55018,3.23836,1
113.13603,9.31000,      -0.54942,3.23825,1
113.23589,9.32000,      -0.54849,3.23814,1
113.33580,9.33000,      -0.54769,3.23802,1
113.43564,9.34000,      -0.54682,3.23791,1
113.53552,9.35000,      -0.54589,3.23780,1
113.63533,9.36000,      -0.54515,3.23769,1
113.73518,9.37000,      -0.54438,3.23757,1
113.83507,9.38000,      -0.54348,3.23746,1
113.93484,9.39000,      -0.54256,3.23735,1
114.03469,9.40000,      -0.54150,3.23723,1
114.13451,9.41000,      -0.54097,3.23712,1
114.23428,9.42000,      -0.53973,3.23701,1
114.33402,9.43000,      -0.53880,3.23689,1
114.43380,9.44000,      -0.53779,3.23678,1
114.53351,9.45000,      -0.53681,3.23667,1
114.63321,9.46000,      -0.53597,3.23655,1
114.73293,9.47000,      -0.53499,3.23644,1
114.83270,9.48000,      -0.53406,3.23633,1
114.93243,9.49000,      -0.53308,3.23621,1
115.03218,9.50000,      -0.53221,3.23610,1
115.13192,9.51000,      -0.53131,3.23598,1
115.23162,9.52000,      -0.53038,3.23587,1
115.33129,9.53000,      -0.52950,3.23576,1
115.43102,9.54000,      -0.52855,3.23564,1
115.53075,9.55000,      -0.52765,3.23553,1
115.63054,9.56000,      -0.52675,3.23541,1
115.73031,9.57000,      -0.52587,3.23530,1
115.82998,9.58000,      -0.52500,3.23518,1
115.92975,9.59000,      -0.52410,3.23507,1
116.02948,9.60000,      -0.52312,3.23495,1
116.12923,9.61000,      -0.52230,3.23484,1
116.22900,9.62000,      -0.52163,3.23472,1
116.32879,9.63000,      -0.52057,3.23461,1
116.42864,9.64000,      -0.51954,3.23449,1
116.52848,9.65000,      -0.51867,3.23438,1
116.62833,9.66000,      -0.51782,3.23426,1
116.72815,9.67000,      -0.51694,3.23414,1
116.82795,9.68000,      -0.51601,3.23403,1
116.92782,9.69000,      -0.51509,3.23391,1
117.02766,9.70000,      -0.51419,3.23380,1
117.12754,9.71000,      -0.51328,3.23368,1
117.22741,9.72000,      -0.51243,3.23356,1
117.32731,9.73000,      -0.51166,3.23345,1
117.42713,9.74000,      -0.51087,3.23333,1
117.52698,9.75000,      -0.50978,3.23321,1
117.62684,9.76000,      -0.50922,3.23310,1
117.72666,9.77000,      -0.50806,3.23298,1
117.82659,9.78000,      -0.50700,3.23286,1
117.92648,9.79000,      -0.50612,3.23275,1
118.02636,9.80000,      -0.50517,3.23263,1
118.12628,9.81000,      -0.50434,3.23251,1
118.22626,9.82000,      -0.50347,3.23239,1
118.32621,9.83000,      -0.50254,3.23228,1
118.42618,9.84000,      -0.50159,3.23216,1
118.52607,9.85000,      -0.50068,3.23204,1
118.62603,9.86000,      -0.49994,3.23192,1
118.72598,9.87000,      -0.49898,3.23181,1
118.82592,9.88000,      -0.49798,3.23169,1
118.92595,9.89000,      -0.49726,3.23157,1
119.02536,9.90000,      -0.49638,3.23145,1
119.12524,9.91000,      -0.49532,3.23133,1
119.22514,9.92000,      -0.49447,3.23121,1
119.32509,9.93000,      -0.49352,3.23110,1
119.42500,9.94000,      -0.49259,3.23098,1
119.52490,9.95000,      -0.49163,3.23086,1
119.62456,9.96000,      -0.49086,3.23074,1
119.72400,9.97000,      -0.49004,3.23062,1
119.82331,9.98000,      -0.48911,3.23050,1
119.92143,9.99000,      -0.48813,3.23039,1
119.99200,9.99917,      -0.48750,3.23030,1