File: DSC图/ExpAll_常规2.csv
#EXPORTTYPE:                 ,ALL
#FILE:                       ,常规2.ngb-sd7
#FORMAT:                     ,NETZSCH5
#FTYPE:                      ,ANSI
#IDENTITY:                   ,2
#DECIMAL:                    ,POINT
#SEPARATOR:                  ,COMMA
#MTYPE:                      ,DSC
#INSTRUMENT:                 ,NETZSCH DSC 204F1 Phoenix
#PROJECT:                    ,1
#DATE/TIME:                  ,2023/4/24 15:14:12 (UTC+8)
#CORR. FILE:                 ,
#TEMPCAL:                    ,applied
#SENSITIVITY:                ,applied
#LABORATORY:                 ,
#OPERATOR:                   ,0
#REMARK:                     ,
#SAMPLE:                     ,常规
#SAMPLE MASS /mg:            ,8.49
#MATERIAL:                   ,
#REFERENCE:                  ,
#REFERENCE MASS /mg:         ,0
#TYPE OF CRUCIBLE:           ,Concavus Pan Al, open
#SAMPLE CRUCIBLE MASS /mg:   ,0
#REFERENCE CRUCIBLE MASS /mg:,0
#M.RANGE /μV:                ,5000
#TAU-R:                      ,---
#CORR. CODE:                 ,000
#EXO:                        ,+1
#RANGE:                      ,20°C/10.0(K/min)/120°C
#SEGMENT:                    ,S1/1
#SEG. 1:                     ,20°C/10.0(K/min)/120°C

#*RESULTS:     ,File,Segment,Result,Unit,Y_value,Unit ,Range_Xmin,Unit,Range_Xmax,Unit,Range_Ymin,Unit ,Range_Ymax,Unit
#*Area (DSC)(o),常规2 ,1      ,-51.25,J/g ,-      ,-    ,44.4      ,°C  ,115.2     ,°C  ,-0.2609   ,mW/mg,-0.4539   ,mW/mg
#*Onset (DSC)  ,常规2 ,1      ,44.4  ,°C  ,-0.2548,mW/mg,35.9      ,°C  ,86.2      ,°C  ,-0.209    ,mW/mg,-0.5754   ,mW/mg
#*Peak (DSC)   ,常规2 ,1      ,87.7  ,°C  ,-0.5759,mW/mg,35.9      ,°C  ,104.0     ,°C  ,-0.209    ,mW/mg,-0.5238   ,mW/mg
#*End (DSC)    ,常规2 ,1      ,115.2 ,°C  ,-0.454 ,mW/mg,88.1      ,°C  ,120.0     ,°C  ,-0.5755   ,mW/mg,-0.4175   ,mW/mg

##Temp./°C,Time/min,DSC/(mW/mg),Sensit./(uV/mW),Segment
 19.85800,0.00000,-5.894199e-002,3.29776,1
 19.85929,0.01000,-5.886052e-002,3.29775,1
 19.86038,0.02000,-5.883355e-002,3.29775,1
 19.86426,0.03000,-5.869759e-002,3.29775,1
 19.87560,0.04000,-5.842567e-002,3.29775,1
 19.89774,0.05000,-5.714721e-002,3.29775,1
 19.93184,0.06000,-5.453464e-002,3.29774,1
 19.97714,0.07000,-4.974543e-002,3.29774,1
 20.03237,0.08000,-4.384065e-002,3.29773,1
 20.09609,0.09000,-3.641318e-002,3.29772,1
 20.16695,0.10000,-2.819850e-002,3.29771,1
 20.22170,0.11000,-1.971459e-002,3.29770,1
 20.28146,0.12000,-1.136801e-002,3.29770,1
 20.34639,0.13000,-4.004630e-003,3.29769,1
 20.41651,0.14000, 2.076625e-003,3.29768,1
 20.49170,0.15000, 6.929971e-003,3.29767,1
 20.57167,0.16000, 1.039245e-002,3.29765,1
 20.65613,0.17000, 1.238286e-002,3.29764,1
 20.74461,0.18000, 1.290007e-002,3.29763,1
 20.83654,0.19000, 1.202720e-002,3.29761,1
 20.93152,0.20000, 1.014576e-002,3.29760,1
 21.02903,0.21000, 7.037158e-003,3.29759,1
 21.12849,0.22000, 2.975291e-003,3.29757,1
 21.22980,0.23000,-1.877743e-003,3.29756,1
 21.33241,0.24000,-7.357889e-003,3.29754,1
 21.43613,0.25000,-1.338285e-002,3.29752,1
 21.54077,0.26000,-1.992593e-002,3.29751,1
 21.64605,0.27000,-2.649633e-002,3.29749,1
 21.75179,0.28000,-3.303954e-002,3.29747,1
 21.85789,0.29000,-4.001886e-002,3.29746,1
 21.96425,0.30000,-4.661672e-002,3.29744,1
 22.07082,0.31000,-5.318740e-002,3.29742,1
 22.17754,0.32000,-5.973062e-002,3.29741,1
 22.28434,0.33000,-6.597469e-002,3.29739,1
 22.39113,0.34000,-7.205503e-002,3.29737,1
 22.49789,0.35000,-7.761790e-002,3.29735,1
 22.60474,0.36000,-8.320725e-002,3.29733,1
 22.71152,0.37000,-8.819765e-002,3.29732,1
 22.81831,0.38000,-9.321508e-002,3.29730,1
 22.92507,0.39000,-9.793306e-002,3.29728,1
 23.03175,0.40000,      -0.10221,3.29726,1
 23.13839,0.41000,      -0.10642,3.29724,1
 23.24508,0.42000,      -0.11048,3.29723,1
 23.35167,0.43000,      -0.11413,3.29721,1
 23.45825,0.44000,      -0.11765,3.29719,1
 23.56485,0.45000,      -0.12014,3.29717,1
 23.67143,0.46000,      -0.12319,3.29715,1
 23.77803,0.47000,      -0.12628,3.29713,1
 23.88469,0.48000,      -0.12909,3.29711,1
 23.99128,0.49000,      -0.13181,3.29709,1
 24.09785,0.50000,      -0.13381,3.29707,1
 24.20436,0.51000,      -0.13602,3.29705,1
 24.31092,0.52000,      -0.13807,3.29703,1
 24.41749,0.53000,      -0.14000,3.29701,1
 24.52407,0.54000,      -0.14197,3.29699,1
 24.63070,0.55000,      -0.14355,3.29697,1
 24.73728,0.56000,      -0.14511,3.29695,1
 24.84389,0.57000,      -0.14670,3.29693,1
 24.95048,0.58000,      -0.14825,3.29691,1
 25.05700,0.59000,      -0.14951,3.29689,1
 25.16361,0.60000,      -0.15085,3.29687,1
 25.27023,0.61000,      -0.15192,3.29685,1
 25.37680,0.62000,      -0.15306,3.29683,1
 25.48334,0.63000,      -0.15413,3.29681,1
 25.58989,0.64000,      -0.15522,3.29678,1
 25.69643,0.65000,      -0.15629,3.29676,1
 25.80290,0.66000,      -0.15722,3.29674,1
 25.90939,0.67000,      -0.15815,3.29672,1
 26.01587,0.68000,      -0.15911,3.29670,1
 26.12231,0.69000,      -0.15985,3.29668,1
 26.22874,0.70000,      -0.16089,3.29665,1
 26.33523,0.71000,      -0.16184,3.29663,1
 26.44159,0.72000,      -0.16228,3.29661,1
 26.54790,0.73000,      -0.16313,3.29659,1
 26.65421,0.74000,      -0.16376,3.29656,1
 26.76046,0.75000,      -0.16447,3.29654,1
 26.86672,0.76000,      -0.16538,3.29652,1
 26.97290,0.77000,      -0.16604,3.29650,1
 27.07902,0.78000,      -0.16680,3.29647,1
 27.18515,0.79000,      -0.16754,3.29645,1
 27.29123,0.80000,      -0.16801,3.29643,1
 27.39730,0.81000,      -0.16864,3.29640,1
 27.50333,0.82000,      -0.16935,3.29638,1
 27.60930,0.83000,      -0.16993,3.29636,1
 27.71531,0.84000,      -0.17048,3.29633,1
 27.82133,0.85000,      -0.17116,3.29631,1
 27.92723,0.86000,      -0.17174,3.29629,1
 28.03307,0.87000,      -0.17229,3.29626,1
 28.13887,0.88000,      -0.17283,3.29624,1
 28.24469,0.89000,      -0.17349,3.29621,1
 28.35049,0.90000,      -0.17380,3.29619,1
 28.45620,0.91000,      -0.17445,3.29616,1
 28.56187,0.92000,      -0.17498,3.29614,1
 28.66756,0.93000,      -0.17550,3.29612,1
 28.77320,0.94000,      -0.17610,3.29609,1
 28.87875,0.95000,      -0.17670,3.29607,1
 28.98423,0.96000,      -0.17744,3.29604,1
 29.08971,0.97000,      -0.17783,3.29602,1
 29.19513,0.98000,      -0.17835,3.29599,1
 29.30064,0.99000,      -0.17887,3.29596,1
 29.40602,1.00000,      -0.17945,3.29594,1
 29.51131,1.01000,      -0.17997,3.29591,1
 29.61661,1.02000,      -0.18041,3.29589,1
 29.72187,1.03000,      -0.18088,3.29586,1
 29.82710,1.04000,      -0.18148,3.29584,1
 29.93220,1.05000,      -0.18197,3.29581,1
 30.03730,1.06000,      -0.18249,3.29578,1
 30.14243,1.07000,      -0.18304,3.29576,1
 30.24746,1.08000,      -0.18329,3.29573,1
 30.35238,1.09000,      -0.18401,3.29571,1
 30.45726,1.10000,      -0.18461,3.29568,1
 30.56215,1.11000,      -0.18472,3.29565,1
 30.66695,1.12000,      -0.18522,3.29563,1
 30.77167,1.13000,      -0.18582,3.29560,1
 30.87626,1.14000,      -0.18645,3.29557,1
 30.98089,1.15000,      -0.18697,3.29554,1
 31.08546,1.16000,      -0.18738,3.29552,1
 31.18998,1.17000,      -0.18810,3.29549,1
 31.29443,1.18000,      -0.18856,3.29546,1
 31.39880,1.19000,      -0.18919,3.29544,1
 31.50310,1.20000,      -0.18950,3.29541,1
 31.60741,1.21000,      -0.18969,3.29538,1
 31.71162,1.22000,      -0.19002,3.29535,1
 31.81579,1.23000,      -0.19049,3.29532,1
 31.91989,1.24000,      -0.19106,3.29530,1
 32.02393,1.25000,      -0.19164,3.29527,1
 32.12793,1.26000,      -0.19205,3.29524,1
 32.23185,1.27000,      -0.19249,3.29521,1
 32.33574,1.28000,      -0.19293,3.29518,1
 32.43962,1.29000,      -0.19351,3.29515,1
 32.54346,1.30000,      -0.19406,3.29513,1
 32.64720,1.31000,      -0.19450,3.29510,1
 32.75092,1.32000,      -0.19485,3.29507,1
 32.85462,1.33000,      -0.19521,3.29504,1
 32.95834,1.34000,      -0.19565,3.29501,1
 33.06198,1.35000,      -0.19606,3.29498,1
 33.16561,1.36000,      -0.19639,3.29495,1
 33.26916,1.37000,      -0.19673,3.29492,1
 33.37264,1.38000,      -0.19747,3.29489,1
 33.47611,1.39000,      -0.19810,3.29486,1
 33.57959,1.40000,      -0.19821,3.29483,1
 33.68300,1.41000,      -0.19851,3.29480,1
 33.78641,1.42000,      -0.19903,3.29477,1
 33.88970,1.43000,      -0.19966,3.29474,1
 33.99297,1.44000,      -0.20016,3.29471,1
 34.09621,1.45000,      -0.20044,3.29468,1
 34.19939,1.46000,      -0.20101,3.29465,1
 34.30249,1.47000,      -0.20134,3.29462,1
 34.40566,1.48000,      -0.20192,3.29459,1
 34.50870,1.49000,      -0.20252,3.29456,1
 34.61172,1.50000,      -0.20274,3.29453,1
 34.71472,1.51000,      -0.20356,3.29450,1
 34.81766,1.52000,      -0.20373,3.29447,1
 34.92049,1.53000,      -0.20431,3.29444,1
 35.02329,1.54000,      -0.20486,3.29441,1
 35.12608,1.55000,      -0.20530,3.29438,1
 35.22879,1.56000,      -0.20595,3.29434,1
 35.33148,1.57000,      -0.20639,3.29431,1
 35.43415,1.58000,      -0.20686,3.29428,1
 35.53682,1.59000,      -0.20738,3.29425,1
 35.63939,1.60000,      -0.20780,3.29422,1
 35.74193,1.61000,      -0.20823,3.29419,1
 35.84439,1.62000,      -0.20873,3.29415,1
 35.94685,1.63000,      -0.20922,3.29412,1
 36.04943,1.64000,      -0.20966,3.29409,1
 36.15189,1.65000,      -0.21016,3.29406,1
 36.25430,1.66000,      -0.21071,3.29403,1
 36.35667,1.67000,      -0.21087,3.29399,1
 36.45902,1.68000,      -0.21145,3.29396,1
 36.56136,1.69000,      -0.21205,3.29393,1
 36.66359,1.70000,      -0.21260,3.29390,1
 36.76577,1.71000,      -0.21323,3.29386,1
 36.86795,1.72000,      -0.21384,3.29383,1
 36.97018,1.73000,      -0.21436,3.29380,1
 37.07241,1.74000,      -0.21491,3.29376,1
 37.17462,1.75000,      -0.21538,3.29373,1
 37.27682,1.76000,      -0.21595,3.29370,1
 37.37897,1.77000,      -0.21617,3.29366,1
 37.48111,1.78000,      -0.21675,3.29363,1
 37.58320,1.79000,      -0.21760,3.29360,1
 37.68531,1.80000,      -0.21820,3.29356,1
 37.78743,1.81000,      -0.21875,3.29353,1
 37.88951,1.82000,      -0.21897,3.29349,1
 37.99161,1.83000,      -0.21952,3.29346,1
 38.09359,1.84000,      -0.22024,3.29343,1
 38.19557,1.85000,      -0.22087,3.29339,1
 38.29761,1.86000,      -0.22147,3.29336,1
 38.39964,1.87000,      -0.22164,3.29332,1
 38.50166,1.88000,      -0.22219,3.29329,1
 38.60362,1.89000,      -0.22287,3.29325,1
 38.70559,1.90000,      -0.22369,3.29322,1
 38.80756,1.91000,      -0.22433,3.29318,1
 38.90948,1.92000,      -0.22468,3.29315,1
 39.01144,1.93000,      -0.22531,3.29311,1
 39.11343,1.94000,      -0.22595,3.29308,1
 39.21536,1.95000,      -0.22663,3.29304,1
 39.31721,1.96000,      -0.22732,3.29301,1
 39.41908,1.97000,      -0.22787,3.29297,1
 39.52093,1.98000,      -0.22839,3.29293,1
 39.62275,1.99000,      -0.22897,3.29290,1
 39.72457,2.00000,      -0.22949,3.29286,1
 39.82634,2.01000,      -0.23009,3.29283,1
 39.92815,2.02000,      -0.23078,3.29279,1
 40.02990,2.03000,      -0.23160,3.29275,1
 40.13169,2.04000,      -0.23237,3.29272,1
 40.23346,2.05000,      -0.23273,3.29268,1
 40.33510,2.06000,      -0.23333,3.29264,1
 40.43674,2.07000,      -0.23396,3.29261,1
 40.53839,2.08000,      -0.23468,3.29257,1
 40.63998,2.09000,      -0.23533,3.29253,1
 40.74151,2.10000,      -0.23605,3.29250,1
 40.84302,2.11000,      -0.23684,3.29246,1
 40.94462,2.12000,      -0.23726,3.29242,1
 41.04616,2.13000,      -0.23797,3.29238,1
 41.14759,2.14000,      -0.23866,3.29235,1
 41.24898,2.15000,      -0.23929,3.29231,1
 41.35038,2.16000,      -0.24000,3.29227,1
 41.45180,2.17000,      -0.24063,3.29223,1
 41.55323,2.18000,      -0.24132,3.29220,1
 41.65464,2.19000,      -0.24200,3.29216,1
 41.75603,2.20000,      -0.24264,3.29212,1
 41.85744,2.21000,      -0.24327,3.29208,1
 41.95874,2.22000,      -0.24404,3.29204,1
 42.06007,2.23000,      -0.24478,3.29200,1
 42.16133,2.24000,      -0.24544,3.29197,1
 42.26254,2.25000,      -0.24590,3.29193,1
 42.36382,2.26000,      -0.24653,3.29189,1
 42.46505,2.27000,      -0.24725,3.29185,1
 42.56626,2.28000,      -0.24794,3.29181,1
 42.66746,2.29000,      -0.24887,3.29177,1
 42.76875,2.30000,      -0.24939,3.29173,1
 42.87002,2.31000,      -0.25005,3.29169,1
 42.97120,2.32000,      -0.25068,3.29165,1
 43.07236,2.33000,      -0.25167,3.29162,1
 43.17356,2.34000,      -0.25241,3.29158,1
 43.27474,2.35000,      -0.25282,3.29154,1
 43.37593,2.36000,      -0.25351,3.29150,1
 43.47713,2.37000,      -0.25417,3.29146,1
 43.57828,2.38000,      -0.25477,3.29142,1
 43.67944,2.39000,      -0.25554,3.29138,1
 43.78064,2.40000,      -0.25628,3.29134,1
 43.88180,2.41000,      -0.25697,3.29130,1
 43.98295,2.42000,      -0.25776,3.29126,1
 44.08408,2.43000,      -0.25848,3.29121,1
 44.18533,2.44000,      -0.25919,3.29117,1
 44.28656,2.45000,      -0.25977,3.29113,1
 44.38775,2.46000,      -0.26078,3.29109,1
 44.48900,2.47000,      -0.26142,3.29105,1
 44.59023,2.48000,      -0.26208,3.29101,1
 44.69151,2.49000,      -0.26279,3.29097,1
 44.79275,2.50000,      -0.26342,3.29093,1
 44.89400,2.51000,      -0.26416,3.29089,1
 44.99531,2.52000,      -0.26488,3.29084,1
 45.09667,2.53000,      -0.26576,3.29080,1
 45.19800,2.54000,      -0.26666,3.29076,1
 45.29933,2.55000,      -0.26746,3.29072,1
 45.40069,2.56000,      -0.26809,3.29068,1
 45.50208,2.57000,      -0.26881,3.29063,1
 45.60343,2.58000,      -0.26971,3.29059,1
 45.70472,2.59000,      -0.27056,3.29055,1
 45.80607,2.60000,      -0.27122,3.29051,1
 45.90744,2.61000,      -0.27213,3.29047,1
 46.00887,2.62000,      -0.27301,3.29042,1
 46.11030,2.63000,      -0.27380,3.29038,1
 46.21167,2.64000,      -0.27446,3.29034,1
 46.31303,2.65000,      -0.27523,3.29029,1
 46.41446,2.66000,      -0.27608,3.29025,1
 46.51587,2.67000,      -0.27696,3.29021,1
 46.61728,2.68000,      -0.27773,3.29016,1
 46.71871,2.69000,      -0.27858,3.29012,1
 46.82008,2.70000,      -0.27944,3.29008,1
 46.92148,2.71000,      -0.28029,3.29003,1
 47.02285,2.72000,      -0.28106,3.28999,1
 47.12418,2.73000,      -0.28196,3.28994,1
 47.22552,2.74000,      -0.28292,3.28990,1
 47.32690,2.75000,      -0.28375,3.28986,1
 47.42818,2.76000,      -0.28460,3.28981,1
 47.52944,2.77000,      -0.28523,3.28977,1
 47.63079,2.78000,      -0.28617,3.28972,1
 47.73207,2.79000,      -0.28745,3.28968,1
 47.83333,2.80000,      -0.28825,3.28963,1
 47.93451,2.81000,      -0.28902,3.28959,1
 48.03570,2.82000,      -0.28993,3.28954,1
 48.13687,2.83000,      -0.29086,3.28950,1
 48.23805,2.84000,      -0.29171,3.28945,1
 48.33916,2.85000,      -0.29256,3.28941,1
 48.44026,2.86000,      -0.29328,3.28936,1
 48.54138,2.87000,      -0.29397,3.28932,1
 48.64248,2.88000,      -0.29507,3.28927,1
 48.74357,2.89000,      -0.29603,3.28923,1
 48.84464,2.90000,      -0.29677,3.28918,1
 48.94574,2.91000,      -0.29776,3.28914,1
 49.04680,2.92000,      -0.29856,3.28909,1
 49.14784,2.93000,      -0.29949,3.28904,1
 49.24882,2.94000,      -0.30048,3.28900,1
 49.34984,2.95000,      -0.30128,3.28895,1
 49.45090,2.96000,      -0.30205,3.28891,1
 49.55189,2.97000,      -0.30287,3.28886,1
 49.65275,2.98000,      -0.30375,3.28881,1
 49.75372,2.99000,      -0.30463,3.28877,1
 49.85472,3.00000,      -0.30548,3.28872,1
 49.95574,3.01000,      -0.30647,3.28867,1
 50.05664,3.02000,      -0.30705,3.28863,1
 50.15756,3.03000,      -0.30812,3.28858,1
 50.25851,3.04000,      -0.30911,3.28853,1
 50.35944,3.05000,      -0.30991,3.28848,1
 50.46036,3.06000,      -0.31049,3.28844,1
 50.56125,3.07000,      -0.31153,3.28839,1
 50.66208,3.08000,      -0.31244,3.28834,1
 50.76289,3.09000,      -0.31345,3.28829,1
 50.86370,3.10000,      -0.31444,3.28825,1
 50.96449,3.11000,      -0.31541,3.28820,1
 51.06533,3.12000,      -0.31626,3.28815,1
 51.16608,3.13000,      -0.31719,3.28810,1
 51.26684,3.14000,      -0.31813,3.28805,1
 51.36759,3.15000,      -0.31893,3.28801,1
 51.46831,3.16000,      -0.31978,3.28796,1
 51.56903,3.17000,      -0.32058,3.28791,1
 51.66982,3.18000,      -0.32146,3.28786,1
 51.77056,3.19000,      -0.32242,3.28781,1
 51.87125,3.20000,      -0.32346,3.28776,1
 51.97195,3.21000,      -0.32440,3.28771,1
 52.07261,3.22000,      -0.32506,3.28767,1
 52.17328,3.23000,      -0.32616,3.28762,1
 52.27390,3.24000,      -0.32701,3.28757,1
 52.37461,3.25000,      -0.32778,3.28752,1
 52.47521,3.26000,      -0.32864,3.28747,1
 52.57585,3.27000,      -0.32954,3.28742,1
 52.67654,3.28000,      -0.33051,3.28737,1
 52.77728,3.29000,      -0.33163,3.28732,1
 52.87793,3.30000,      -0.33216,3.28727,1
 52.97852,3.31000,      -0.33337,3.28722,1
 53.07923,3.32000,      -0.33430,3.28717,1
 53.17992,3.33000,      -0.33527,3.28712,1
 53.28066,3.34000,      -0.33617,3.28707,1
 53.38134,3.35000,      -0.33708,3.28702,1
 53.48202,3.36000,      -0.33774,3.28697,1
 53.58270,3.37000,      -0.33876,3.28692,1
 53.68331,3.38000,      -0.33983,3.28687,1
 53.78405,3.39000,      -0.34077,3.28682,1
 53.88477,3.40000,      -0.34168,3.28676,1
 53.98541,3.41000,      -0.34261,3.28671,1
 54.08613,3.42000,      -0.34352,3.28666,1
 54.18685,3.43000,      -0.34448,3.28661,1
 54.28756,3.44000,      -0.34539,3.28656,1
 54.38826,3.45000,      -0.34641,3.28651,1
 54.48898,3.46000,      -0.34732,3.28646,1
 54.58975,3.47000,      -0.34790,3.28640,1
 54.69043,3.48000,      -0.34900,3.28635,1
 54.79103,3.49000,      -0.35040,3.28630,1
 54.89166,3.50000,      -0.35120,3.28625,1
 54.99233,3.51000,      -0.35205,3.28620,1
 55.09297,3.52000,      -0.35307,3.28614,1
 55.19359,3.53000,      -0.35401,3.28609,1
 55.29420,3.54000,      -0.35495,3.28604,1
 55.39484,3.55000,      -0.35588,3.28599,1
 55.49546,3.56000,      -0.35679,3.28593,1
 55.59605,3.57000,      -0.35775,3.28588,1
 55.69670,3.58000,      -0.35869,3.28583,1
 55.79730,3.59000,      -0.35968,3.28578,1
 55.89787,3.60000,      -0.36075,3.28572,1
 55.99849,3.61000,      -0.36169,3.28567,1
 56.09911,3.62000,      -0.36274,3.28562,1
 56.19969,3.63000,      -0.36367,3.28556,1
 56.30026,3.64000,      -0.36453,3.28551,1
 56.40089,3.65000,      -0.36538,3.28546,1
 56.50141,3.66000,      -0.36626,3.28540,1
 56.60200,3.67000,      -0.36720,3.28535,1
 56.70264,3.68000,      -0.36819,3.28529,1
 56.80330,3.69000,      -0.36910,3.28524,1
 56.90392,3.70000,      -0.37004,3.28519,1
 57.00457,3.71000,      -0.37103,3.28513,1
 57.10521,3.72000,      -0.37202,3.28508,1
 57.20585,3.73000,      -0.37307,3.28502,1
 57.30646,3.74000,      -0.37403,3.28497,1
 57.40707,3.75000,      -0.37470,3.28491,1
 57.50766,3.76000,      -0.37588,3.28486,1
 57.60828,3.77000,      -0.37693,3.28480,1
 57.70887,3.78000,      -0.37784,3.28475,1
 57.80946,3.79000,      -0.37888,3.28469,1
 57.91005,3.80000,      -0.37985,3.28464,1
 58.01056,3.81000,      -0.38084,3.28458,1
 58.11108,3.82000,      -0.38183,3.28453,1
 58.21162,3.83000,      -0.38261,3.28447,1
 58.31220,3.84000,      -0.38357,3.28442,1
 58.41272,3.85000,      -0.38451,3.28436,1
 58.51326,3.86000,      -0.38561,3.28430,1
 58.61374,3.87000,      -0.38658,3.28425,1
 58.71423,3.88000,      -0.38757,3.28419,1
 58.81467,3.89000,      -0.38856,3.28414,1
 58.91511,3.90000,      -0.38947,3.28408,1
 59.01556,3.91000,      -0.39038,3.28402,1
 59.11600,3.92000,      -0.39140,3.28397,1
 59.21641,3.93000,      -0.39239,3.28391,1
 59.31677,3.94000,      -0.39333,3.28385,1
 59.41716,3.95000,      -0.39422,3.28380,1
 59.51762,3.96000,      -0.39521,3.28374,1
 59.61807,3.97000,      -0.39636,3.28368,1
 59.71851,3.98000,      -0.39730,3.28363,1
 59.81889,3.99000,      -0.39835,3.28357,1
 59.91928,4.00000,      -0.39910,3.28351,1
 60.01969,4.01000,      -0.40012,3.28345,1
 60.12018,4.02000,      -0.40117,3.28340,1
 60.22062,4.03000,      -0.40219,3.28334,1
 60.32108,4.04000,      -0.40321,3.28328,1
 60.42149,4.05000,      -0.40401,3.28322,1
 60.52190,4.06000,      -0.40500,3.28316,1
 60.62234,4.07000,      -0.40597,3.28311,1
 60.72277,4.08000,      -0.40685,3.28305,1
 60.82323,4.09000,      -0.40790,3.28299,1
 60.92370,4.10000,      -0.40867,3.28293,1
 61.02418,4.11000,      -0.40969,3.28287,1
 61.12459,4.12000,      -0.41069,3.28281,1
 61.22503,4.13000,      -0.41174,3.28276,1
 61.32556,4.14000,      -0.41262,3.28270,1
 61.42607,4.15000,      -0.41364,3.28264,1
 61.52652,4.16000,      -0.41458,3.28258,1
 61.62693,4.17000,      -0.41557,3.28252,1
 61.72733,4.18000,      -0.41665,3.28246,1
 61.82779,4.19000,      -0.41753,3.28240,1
 61.92821,4.20000,      -0.41845,3.28234,1
 62.02869,4.21000,      -0.41939,3.28228,1
 62.12911,4.22000,      -0.42041,3.28222,1
 62.22946,4.23000,      -0.42140,3.28216,1
 62.32990,4.24000,      -0.42234,3.28210,1
 62.43031,4.25000,      -0.42331,3.28204,1
 62.53071,4.26000,      -0.42427,3.28198,1
 62.63113,4.27000,      -0.42524,3.28192,1
 62.73154,4.28000,      -0.42618,3.28186,1
 62.83197,4.29000,      -0.42715,3.28180,1
 62.93238,4.30000,      -0.42800,3.28174,1
 63.03274,4.31000,      -0.42892,3.28168,1
 63.13321,4.32000,      -0.42980,3.28162,1
 63.23366,4.33000,      -0.43074,3.28156,1
 63.33407,4.34000,      -0.43171,3.28150,1
 63.43449,4.35000,      -0.43276,3.28144,1
 63.53492,4.36000,      -0.43373,3.28138,1
 63.63531,4.37000,      -0.43456,3.28131,1
 63.73579,4.38000,      -0.43552,3.28125,1
 63.83630,4.39000,      -0.43644,3.28119,1
 63.93679,4.40000,      -0.43729,3.28113,1
 64.03725,4.41000,      -0.43829,3.28107,1
 64.13770,4.42000,      -0.43928,3.28101,1
 64.23821,4.43000,      -0.44036,3.28094,1
 64.33869,4.44000,      -0.44133,3.28088,1
 64.43921,4.45000,      -0.44227,3.28082,1
 64.53975,4.46000,      -0.44324,3.28076,1
 64.64028,4.47000,      -0.44420,3.28070,1
 64.74079,4.48000,      -0.44523,3.28063,1
 64.84133,4.49000,      -0.44611,3.28057,1
 64.94185,4.50000,      -0.44714,3.28051,1
 65.04234,4.51000,      -0.44797,3.28044,1
 65.14285,4.52000,      -0.44883,3.28038,1
 65.24338,4.53000,      -0.44974,3.28032,1
 65.34385,4.54000,      -0.45076,3.28026,1
 65.44436,4.55000,      -0.45168,3.28019,1
 65.54490,4.56000,      -0.45267,3.28013,1
 65.64543,4.57000,      -0.45361,3.28007,1
 65.74597,4.58000,      -0.45464,3.28000,1
 65.84643,4.59000,      -0.45569,3.27994,1
 65.94689,4.60000,      -0.45655,3.27987,1
 66.04741,4.61000,      -0.45749,3.27981,1
 66.14793,4.62000,      -0.45846,3.27975,1
 66.24841,4.63000,      -0.45929,3.27968,1
 66.34890,4.64000,      -0.46020,3.27962,1
 66.44933,4.65000,      -0.46112,3.27955,1
 66.54980,4.66000,      -0.46230,3.27949,1
 66.65026,4.67000,      -0.46324,3.27942,1
 66.75074,4.68000,      -0.46416,3.27936,1
 66.85121,4.69000,      -0.46505,3.27930,1
 66.95167,4.70000,      -0.46601,3.27923,1
 67.05213,4.71000,      -0.46696,3.27917,1
 67.15262,4.72000,      -0.46790,3.27910,1
 67.25310,4.73000,      -0.46879,3.27904,1
 67.35359,4.74000,      -0.46962,3.27897,1
 67.45408,4.75000,      -0.47053,3.27890,1
 67.55459,4.76000,      -0.47145,3.27884,1
 67.65508,4.77000,      -0.47228,3.27877,1
 67.75557,4.78000,      -0.47328,3.27871,1
 67.85602,4.79000,      -0.47452,3.27864,1
 67.95656,4.80000,      -0.47505,3.27858,1
 68.05703,4.81000,      -0.47607,3.27851,1
 68.15751,4.82000,      -0.47699,3.27844,1
 68.25802,4.83000,      -0.47785,3.27838,1
 68.35856,4.84000,      -0.47871,3.27831,1
 68.45903,4.85000,      -0.47960,3.27824,1
 68.55956,4.86000,      -0.48046,3.27818,1
 68.65998,4.87000,      -0.48132,3.27811,1
 68.76043,4.88000,      -0.48234,3.27804,1
 68.86087,4.89000,      -0.48326,3.27798,1
 68.96133,4.90000,      -0.48404,3.27791,1
 69.06177,4.91000,      -0.48495,3.27784,1
 69.16228,4.92000,      -0.48590,3.27778,1
 69.26272,4.93000,      -0.48676,3.27771,1
 69.36316,4.94000,      -0.48759,3.27764,1
 69.46359,4.95000,      -0.48837,3.27757,1
 69.56398,4.96000,      -0.48931,3.27751,1
 69.66438,4.97000,      -0.49020,3.27744,1
 69.76479,4.98000,      -0.49114,3.27737,1
 69.86518,4.99000,      -0.49200,3.27730,1
 69.96552,5.00000,      -0.49286,3.27723,1
 70.06592,5.01000,      -0.49394,3.27717,1
 70.16626,5.02000,      -0.49475,3.27710,1
 70.26662,5.03000,      -0.49523,3.27703,1
 70.36695,5.04000,      -0.49625,3.27696,1
 70.46726,5.05000,      -0.49725,3.27689,1
 70.56764,5.06000,      -0.49809,3.27682,1
 70.66803,5.07000,      -0.49867,3.27676,1
 70.76846,5.08000,      -0.49967,3.27669,1
 70.86882,5.09000,      -0.50048,3.27662,1
 70.96915,5.10000,      -0.50134,3.27655,1
 71.06951,5.11000,      -0.50212,3.27648,1
 71.16985,5.12000,      -0.50309,3.27641,1
 71.27018,5.13000,      -0.50398,3.27634,1
 71.37052,5.14000,      -0.50481,3.27627,1
 71.47087,5.15000,      -0.50565,3.27620,1
 71.57116,5.16000,      -0.50648,3.27613,1
 71.67146,5.17000,      -0.50723,3.27606,1
 71.77177,5.18000,      -0.50799,3.27599,1
 71.87215,5.19000,      -0.50879,3.27592,1
 71.97252,5.20000,      -0.50960,3.27585,1
 72.07284,5.21000,      -0.51041,3.27578,1
 72.17320,5.22000,      -0.51119,3.27571,1
 72.27352,5.23000,      -0.51194,3.27564,1
 72.37384,5.24000,      -0.51275,3.27557,1
 72.47420,5.25000,      -0.51303,3.27550,1
 72.57448,5.26000,      -0.51433,3.27543,1
 72.67475,5.27000,      -0.51500,3.27536,1
 72.77502,5.28000,      -0.51587,3.27529,1
 72.87528,5.29000,      -0.51656,3.27522,1
 72.97559,5.30000,      -0.51748,3.27515,1
 73.07587,5.31000,      -0.51821,3.27508,1
 73.17615,5.32000,      -0.51899,3.27500,1
 73.27641,5.33000,      -0.51985,3.27493,1
 73.37670,5.34000,      -0.52063,3.27486,1
 73.47700,5.35000,      -0.52086,3.27479,1
 73.57725,5.36000,      -0.52192,3.27472,1
 73.67756,5.37000,      -0.52267,3.27465,1
 73.77784,5.38000,      -0.52351,3.27457,1
 73.87811,5.39000,      -0.52431,3.27450,1
 73.97843,5.40000,      -0.52504,3.27443,1
 74.07874,5.41000,      -0.52577,3.27436,1
 74.17900,5.42000,      -0.52630,3.27428,1
 74.27934,5.43000,      -0.52708,3.27421,1
 74.37967,5.44000,      -0.52783,3.27414,1
 74.48002,5.45000,      -0.52809,3.27407,1
 74.58038,5.46000,      -0.52926,3.27399,1
 74.68074,5.47000,      -0.52985,3.27392,1
 74.78108,5.48000,      -0.53055,3.27385,1
 74.88144,5.49000,      -0.53119,3.27377,1
 74.98175,5.50000,      -0.53200,3.27370,1
 75.08213,5.51000,      -0.53272,3.27363,1
 75.18251,5.52000,      -0.53315,3.27355,1
 75.28285,5.53000,      -0.53379,3.27348,1
 75.38323,5.54000,      -0.53457,3.27341,1
 75.48356,5.55000,      -0.53536,3.27333,1
 75.58397,5.56000,      -0.53614,3.27326,1
 75.68434,5.57000,      -0.53681,3.27319,1
 75.78472,5.58000,      -0.53751,3.27311,1
 75.88503,5.59000,      -0.53815,3.27304,1
 75.98534,5.60000,      -0.53880,3.27296,1
 76.08567,5.61000,      -0.53941,3.27289,1
 76.18602,5.62000,      -0.54003,3.27281,1
 76.28633,5.63000,      -0.54062,3.27274,1
 76.38666,5.64000,      -0.54127,3.27266,1
 76.48693,5.65000,      -0.54188,3.27259,1
 76.58723,5.66000,      -0.54228,3.27251,1
 76.68754,5.67000,      -0.54306,3.27244,1
 76.78784,5.68000,      -0.54395,3.27236,1
 76.88816,5.69000,      -0.54438,3.27229,1
 76.98852,5.70000,      -0.54494,3.27221,1
 77.08889,5.71000,      -0.54564,3.27214,1
 77.18918,5.72000,      -0.54631,3.27206,1
 77.28954,5.73000,      -0.54693,3.27199,1
 77.38993,5.74000,      -0.54725,3.27191,1
 77.49025,5.75000,      -0.54759,3.27183,1
 77.59052,5.76000,      -0.54837,3.27176,1
 77.69085,5.77000,      -0.54883,3.27168,1
 77.79115,5.78000,      -0.54942,3.27161,1
 77.89149,5.79000,      -0.55031,3.27153,1
 77.99189,5.80000,      -0.55098,3.27145,1
 78.09218,5.81000,      -0.55160,3.27138,1
 78.19251,5.82000,      -0.55175,3.27130,1
 78.29285,5.83000,      -0.55240,3.27122,1
 78.39321,5.84000,      -0.55307,3.27115,1
 78.49354,5.85000,      -0.55369,3.27107,1
 78.59385,5.86000,      -0.55409,3.27099,1
 78.69416,5.87000,      -0.55457,3.27092,1
 78.79449,5.88000,      -0.55507,3.27084,1
 78.89484,5.89000,      -0.55556,3.27076,1
 78.99511,5.90000,      -0.55606,3.27068,1
 79.09549,5.91000,      -0.55660,3.27061,1
 79.19580,5.92000,      -0.55714,3.27053,1
 79.29611,5.93000,      -0.55764,3.27045,1
 79.39641,5.94000,      -0.55785,3.27037,1
 79.49672,5.95000,      -0.55847,3.27029,1
 79.59715,5.96000,      -0.55892,3.27022,1
 79.69744,5.97000,      -0.55940,3.27014,1
 79.79775,5.98000,      -0.56002,3.27006,1
 79.89805,5.99000,      -0.56037,3.26998,1
 79.99828,6.00000,      -0.56057,3.26990,1
 80.09851,6.01000,      -0.56114,3.26982,1
 80.19879,6.02000,      -0.56151,3.26974,1
 80.29905,6.03000,      -0.56194,3.26967,1
 80.39928,6.04000,      -0.56242,3.26959,1
 80.49957,6.05000,      -0.56298,3.26951,1
 80.59985,6.06000,      -0.56341,3.26943,1
 80.70018,6.07000,      -0.56386,3.26935,1
 80.80046,6.08000,      -0.56443,3.26927,1
 80.90069,6.09000,      -0.56458,3.26919,1
 81.00092,6.10000,      -0.56476,3.26911,1
 81.10111,6.11000,      -0.56516,3.26903,1
 81.20138,6.12000,      -0.56556,3.26895,1
 81.30156,6.13000,      -0.56595,3.26887,1
 81.40174,6.14000,      -0.56638,3.26879,1
 81.50200,6.15000,      -0.56681,3.26871,1
 81.60215,6.16000,      -0.56715,3.26863,1
 81.70241,6.17000,      -0.56742,3.26855,1
 81.80267,6.18000,      -0.56776,3.26847,1
 81.90295,6.19000,      -0.56791,3.26839,1
 82.00323,6.20000,      -0.56801,3.26831,1
 82.10354,6.21000,      -0.56824,3.26823,1
 82.20384,6.22000,      -0.56886,3.26815,1
 82.30410,6.23000,      -0.56907,3.26807,1
 82.40436,6.24000,      -0.56928,3.26799,1
 82.50466,6.25000,      -0.56957,3.26791,1
 82.60487,6.26000,      -0.56994,3.26782,1
 82.70510,6.27000,      -0.57020,3.26774,1
 82.80533,6.28000,      -0.57049,3.26766,1
 82.90552,6.29000,      -0.57056,3.26758,1
 83.00574,6.30000,      -0.57135,3.26750,1
 83.10592,6.31000,      -0.57180,3.26742,1
 83.20608,6.32000,      -0.57135,3.26733,1
 83.30630,6.33000,      -0.57139,3.26725,1
 83.40649,6.34000,      -0.57166,3.26717,1
 83.50664,6.35000,      -0.57164,3.26709,1
 83.60679,6.36000,      -0.57202,3.26701,1
 83.70692,6.37000,      -0.57222,3.26692,1
 83.80702,6.38000,      -0.57243,3.26684,1
 83.90713,6.39000,      -0.57256,3.26676,1
 84.00726,6.40000,      -0.57274,3.26668,1
 84.10741,6.41000,      -0.57294,3.26659,1
 84.20749,6.42000,      -0.57304,3.26651,1
 84.30764,6.43000,      -0.57355,3.26643,1
 84.40775,6.44000,      -0.57387,3.26635,1
 84.50775,6.45000,      -0.57388,3.26626,1
 84.60784,6.46000,      -0.57404,3.26618,1
 84.70792,6.47000,      -0.57413,3.26610,1
 84.80792,6.48000,      -0.57418,3.26601,1
 84.90802,6.49000,      -0.57430,3.26593,1
 85.00805,6.50000,      -0.57432,3.26585,1
 85.10813,6.51000,      -0.57442,3.26576,1
 85.20816,6.52000,      -0.57460,3.26568,1
 85.30820,6.53000,      -0.57472,3.26559,1
 85.40823,6.54000,      -0.57485,3.26551,1
 85.50831,6.55000,      -0.57511,3.26543,1
 85.60831,6.56000,      -0.57513,3.26534,1
 85.70833,6.57000,      -0.57522,3.26526,1
 85.80836,6.58000,      -0.57532,3.26517,1
 85.90836,6.59000,      -0.57550,3.26509,1
 86.00843,6.60000,      -0.57560,3.26500,1
 86.10838,6.61000,      -0.57556,3.26492,1
 86.20841,6.62000,      -0.57544,3.26483,1
 86.30836,6.63000,      -0.57554,3.26475,1
 86.40843,6.64000,      -0.57569,3.26466,1
 86.50849,6.65000,      -0.57573,3.26458,1
 86.60852,6.66000,      -0.57575,3.26449,1
 86.70851,6.67000,      -0.57579,3.26441,1
 86.80856,6.68000,      -0.57584,3.26432,1
 86.90859,6.69000,      -0.57580,3.26424,1
 87.00862,6.70000,      -0.57570,3.26415,1
 87.10864,6.71000,      -0.57580,3.26407,1
 87.20874,6.72000,      -0.57579,3.26398,1
 87.30884,6.73000,      -0.57569,3.26389,1
 87.40892,6.74000,      -0.57571,3.26381,1
 87.50898,6.75000,      -0.57575,3.26372,1
 87.60908,6.76000,      -0.57577,3.26364,1
 87.70921,6.77000,      -0.57587,3.26355,1
 87.80934,6.78000,      -0.57569,3.26346,1
 87.90939,6.79000,      -0.57571,3.26338,1
 88.00946,6.80000,      -0.57556,3.26329,1
 88.10952,6.81000,      -0.57552,3.26320,1
 88.20964,6.82000,      -0.57548,3.26312,1
 88.30975,6.83000,      -0.57550,3.26303,1
 88.40990,6.84000,      -0.57540,3.26294,1
 88.50997,6.85000,      -0.57534,3.26285,1
 88.61007,6.86000,      -0.57530,3.26277,1
 88.71018,6.87000,      -0.57528,3.26268,1
 88.81028,6.88000,      -0.57514,3.26259,1
 88.91041,6.89000,      -0.57488,3.26250,1
 89.01052,6.90000,      -0.57478,3.26242,1
 89.11075,6.91000,      -0.57469,3.26233,1
 89.21088,6.92000,      -0.57465,3.26224,1
 89.31095,6.93000,      -0.57445,3.26215,1
 89.41108,6.94000,      -0.57449,3.26206,1
 89.51126,6.95000,      -0.57442,3.26197,1
 89.61144,6.96000,      -0.57444,3.26189,1
 89.71159,6.97000,      -0.57437,3.26180,1
 89.81175,6.98000,      -0.57417,3.26171,1
 89.91195,6.99000,      -0.57399,3.26162,1
 90.01216,7.00000,      -0.57387,3.26153,1
 90.11246,7.01000,      -0.57372,3.26144,1
 90.21262,7.02000,      -0.57354,3.26135,1
 90.31284,7.03000,      -0.57337,3.26126,1
 90.41308,7.04000,      -0.57316,3.26117,1
 90.51331,7.05000,      -0.57302,3.26109,1
 90.61354,7.06000,      -0.57292,3.26100,1
 90.71377,7.07000,      -0.57275,3.26091,1
 90.81402,7.08000,      -0.57262,3.26082,1
 90.91431,7.09000,      -0.57261,3.26073,1
 91.01461,7.10000,      -0.57230,3.26064,1
 91.11487,7.11000,      -0.57212,3.26055,1
 91.21510,7.12000,      -0.57189,3.26046,1
 91.31539,7.13000,      -0.57169,3.26037,1
 91.41564,7.14000,      -0.57148,3.26027,1
 91.51593,7.15000,      -0.57147,3.26018,1
 91.61618,7.16000,      -0.57130,3.26009,1
 91.71644,7.17000,      -0.57109,3.26000,1
 91.81669,7.18000,      -0.57067,3.25991,1
 91.91695,7.19000,      -0.57046,3.25982,1
 92.01726,7.20000,      -0.57023,3.25973,1
 92.11749,7.21000,      -0.57036,3.25964,1
 92.21780,7.22000,      -0.57026,3.25955,1
 92.31810,7.23000,      -0.56979,3.25946,1
 92.41833,7.24000,      -0.56977,3.25936,1
 92.51856,7.25000,      -0.56971,3.25927,1
 92.61880,7.26000,      -0.56939,3.25918,1
 92.71910,7.27000,      -0.56905,3.25909,1
 92.81941,7.28000,      -0.56885,3.25900,1
 92.91967,7.29000,      -0.56875,3.25891,1
 93.01989,7.30000,      -0.56852,3.25881,1
 93.12005,7.31000,      -0.56829,3.25872,1
 93.22031,7.32000,      -0.56803,3.25863,1
 93.32059,7.33000,      -0.56783,3.25854,1
 93.42089,7.34000,      -0.56754,3.25844,1
 93.52111,7.35000,      -0.56723,3.25835,1
 93.62134,7.36000,      -0.56680,3.25826,1
 93.72157,7.37000,      -0.56660,3.25817,1
 93.82182,7.38000,      -0.56642,3.25807,1
 93.92205,7.39000,      -0.56622,3.25798,1
 94.02225,7.40000,      -0.56593,3.25789,1
 94.12241,7.41000,      -0.56562,3.25779,1
 94.22254,7.42000,      -0.56531,3.25770,1
 94.32267,7.43000,      -0.56502,3.25761,1
 94.42280,7.44000,      -0.56462,3.25751,1
 94.52300,7.45000,      -0.56425,3.25742,1
 94.62315,7.46000,      -0.56397,3.25733,1
 94.72328,7.47000,      -0.56360,3.25723,1
 94.82339,7.48000,      -0.56334,3.25714,1
 94.92348,7.49000,      -0.56316,3.25705,1
 95.02361,7.50000,      -0.56282,3.25695,1
 95.12372,7.51000,      -0.56239,3.25686,1
 95.22387,7.52000,      -0.56222,3.25676,1
 95.32393,7.53000,      -0.56215,3.25667,1
 95.42397,7.54000,      -0.56151,3.25657,1
 95.52403,7.55000,      -0.56095,3.25648,1
 95.62410,7.56000,      -0.56074,3.25638,1
 95.72420,7.57000,      -0.56018,3.25629,1
 95.82421,7.58000,      -0.55989,3.25620,1
 95.92426,7.59000,      -0.55983,3.25610,1
 96.02431,7.60000,      -0.55951,3.25601,1
 96.12436,7.61000,      -0.55895,3.25591,1
 96.22444,7.62000,      -0.55855,3.25582,1
 96.32454,7.63000,      -0.55807,3.25572,1
 96.42457,7.64000,      -0.55765,3.25562,1
 96.52457,7.65000,      -0.55728,3.25553,1
 96.62459,7.66000,      -0.55691,3.25543,1
 96.72464,7.67000,      -0.55648,3.25534,1
 96.82467,7.68000,      -0.55611,3.25524,1
 96.92472,7.69000,      -0.55575,3.25515,1
 97.02475,7.70000,      -0.55529,3.25505,1
 97.12482,7.71000,      -0.55498,3.25495,1
 97.22477,7.72000,      -0.55453,3.25486,1
 97.32479,7.73000,      -0.55413,3.25476,1
 97.42492,7.74000,      -0.55379,3.25466,1
 97.52500,7.75000,      -0.55322,3.25457,1
 97.62502,7.76000,      -0.55280,3.25447,1
 97.72507,7.77000,      -0.55229,3.25437,1
 97.82510,7.78000,      -0.55176,3.25428,1
 97.92521,7.79000,      -0.55130,3.25418,1
 98.02531,7.80000,      -0.55077,3.25408,1
 98.12544,7.81000,      -0.55045,3.25399,1
 98.22554,7.82000,      -0.55000,3.25389,1
 98.32564,7.83000,      -0.54985,3.25379,1
 98.42585,7.84000,      -0.54960,3.25369,1
 98.52607,7.85000,      -0.54917,3.25360,1
 98.62630,7.86000,      -0.54864,3.25350,1
 98.72651,7.87000,      -0.54818,3.25340,1
 98.82669,7.88000,      -0.54823,3.25330,1
 98.92692,7.89000,      -0.54800,3.25320,1
 99.02721,7.90000,      -0.54774,3.25311,1
 99.12748,7.91000,      -0.54740,3.25301,1
 99.22780,7.92000,      -0.54719,3.25291,1
 99.32820,7.93000,      -0.54713,3.25281,1
 99.42848,7.94000,      -0.54695,3.25271,1
 99.52882,7.95000,      -0.54672,3.25261,1
 99.62918,7.96000,      -0.54635,3.25251,1
 99.72951,7.97000,      -0.54615,3.25241,1
 99.82993,7.98000,      -0.54616,3.25232,1
 99.93031,7.99000,      -0.54557,3.25222,1
100.03066,8.00000,      -0.54520,3.25212,1
100.13103,8.01000,      -0.54522,3.25202,1
100.23136,8.02000,      -0.54488,3.25192,1
100.33169,8.03000,      -0.54440,3.25182,1
100.43200,8.04000,      -0.54395,3.25172,1
100.53231,8.05000,      -0.54358,3.25162,1
100.63262,8.06000,      -0.54324,3.25152,1
100.73290,8.07000,      -0.54273,3.25142,1
100.83321,8.08000,      -0.54211,3.25132,1
100.93356,8.09000,      -0.54138,3.25122,1
101.03375,8.10000,      -0.54076,3.25112,1
101.13405,8.11000,      -0.54017,3.25102,1
101.23428,8.12000,      -0.53961,3.25092,1
101.33448,8.13000,      -0.53907,3.25082,1
101.43467,8.14000,      -0.53845,3.25071,1
101.53485,8.15000,      -0.53773,3.25061,1
101.63502,8.16000,      -0.53702,3.25051,1
101.73516,8.17000,      -0.53638,3.25041,1
101.83534,8.18000,      -0.53590,3.25031,1
101.93549,8.19000,      -0.53533,3.25021,1
102.03559,8.20000,      -0.53472,3.25011,1
102.13571,8.21000,      -0.53415,3.25001,1
102.23580,8.22000,      -0.53353,3.24991,1
102.33587,8.23000,      -0.53302,3.24980,1
102.43598,8.24000,      -0.53249,3.24970,1
102.53610,8.25000,      -0.53198,3.24960,1
102.63618,8.26000,      -0.53147,3.24950,1
102.73628,8.27000,      -0.53088,3.24940,1
102.83636,8.28000,      -0.53001,3.24929,1
102.93649,8.29000,      -0.52973,3.24919,1
103.03656,8.30000,      -0.52914,3.24909,1
103.13664,8.31000,      -0.52860,3.24899,1
103.23669,8.32000,      -0.52804,3.24889,1
103.33675,8.33000,      -0.52733,3.24878,1
103.43684,8.34000,      -0.52691,3.24868,1
103.53690,8.35000,      -0.52660,3.24858,1
103.63705,8.36000,      -0.52609,3.24847,1
103.73716,8.37000,      -0.52547,3.24837,1
103.83725,8.38000,      -0.52490,3.24827,1
103.93728,8.39000,      -0.52429,3.24817,1
104.03738,8.40000,      -0.52353,3.24806,1
104.13738,8.41000,      -0.52305,3.24796,1
104.23746,8.42000,      -0.52268,3.24786,1
104.33759,8.43000,      -0.52214,3.24775,1
104.43772,8.44000,      -0.52160,3.24765,1
104.53772,8.45000,      -0.52085,3.24754,1
104.63772,8.46000,      -0.52031,3.24744,1
104.73772,8.47000,      -0.52013,3.24734,1
104.83767,8.48000,      -0.51938,3.24723,1
104.93757,8.49000,      -0.51870,3.24713,1
105.03759,8.50000,      -0.51828,3.24702,1
105.13756,8.51000,      -0.51788,3.24692,1
105.23752,8.52000,      -0.51732,3.24682,1
105.33746,8.53000,      -0.51681,3.24671,1
105.43736,8.54000,      -0.51621,3.24661,1
105.53728,8.55000,      -0.51554,3.24650,1
105.63713,8.56000,      -0.51506,3.24640,1
105.73697,8.57000,      -0.51447,3.24629,1
105.83689,8.58000,      -0.51388,3.24619,1
105.93680,8.59000,      -0.51323,3.24608,1
106.03670,8.60000,      -0.51266,3.24598,1
106.13664,8.61000,      -0.51210,3.24587,1
106.23651,8.62000,      -0.51148,3.24577,1
106.33634,8.63000,      -0.51092,3.24566,1
106.43620,8.64000,      -0.51030,3.24556,1
106.53611,8.65000,      -0.50970,3.24545,1
106.63605,8.66000,      -0.50920,3.24535,1
106.73593,8.67000,      -0.50858,3.24524,1
106.83585,8.68000,      -0.50801,3.24513,1
106.93577,8.69000,      -0.50742,3.24503,1
107.03567,8.70000,      -0.50677,3.24492,1
107.13551,8.71000,      -0.50621,3.24482,1
107.23544,8.72000,      -0.50570,3.24471,1
107.33538,8.73000,      -0.50513,3.24460,1
107.43533,8.74000,      -0.50449,3.24450,1
107.53525,8.75000,      -0.50387,3.24439,1
107.63521,8.76000,      -0.50308,3.24428,1
107.73516,8.77000,      -0.50271,3.24418,1
107.83503,8.78000,      -0.50237,3.24407,1
107.93495,8.79000,      -0.50155,3.24396,1
108.03489,8.80000,      -0.50096,3.24385,1
108.13477,8.81000,      -0.50031,3.24375,1
108.23472,8.82000,      -0.49967,3.24364,1
108.33467,8.83000,      -0.49893,3.24353,1
108.43461,8.84000,      -0.49848,3.24343,1
108.53456,8.85000,      -0.49778,3.24332,1
108.63456,8.86000,      -0.49721,3.24321,1
108.73452,8.87000,      -0.49668,3.24310,1
108.83452,8.88000,      -0.49603,3.24299,1
108.93449,8.89000,      -0.49535,3.24289,1
109.03443,8.90000,      -0.49468,3.24278,1
109.13444,8.91000,      -0.49436,3.24267,1
109.23443,8.92000,      -0.49346,3.24256,1
109.33441,8.93000,      -0.49271,3.24245,1
109.43444,8.94000,      -0.49211,3.24234,1
109.53439,8.95000,      -0.49155,3.24223,1
109.63439,8.96000,      -0.49107,3.24213,1
109.73441,8.97000,      -0.49036,3.24202,1
109.83441,8.98000,      -0.48977,3.24191,1
109.93441,8.99000,      -0.48904,3.24180,1
110.03438,9.00000,      -0.48839,3.24169,1
110.13441,9.01000,      -0.48805,3.24158,1
110.23441,9.02000,      -0.48779,3.24147,1
110.33441,9.03000,      -0.48694,3.24136,1
110.43436,9.04000,      -0.48621,3.24125,1
110.53434,9.05000,      -0.48534,3.24114,1
110.63434,9.06000,      -0.48456,3.24103,1
110.73429,9.07000,      -0.48394,3.24092,1
110.83426,9.08000,      -0.48354,3.24081,1
110.93429,9.09000,      -0.48289,3.24070,1
111.03433,9.10000,      -0.48224,3.24059,1
111.13438,9.11000,      -0.48165,3.24048,1
111.23439,9.12000,      -0.48097,3.24037,1
111.33436,9.13000,      -0.48013,3.24026,1
111.43429,9.14000,      -0.47948,3.24015,1
111.53429,9.15000,      -0.47880,3.24004,1
111.63425,9.16000,      -0.47838,3.23993,1
111.73423,9.17000,      -0.47759,3.23982,1
111.83416,9.18000,      -0.47702,3.23970,1
111.93413,9.19000,      -0.47657,3.23959,1
112.03410,9.20000,      -0.47572,3.23948,1
112.13403,9.21000,      -0.47508,3.23937,1
112.23397,9.22000,      -0.47432,3.23926,1
112.33390,9.23000,      -0.47361,3.23915,1
112.43382,9.24000,      -0.47293,3.23904,1
112.53377,9.25000,      -0.47229,3.23892,1
112.63367,9.26000,      -0.47166,3.23881,1
112.73367,9.27000,      -0.47099,3.23870,1
112.83369,9.28000,      -0.47037,3.23859,1
112.93357,9.29000,      -0.46994,3.23848,1
113.03349,9.30000,      -0.46910,3.23836,1
113.13344,9.31000,      -0.46834,3.23825,1
113.23344,9.32000,      -0.46758,3.23814,1
113.33343,9.33000,      -0.46676,3.23803,1
113.43339,9.34000,      -0.46628,3.23791,1
113.53336,9.35000,      -0.46560,3.23780,1
113.63333,9.36000,      -0.46490,3.23769,1
113.73328,9.37000,      -0.46425,3.23758,1
113.83331,9.38000,      -0.46360,3.23746,1
113.93330,9.39000,      -0.46284,3.23735,1
114.03328,9.40000,      -0.46191,3.23724,1
114.13330,9.41000,      -0.46132,3.23712,1
114.23333,9.42000,      -0.46064,3.23701,1
114.33334,9.43000,      -0.45996,3.23690,1
114.43343,9.44000,      -0.45931,3.23678,1
114.53348,9.45000,      -0.45855,3.23667,1
114.63354,9.46000,      -0.45787,3.23655,1
114.73359,9.47000,      -0.45700,3.23644,1
114.83364,9.48000,      -0.45624,3.23633,1
114.93369,9.49000,      -0.45562,3.23621,1
115.03372,9.50000,      -0.45475,3.23610,1
115.13372,9.51000,      -0.45426,3.23598,1
115.23375,9.52000,      -0.45364,3.23587,1
115.33375,9.53000,      -0.45291,3.23575,1
115.43375,9.54000,      -0.45229,3.23564,1
115.53380,9.55000,      -0.45158,3.23552,1
115.63382,9.56000,      -0.45068,3.23541,1
115.73384,9.57000,      -0.44989,3.23529,1
115.83382,9.58000,      -0.44910,3.23518,1
115.93385,9.59000,      -0.44862,3.23506,1
116.03392,9.60000,      -0.44780,3.23495,1
116.13403,9.61000,      -0.44715,3.23483,1
116.23403,9.62000,      -0.44650,3.23472,1
116.33408,9.63000,      -0.44566,3.23460,1
116.43410,9.64000,      -0.44484,3.23449,1
116.53418,9.65000,      -0.44408,3.23437,1
116.63421,9.66000,      -0.44337,3.23425,1
116.73421,9.67000,      -0.44275,3.23414,1
116.83421,9.68000,      -0.44213,3.23402,1
116.93431,9.69000,      -0.44129,3.23390,1
117.03436,9.70000,      -0.44044,3.23379,1
117.13438,9.71000,      -0.43979,3.23367,1
117.23441,9.72000,      -0.43903,3.23356,1
117.33448,9.73000,      -0.43832,3.23344,1
117.43456,9.74000,      -0.43762,3.23332,1
117.53466,9.75000,      -0.43672,3.23321,1
117.63470,9.76000,      -0.43598,3.23309,1
117.73472,9.77000,      -0.43519,3.23297,1
117.83482,9.78000,      -0.43435,3.23285,1
117.93489,9.79000,      -0.43356,3.23274,1
118.03485,9.80000,      -0.43285,3.23262,1
118.13479,9.81000,      -0.43214,3.23250,1
118.23480,9.82000,      -0.43130,3.23238,1
118.33480,9.83000,      -0.43056,3.23227,1
118.43482,9.84000,      -0.42983,3.23215,1
118.53474,9.85000,      -0.42901,3.23203,1
118.63466,9.86000,      -0.42830,3.23191,1
118.73456,9.87000,      -0.42757,3.23180,1
118.83448,9.88000,      -0.42684,3.23168,1
118.93433,9.89000,      -0.42602,3.23156,1
119.03369,9.90000,      -0.42525,3.23144,1
119.13356,9.91000,      -0.42446,3.23132,1
119.23335,9.92000,      -0.42362,3.23121,1
119.33309,9.93000,      -0.42288,3.23109,1
119.43286,9.94000,      -0.42218,3.23097,1
119.53252,9.95000,      -0.42139,3.23085,1
119.63216,9.96000,      -0.42057,3.23073,1
119.73142,9.97000,      -0.41953,3.23061,1
119.83046,9.98000,      -0.41887,3.23050,1
119.92814,9.99000,      -0.41803,3.23038,1
120.00000,9.99833,      -0.41750,3.23029,1