File: DSC图/ExpAll_冷榨2.csv
#EXPORTTYPE:                 ,ALL
#FILE:                       ,¿‰’•2.ngb-sd7
#FORMAT:                     ,NETZSCH5
#FTYPE:                      ,ANSI
#IDENTITY:                   ,2
#DECIMAL:                    ,POINT
#SEPARATOR:                  ,COMMA
#MTYPE:                      ,DSC
#INSTRUMENT:                 ,NETZSCH DSC 204F1 Phoenix
#PROJECT:                    ,1
#DATE/TIME:                  ,2023/4/24 16:19:05 (UTC+8)
#CORR. FILE:                 ,
#TEMPCAL:                    ,applied
#SENSITIVITY:                ,applied
#LABORATORY:                 ,
#OPERATOR:                   ,0
#REMARK:                     ,
#SAMPLE:                     ,¿‰’•
#SAMPLE MASS /mg:            ,8.76
#MATERIAL:                   ,
#REFERENCE:                  ,
#REFERENCE MASS /mg:         ,0
#TYPE OF CRUCIBLE:           ,Concavus Pan Al, open
#SAMPLE CRUCIBLE MASS /mg:   ,0
#REFERENCE CRUCIBLE MASS /mg:,0
#M.RANGE /¶ÃV:                ,5000
#TAU-R:                      ,---
#CORR. CODE:                 ,000
#EXO:                        ,+1
#RANGE:                      ,20°„C/10.0(K/min)/120°„C
#SEGMENT:                    ,S1/1
#SEG. 1:                     ,20°„C/10.0(K/min)/120°„C

#*RESULTS:     ,File,Segment,Result,Unit,Y_value,Unit ,Range_Xmin,Unit,Range_Xmax,Unit,Range_Ymin,Unit ,Range_Ymax,Unit
#*Area (DSC)(o),¿‰’•2 ,1      ,-50.77,J/g ,-      ,-    ,42.3      ,°„C  ,112.2     ,°„C  ,-0.4249   ,mW/mg,-0.6664   ,mW/mg
#*Onset (DSC)  ,¿‰’•2 ,1      ,42.3  ,°„C  ,-0.4015,mW/mg,25.8      ,°„C  ,88.3      ,°„C  ,-0.3704   ,mW/mg,-0.7892   ,mW/mg
#*Peak (DSC)   ,¿‰’•2 ,1      ,90.1  ,°„C  ,-0.7905,mW/mg,25.8      ,°„C  ,102.0     ,°„C  ,-0.3704   ,mW/mg,-0.751    ,mW/mg
#*End (DSC)    ,¿‰’•2 ,1      ,112.2 ,°„C  ,-0.6679,mW/mg,91.0      ,°„C  ,119.9     ,°„C  ,-0.7903   ,mW/mg,-0.5908   ,mW/mg

##Temp./°„C,Time/min,DSC/(mW/mg),Sensit./(uV/mW),Segment
  7.85400,0.00000, 1.728615e-002,3.29862,1
  7.85557,0.01000, 1.229544e-002,3.29862,1
  7.85815,0.02000, 7.701047e-003,3.29862,1
  7.86642,0.03000, 3.317337e-003,3.29862,1
  7.88532,0.04000,-1.067723e-003,3.29862,1
  7.91777,0.05000,-5.665357e-003,3.29862,1
  7.96449,0.06000,-1.155863e-002,3.29862,1
  8.02449,0.07000,-1.959460e-002,3.29862,1
  8.09618,0.08000,-2.948202e-002,3.29862,1
  8.17793,0.09000,-4.127317e-002,3.29862,1
  8.26772,0.10000,-5.422929e-002,3.29862,1
  8.33787,0.11000,-6.858830e-002,3.29862,1
  8.41428,0.12000,-8.289639e-002,3.29862,1
  8.49695,0.13000,-9.733841e-002,3.29862,1
  8.58584,0.14000,      -0.11176,3.29861,1
  8.68075,0.15000,      -0.12578,3.29861,1
  8.78134,0.16000,      -0.13893,3.29861,1
  8.88723,0.17000,      -0.15137,3.29861,1
  8.99772,0.18000,      -0.16308,3.29861,1
  9.11225,0.19000,      -0.17412,3.29861,1
  9.23039,0.20000,      -0.18443,3.29860,1
  9.35152,0.21000,      -0.19389,3.29860,1
  9.47513,0.22000,      -0.20279,3.29860,1
  9.60084,0.23000,      -0.21099,3.29859,1
  9.72830,0.24000,      -0.21823,3.29859,1
  9.85721,0.25000,      -0.22524,3.29859,1
  9.98741,0.26000,      -0.23208,3.29858,1
 10.11854,0.27000,      -0.23798,3.29858,1
 10.25054,0.28000,      -0.24364,3.29858,1
 10.38328,0.29000,      -0.24888,3.29857,1
 10.51672,0.30000,      -0.25404,3.29857,1
 10.65075,0.31000,      -0.25867,3.29856,1
 10.78528,0.32000,      -0.26293,3.29856,1
 10.92036,0.33000,      -0.26698,3.29855,1
 11.05590,0.34000,      -0.27103,3.29855,1
 11.19187,0.35000,      -0.27487,3.29854,1
 11.32833,0.36000,      -0.27837,3.29853,1
 11.46520,0.37000,      -0.28173,3.29853,1
 11.60261,0.38000,      -0.28473,3.29852,1
 11.74043,0.39000,      -0.28780,3.29851,1
 11.87870,0.40000,      -0.29082,3.29851,1
 12.01743,0.41000,      -0.29361,3.29850,1
 12.15662,0.42000,      -0.29610,3.29849,1
 12.29623,0.43000,      -0.29852,3.29849,1
 12.43626,0.44000,      -0.30098,3.29848,1
 12.57679,0.45000,      -0.30340,3.29847,1
 12.71767,0.46000,      -0.30573,3.29846,1
 12.85902,0.47000,      -0.30789,3.29845,1
 13.00074,0.48000,      -0.31001,3.29844,1
 13.14284,0.49000,      -0.31182,3.29844,1
 13.28534,0.50000,      -0.31368,3.29843,1
 13.42820,0.51000,      -0.31567,3.29842,1
 13.57146,0.52000,      -0.31754,3.29841,1
 13.71503,0.53000,      -0.31926,3.29840,1
 13.85902,0.54000,      -0.32076,3.29839,1
 14.00331,0.55000,      -0.32246,3.29838,1
 14.14787,0.56000,      -0.32419,3.29836,1
 14.29272,0.57000,      -0.32584,3.29835,1
 14.43784,0.58000,      -0.32710,3.29834,1
 14.58320,0.59000,      -0.32835,3.29833,1
 14.72887,0.60000,      -0.32974,3.29832,1
 14.87470,0.61000,      -0.33107,3.29831,1
 15.02082,0.62000,      -0.33243,3.29829,1
 15.16713,0.63000,      -0.33369,3.29828,1
 15.31364,0.64000,      -0.33489,3.29827,1
 15.46033,0.65000,      -0.33586,3.29826,1
 15.60723,0.66000,      -0.33714,3.29824,1
 15.75428,0.67000,      -0.33845,3.29823,1
 15.90151,0.68000,      -0.33955,3.29822,1
 16.04892,0.69000,      -0.34033,3.29820,1
 16.19646,0.70000,      -0.34132,3.29819,1
 16.34410,0.71000,      -0.34231,3.29817,1
 16.49177,0.72000,      -0.34333,3.29816,1
 16.63957,0.73000,      -0.34416,3.29814,1
 16.78744,0.74000,      -0.34492,3.29813,1
 16.93539,0.75000,      -0.34604,3.29811,1
 17.08339,0.76000,      -0.34701,3.29810,1
 17.23143,0.77000,      -0.34779,3.29808,1
 17.37957,0.78000,      -0.34839,3.29806,1
 17.52770,0.79000,      -0.34911,3.29805,1
 17.67584,0.80000,      -0.34984,3.29803,1
 17.82400,0.81000,      -0.35052,3.29801,1
 17.97215,0.82000,      -0.35130,3.29800,1
 18.12021,0.83000,      -0.35197,3.29798,1
 18.26831,0.84000,      -0.35257,3.29796,1
 18.41636,0.85000,      -0.35314,3.29794,1
 18.56434,0.86000,      -0.35376,3.29792,1
 18.71234,0.87000,      -0.35441,3.29791,1
 18.86025,0.88000,      -0.35509,3.29789,1
 19.00803,0.89000,      -0.35521,3.29787,1
 19.15577,0.90000,      -0.35589,3.29785,1
 19.30341,0.91000,      -0.35656,3.29783,1
 19.45105,0.92000,      -0.35687,3.29781,1
 19.59857,0.93000,      -0.35733,3.29779,1
 19.74602,0.94000,      -0.35777,3.29777,1
 19.89336,0.95000,      -0.35816,3.29775,1
 20.04064,0.96000,      -0.35883,3.29773,1
 20.18784,0.97000,      -0.35898,3.29771,1
 20.33485,0.98000,      -0.35955,3.29769,1
 20.48177,0.99000,      -0.35991,3.29767,1
 20.62862,1.00000,      -0.36040,3.29765,1
 20.77533,1.01000,      -0.36073,3.29762,1
 20.92190,1.02000,      -0.36109,3.29760,1
 21.06841,1.03000,      -0.36150,3.29758,1
 21.21479,1.04000,      -0.36176,3.29756,1
 21.36098,1.05000,      -0.36209,3.29754,1
 21.50705,1.06000,      -0.36266,3.29751,1
 21.65295,1.07000,      -0.36278,3.29749,1
 21.79866,1.08000,      -0.36314,3.29747,1
 21.94434,1.09000,      -0.36337,3.29744,1
 22.08980,1.10000,      -0.36380,3.29742,1
 22.23508,1.11000,      -0.36411,3.29740,1
 22.38031,1.12000,      -0.36450,3.29737,1
 22.52528,1.13000,      -0.36480,3.29735,1
 22.67010,1.14000,      -0.36484,3.29732,1
 22.81472,1.15000,      -0.36504,3.29730,1
 22.95923,1.16000,      -0.36556,3.29727,1
 23.10346,1.17000,      -0.36581,3.29725,1
 23.24754,1.18000,      -0.36607,3.29722,1
 23.39157,1.19000,      -0.36613,3.29720,1
 23.53538,1.20000,      -0.36631,3.29717,1
 23.67898,1.21000,      -0.36698,3.29715,1
 23.82239,1.22000,      -0.36721,3.29712,1
 23.96564,1.23000,      -0.36741,3.29710,1
 24.10869,1.24000,      -0.36745,3.29707,1
 24.25166,1.25000,      -0.36778,3.29704,1
 24.39443,1.26000,      -0.36791,3.29702,1
 24.53702,1.27000,      -0.36808,3.29699,1
 24.67944,1.28000,      -0.36831,3.29696,1
 24.82164,1.29000,      -0.36858,3.29694,1
 24.96370,1.30000,      -0.36892,3.29691,1
 25.10556,1.31000,      -0.36927,3.29688,1
 25.24720,1.32000,      -0.36953,3.29685,1
 25.38869,1.33000,      -0.36975,3.29682,1
 25.52997,1.34000,      -0.36995,3.29680,1
 25.67111,1.35000,      -0.37002,3.29677,1
 25.81208,1.36000,      -0.37041,3.29674,1
 25.95285,1.37000,      -0.37069,3.29671,1
 26.09348,1.38000,      -0.37091,3.29668,1
 26.23384,1.39000,      -0.37101,3.29665,1
 26.37400,1.40000,      -0.37131,3.29662,1
 26.51397,1.41000,      -0.37140,3.29659,1
 26.65380,1.42000,      -0.37163,3.29656,1
 26.79338,1.43000,      -0.37183,3.29654,1
 26.93279,1.44000,      -0.37206,3.29651,1
 27.07192,1.45000,      -0.37233,3.29648,1
 27.21089,1.46000,      -0.37261,3.29645,1
 27.34964,1.47000,      -0.37281,3.29641,1
 27.48825,1.48000,      -0.37299,3.29638,1
 27.62664,1.49000,      -0.37319,3.29635,1
 27.76477,1.50000,      -0.37349,3.29632,1
 27.90279,1.51000,      -0.37380,3.29629,1
 28.04061,1.52000,      -0.37405,3.29626,1
 28.17816,1.53000,      -0.37417,3.29623,1
 28.31554,1.54000,      -0.37453,3.29620,1
 28.45266,1.55000,      -0.37480,3.29617,1
 28.58962,1.56000,      -0.37495,3.29613,1
 28.72639,1.57000,      -0.37523,3.29610,1
 28.86292,1.58000,      -0.37540,3.29607,1
 28.99923,1.59000,      -0.37552,3.29604,1
 29.13536,1.60000,      -0.37601,3.29600,1
 29.27133,1.61000,      -0.37608,3.29597,1
 29.40711,1.62000,      -0.37630,3.29594,1
 29.54267,1.63000,      -0.37666,3.29591,1
 29.67803,1.64000,      -0.37681,3.29587,1
 29.81326,1.65000,      -0.37706,3.29584,1
 29.94826,1.66000,      -0.37728,3.29581,1
 30.08310,1.67000,      -0.37764,3.29577,1
 30.21777,1.68000,      -0.37792,3.29574,1
 30.35223,1.69000,      -0.37820,3.29571,1
 30.48644,1.70000,      -0.37855,3.29567,1
 30.62048,1.71000,      -0.37894,3.29564,1
 30.75433,1.72000,      -0.37908,3.29560,1
 30.88807,1.73000,      -0.37926,3.29557,1
 31.02157,1.74000,      -0.37938,3.29553,1
 31.15497,1.75000,      -0.37986,3.29550,1
 31.28810,1.76000,      -0.38041,3.29546,1
 31.42105,1.77000,      -0.38053,3.29543,1
 31.55385,1.78000,      -0.38078,3.29539,1
 31.68641,1.79000,      -0.38116,3.29536,1
 31.81880,1.80000,      -0.38154,3.29532,1
 31.95100,1.81000,      -0.38190,3.29529,1
 32.08305,1.82000,      -0.38221,3.29525,1
 32.21489,1.83000,      -0.38262,3.29522,1
 32.34654,1.84000,      -0.38279,3.29518,1
 32.47808,1.85000,      -0.38299,3.29514,1
 32.60948,1.86000,      -0.38337,3.29511,1
 32.74070,1.87000,      -0.38375,3.29507,1
 32.87169,1.88000,      -0.38411,3.29503,1
 33.00249,1.89000,      -0.38457,3.29500,1
 33.13323,1.90000,      -0.38498,3.29496,1
 33.26382,1.91000,      -0.38528,3.29492,1
 33.39421,1.92000,      -0.38559,3.29489,1
 33.52443,1.93000,      -0.38592,3.29485,1
 33.65443,1.94000,      -0.38625,3.29481,1
 33.78433,1.95000,      -0.38661,3.29477,1
 33.91407,1.96000,      -0.38710,3.29474,1
 34.04367,1.97000,      -0.38748,3.29470,1
 34.17310,1.98000,      -0.38789,3.29466,1
 34.30246,1.99000,      -0.38851,3.29462,1
 34.43166,2.00000,      -0.38902,3.29458,1
 34.56069,2.01000,      -0.38906,3.29455,1
 34.68959,2.02000,      -0.38966,3.29451,1
 34.81831,2.03000,      -0.39015,3.29447,1
 34.94689,2.04000,      -0.39069,3.29443,1
 35.07526,2.05000,      -0.39126,3.29439,1
 35.20344,2.06000,      -0.39172,3.29435,1
 35.33146,2.07000,      -0.39194,3.29431,1
 35.45936,2.08000,      -0.39251,3.29427,1
 35.58705,2.09000,      -0.39297,3.29423,1
 35.71456,2.10000,      -0.39344,3.29420,1
 35.84195,2.11000,      -0.39387,3.29416,1
 35.96925,2.12000,      -0.39449,3.29412,1
 36.09625,2.13000,      -0.39495,3.29408,1
 36.22325,2.14000,      -0.39544,3.29404,1
 36.35008,2.15000,      -0.39591,3.29400,1
 36.47672,2.16000,      -0.39629,3.29395,1
 36.60325,2.17000,      -0.39683,3.29391,1
 36.72961,2.18000,      -0.39708,3.29387,1
 36.85582,2.19000,      -0.39749,3.29383,1
 36.98184,2.20000,      -0.39808,3.29379,1
 37.10770,2.21000,      -0.39862,3.29375,1
 37.23339,2.22000,      -0.39922,3.29371,1
 37.35897,2.23000,      -0.39981,3.29367,1
 37.48448,2.24000,      -0.40038,3.29363,1
 37.60972,2.25000,      -0.40095,3.29359,1
 37.73489,2.26000,      -0.40117,3.29355,1
 37.85985,2.27000,      -0.40185,3.29350,1
 37.98470,2.28000,      -0.40247,3.29346,1
 38.10936,2.29000,      -0.40303,3.29342,1
 38.23400,2.30000,      -0.40366,3.29338,1
 38.35846,2.31000,      -0.40425,3.29334,1
 38.48269,2.32000,      -0.40442,3.29329,1
 38.60690,2.33000,      -0.40523,3.29325,1
 38.73095,2.34000,      -0.40563,3.29321,1
 38.85475,2.35000,      -0.40633,3.29317,1
 38.97848,2.36000,      -0.40693,3.29312,1
 39.10202,2.37000,      -0.40752,3.29308,1
 39.22539,2.38000,      -0.40812,3.29304,1
 39.34862,2.39000,      -0.40876,3.29299,1
 39.47175,2.40000,      -0.40936,3.29295,1
 39.59479,2.41000,      -0.40971,3.29291,1
 39.71761,2.42000,      -0.41028,3.29286,1
 39.84033,2.43000,      -0.41088,3.29282,1
 39.96285,2.44000,      -0.41168,3.29278,1
 40.08529,2.45000,      -0.41243,3.29273,1
 40.20756,2.46000,      -0.41311,3.29269,1
 40.32985,2.47000,      -0.41325,3.29265,1
 40.45192,2.48000,      -0.41382,3.29260,1
 40.57400,2.49000,      -0.41452,3.29256,1
 40.69585,2.50000,      -0.41540,3.29251,1
 40.81761,2.51000,      -0.41600,3.29247,1
 40.93925,2.52000,      -0.41633,3.29242,1
 41.06077,2.53000,      -0.41727,3.29238,1
 41.18216,2.54000,      -0.41786,3.29233,1
 41.30344,2.55000,      -0.41856,3.29229,1
 41.42464,2.56000,      -0.41947,3.29224,1
 41.54577,2.57000,      -0.42004,3.29220,1
 41.66682,2.58000,      -0.42074,3.29215,1
 41.78780,2.59000,      -0.42149,3.29211,1
 41.90872,2.60000,      -0.42219,3.29206,1
 42.02952,2.61000,      -0.42300,3.29202,1
 42.15023,2.62000,      -0.42388,3.29197,1
 42.27089,2.63000,      -0.42477,3.29192,1
 42.39141,2.64000,      -0.42526,3.29188,1
 42.51189,2.65000,      -0.42598,3.29183,1
 42.63233,2.66000,      -0.42679,3.29179,1
 42.75261,2.67000,      -0.42773,3.29174,1
 42.87279,2.68000,      -0.42845,3.29169,1
 42.99289,2.69000,      -0.42918,3.29165,1
 43.11289,2.70000,      -0.43001,3.29160,1
 43.23285,2.71000,      -0.43090,3.29155,1
 43.35267,2.72000,      -0.43176,3.29151,1
 43.47241,2.73000,      -0.43259,3.29146,1
 43.59205,2.74000,      -0.43345,3.29141,1
 43.71164,2.75000,      -0.43436,3.29136,1
 43.83116,2.76000,      -0.43522,3.29132,1
 43.95062,2.77000,      -0.43600,3.29127,1
 44.06997,2.78000,      -0.43675,3.29122,1
 44.18925,2.79000,      -0.43764,3.29117,1
 44.30844,2.80000,      -0.43852,3.29112,1
 44.42746,2.81000,      -0.43917,3.29108,1
 44.54644,2.82000,      -0.44005,3.29103,1
 44.66528,2.83000,      -0.44118,3.29098,1
 44.78405,2.84000,      -0.44190,3.29093,1
 44.90274,2.85000,      -0.44279,3.29088,1
 45.02125,2.86000,      -0.44362,3.29083,1
 45.13970,2.87000,      -0.44440,3.29079,1
 45.25810,2.88000,      -0.44500,3.29074,1
 45.37634,2.89000,      -0.44477,3.29069,1
 45.49448,2.90000,      -0.44571,3.29064,1
 45.61246,2.91000,      -0.44683,3.29059,1
 45.73043,2.92000,      -0.44801,3.29054,1
 45.84825,2.93000,      -0.44903,3.29049,1
 45.96602,2.94000,      -0.44997,3.29044,1
 46.08362,2.95000,      -0.45112,3.29039,1
 46.20116,2.96000,      -0.45206,3.29034,1
 46.31854,2.97000,      -0.45315,3.29029,1
 46.43584,2.98000,      -0.45417,3.29024,1
 46.55293,2.99000,      -0.45524,3.29019,1
 46.66993,3.00000,      -0.45636,3.29014,1
 46.78687,3.01000,      -0.45738,3.29009,1
 46.90377,3.02000,      -0.45830,3.29004,1
 47.02052,3.03000,      -0.45931,3.28999,1
 47.13718,3.04000,      -0.46033,3.28994,1
 47.25377,3.05000,      -0.46135,3.28989,1
 47.37033,3.06000,      -0.46237,3.28984,1
 47.48672,3.07000,      -0.46336,3.28979,1
 47.60302,3.08000,      -0.46422,3.28974,1
 47.71923,3.09000,      -0.46529,3.28968,1
 47.83536,3.10000,      -0.46644,3.28963,1
 47.95148,3.11000,      -0.46719,3.28958,1
 48.06748,3.12000,      -0.46827,3.28953,1
 48.18346,3.13000,      -0.46934,3.28948,1
 48.29928,3.14000,      -0.47038,3.28943,1
 48.41505,3.15000,      -0.47161,3.28938,1
 48.53064,3.16000,      -0.47231,3.28932,1
 48.64616,3.17000,      -0.47354,3.28927,1
 48.76157,3.18000,      -0.47451,3.28922,1
 48.87697,3.19000,      -0.47539,3.28917,1
 48.99229,3.20000,      -0.47633,3.28911,1
 49.10746,3.21000,      -0.47743,3.28906,1
 49.22256,3.22000,      -0.47842,3.28901,1
 49.33759,3.23000,      -0.47942,3.28896,1
 49.45256,3.24000,      -0.48025,3.28890,1
 49.56734,3.25000,      -0.48122,3.28885,1
 49.68205,3.26000,      -0.48245,3.28880,1
 49.79672,3.27000,      -0.48354,3.28875,1
 49.91134,3.28000,      -0.48435,3.28869,1
 50.02584,3.29000,      -0.48532,3.28864,1
 50.14025,3.30000,      -0.48628,3.28859,1
 50.25457,3.31000,      -0.48727,3.28853,1
 50.36877,3.32000,      -0.48827,3.28848,1
 50.48284,3.33000,      -0.48934,3.28843,1
 50.59685,3.34000,      -0.49028,3.28837,1
 50.71079,3.35000,      -0.49132,3.28832,1
 50.82467,3.36000,      -0.49234,3.28826,1
 50.93852,3.37000,      -0.49331,3.28821,1
 51.05228,3.38000,      -0.49433,3.28816,1
 51.16600,3.39000,      -0.49548,3.28810,1
 51.27962,3.40000,      -0.49623,3.28805,1
 51.39313,3.41000,      -0.49757,3.28799,1
 51.50664,3.42000,      -0.49877,3.28794,1
 51.62002,3.43000,      -0.49977,3.28788,1
 51.73338,3.44000,      -0.50076,3.28783,1
 51.84669,3.45000,      -0.50178,3.28777,1
 51.95989,3.46000,      -0.50277,3.28772,1
 52.07300,3.47000,      -0.50368,3.28766,1
 52.18598,3.48000,      -0.50462,3.28761,1
 52.29897,3.49000,      -0.50583,3.28755,1
 52.41185,3.50000,      -0.50703,3.28750,1
 52.52466,3.51000,      -0.50813,3.28744,1
 52.63743,3.52000,      -0.50905,3.28739,1
 52.75010,3.53000,      -0.51004,3.28733,1
 52.86270,3.54000,      -0.51111,3.28728,1
 52.97533,3.55000,      -0.51218,3.28722,1
 53.08782,3.56000,      -0.51323,3.28716,1
 53.20020,3.57000,      -0.51430,3.28711,1
 53.31251,3.58000,      -0.51532,3.28705,1
 53.42472,3.59000,      -0.51647,3.28700,1
 53.53685,3.60000,      -0.51747,3.28694,1
 53.64898,3.61000,      -0.51851,3.28688,1
 53.76100,3.62000,      -0.51961,3.28683,1
 53.87300,3.63000,      -0.52074,3.28677,1
 53.98484,3.64000,      -0.52184,3.28671,1
 54.09657,3.65000,      -0.52283,3.28666,1
 54.20836,3.66000,      -0.52372,3.28660,1
 54.32002,3.67000,      -0.52471,3.28654,1
 54.43164,3.68000,      -0.52581,3.28649,1
 54.54325,3.69000,      -0.52696,3.28643,1
 54.65472,3.70000,      -0.52819,3.28637,1
 54.76620,3.71000,      -0.52921,3.28631,1
 54.87754,3.72000,      -0.53018,3.28626,1
 54.98892,3.73000,      -0.53118,3.28620,1
 55.10020,3.74000,      -0.53225,3.28614,1
 55.21139,3.75000,      -0.53329,3.28608,1
 55.32262,3.76000,      -0.53458,3.28602,1
 55.43377,3.77000,      -0.53536,3.28597,1
 55.54495,3.78000,      -0.53662,3.28591,1
 55.65607,3.79000,      -0.53783,3.28585,1
 55.76708,3.80000,      -0.53903,3.28579,1
 55.87808,3.81000,      -0.54008,3.28573,1
 55.98905,3.82000,      -0.54115,3.28567,1
 56.09995,3.83000,      -0.54231,3.28562,1
 56.21082,3.84000,      -0.54351,3.28556,1
 56.32170,3.85000,      -0.54467,3.28550,1
 56.43254,3.86000,      -0.54579,3.28544,1
 56.54334,3.87000,      -0.54692,3.28538,1
 56.65405,3.88000,      -0.54805,3.28532,1
 56.76467,3.89000,      -0.54907,3.28526,1
 56.87531,3.90000,      -0.55046,3.28520,1
 56.98587,3.91000,      -0.55129,3.28514,1
 57.09644,3.92000,      -0.55242,3.28508,1
 57.20690,3.93000,      -0.55371,3.28502,1
 57.31731,3.94000,      -0.55483,3.28496,1
 57.42770,3.95000,      -0.55564,3.28490,1
 57.53800,3.96000,      -0.55701,3.28484,1
 57.64825,3.97000,      -0.55792,3.28478,1
 57.75849,3.98000,      -0.55926,3.28472,1
 57.86864,3.99000,      -0.56042,3.28466,1
 57.97872,4.00000,      -0.56170,3.28460,1
 58.08879,4.01000,      -0.56270,3.28454,1
 58.19875,4.02000,      -0.56372,3.28448,1
 58.30864,4.03000,      -0.56479,3.28442,1
 58.41846,4.04000,      -0.56579,3.28436,1
 58.52825,4.05000,      -0.56673,3.28430,1
 58.63802,4.06000,      -0.56778,3.28423,1
 58.74766,4.07000,      -0.56883,3.28417,1
 58.85731,4.08000,      -0.57003,3.28411,1
 58.96697,4.09000,      -0.57106,3.28405,1
 59.07649,4.10000,      -0.57218,3.28399,1
 59.18597,4.11000,      -0.57326,3.28393,1
 59.29543,4.12000,      -0.57444,3.28387,1
 59.40482,4.13000,      -0.57557,3.28380,1
 59.51413,4.14000,      -0.57664,3.28374,1
 59.62343,4.15000,      -0.57766,3.28368,1
 59.73261,4.16000,      -0.57879,3.28362,1
 59.84172,4.17000,      -0.57992,3.28356,1
 59.95082,4.18000,      -0.58099,3.28349,1
 60.05989,4.19000,      -0.58212,3.28343,1
 60.16893,4.20000,      -0.58328,3.28337,1
 60.27792,4.21000,      -0.58438,3.28331,1
 60.38682,4.22000,      -0.58548,3.28324,1
 60.49572,4.23000,      -0.58658,3.28318,1
 60.60462,4.24000,      -0.58768,3.28312,1
 60.71343,4.25000,      -0.58865,3.28305,1
 60.82213,4.26000,      -0.58983,3.28299,1
 60.93084,4.27000,      -0.59096,3.28293,1
 61.03952,4.28000,      -0.59215,3.28286,1
 61.14815,4.29000,      -0.59304,3.28280,1
 61.25672,4.30000,      -0.59398,3.28274,1
 61.36528,4.31000,      -0.59505,3.28267,1
 61.47375,4.32000,      -0.59645,3.28261,1
 61.58221,4.33000,      -0.59755,3.28255,1
 61.69064,4.34000,      -0.59865,3.28248,1
 61.79902,4.35000,      -0.59978,3.28242,1
 61.90739,4.36000,      -0.60094,3.28235,1
 62.01566,4.37000,      -0.60209,3.28229,1
 62.12395,4.38000,      -0.60298,3.28223,1
 62.23218,4.39000,      -0.60398,3.28216,1
 62.34036,4.40000,      -0.60511,3.28210,1
 62.44849,4.41000,      -0.60621,3.28203,1
 62.55659,4.42000,      -0.60723,3.28197,1
 62.66462,4.43000,      -0.60828,3.28190,1
 62.77261,4.44000,      -0.60936,3.28184,1
 62.88061,4.45000,      -0.61046,3.28177,1
 62.98852,4.46000,      -0.61173,3.28171,1
 63.09641,4.47000,      -0.61275,3.28164,1
 63.20426,4.48000,      -0.61375,3.28158,1
 63.31208,4.49000,      -0.61482,3.28151,1
 63.41990,4.50000,      -0.61606,3.28145,1
 63.52762,4.51000,      -0.61724,3.28138,1
 63.63533,4.52000,      -0.61797,3.28131,1
 63.74298,4.53000,      -0.61886,3.28125,1
 63.85064,4.54000,      -0.62021,3.28118,1
 63.95826,4.55000,      -0.62128,3.28112,1
 64.06580,4.56000,      -0.62231,3.28105,1
 64.17333,4.57000,      -0.62325,3.28098,1
 64.28084,4.58000,      -0.62441,3.28092,1
 64.38823,4.59000,      -0.62549,3.28085,1
 64.49557,4.60000,      -0.62659,3.28079,1
 64.60289,4.61000,      -0.62767,3.28072,1
 64.71020,4.62000,      -0.62872,3.28065,1
 64.81746,4.63000,      -0.62977,3.28059,1
 64.92469,4.64000,      -0.63095,3.28052,1
 65.03187,4.65000,      -0.63203,3.28045,1
 65.13902,4.66000,      -0.63303,3.28038,1
 65.24613,4.67000,      -0.63408,3.28032,1
 65.35318,4.68000,      -0.63513,3.28025,1
 65.46028,4.69000,      -0.63615,3.28018,1
 65.56726,4.70000,      -0.63726,3.28011,1
 65.67425,4.71000,      -0.63849,3.28005,1
 65.78120,4.72000,      -0.63955,3.27998,1
 65.88816,4.73000,      -0.64054,3.27991,1
 65.99507,4.74000,      -0.64154,3.27984,1
 66.10192,4.75000,      -0.64265,3.27978,1
 66.20872,4.76000,      -0.64375,3.27971,1
 66.31559,4.77000,      -0.64483,3.27964,1
 66.42239,4.78000,      -0.64538,3.27957,1
 66.52916,4.79000,      -0.64667,3.27950,1
 66.63593,4.80000,      -0.64780,3.27943,1
 66.74269,4.81000,      -0.64893,3.27937,1
 66.84943,4.82000,      -0.65006,3.27930,1
 66.95613,4.83000,      -0.65117,3.27923,1
 67.06280,4.84000,      -0.65232,3.27916,1
 67.16948,4.85000,      -0.65343,3.27909,1
 67.27616,4.86000,      -0.65448,3.27902,1
 67.38280,4.87000,      -0.65548,3.27895,1
 67.48948,4.88000,      -0.65648,3.27888,1
 67.59605,4.89000,      -0.65748,3.27881,1
 67.70261,4.90000,      -0.65856,3.27874,1
 67.80916,4.91000,      -0.65974,3.27867,1
 67.91570,4.92000,      -0.66056,3.27860,1
 68.02215,4.93000,      -0.66185,3.27853,1
 68.12861,4.94000,      -0.66295,3.27846,1
 68.23503,4.95000,      -0.66409,3.27839,1
 68.34144,4.96000,      -0.66514,3.27832,1
 68.44772,4.97000,      -0.66622,3.27825,1
 68.55408,4.98000,      -0.66727,3.27818,1
 68.66038,4.99000,      -0.66816,3.27811,1
 68.76664,5.00000,      -0.66914,3.27804,1
 68.87285,5.01000,      -0.67027,3.27797,1
 68.97908,5.02000,      -0.67132,3.27790,1
 69.08523,5.03000,      -0.67232,3.27783,1
 69.19136,5.04000,      -0.67353,3.27776,1
 69.29748,5.05000,      -0.67456,3.27769,1
 69.40346,5.06000,      -0.67545,3.27761,1
 69.50943,5.07000,      -0.67643,3.27754,1
 69.61531,5.08000,      -0.67738,3.27747,1
 69.72120,5.09000,      -0.67848,3.27740,1
 69.82705,5.10000,      -0.67959,3.27733,1
 69.93285,5.11000,      -0.68032,3.27726,1
 70.03869,5.12000,      -0.68135,3.27719,1
 70.14444,5.13000,      -0.68256,3.27711,1
 70.25010,5.14000,      -0.68372,3.27704,1
 70.35572,5.15000,      -0.68470,3.27697,1
 70.46134,5.16000,      -0.68556,3.27690,1
 70.56700,5.17000,      -0.68635,3.27683,1
 70.67257,5.18000,      -0.68749,3.27675,1
 70.77810,5.19000,      -0.68851,3.27668,1
 70.88361,5.20000,      -0.68925,3.27661,1
 70.98905,5.21000,      -0.69030,3.27654,1
 71.09451,5.22000,      -0.69125,3.27646,1
 71.19992,5.23000,      -0.69238,3.27639,1
 71.30533,5.24000,      -0.69336,3.27632,1
 71.41064,5.25000,      -0.69425,3.27624,1
 71.51603,5.26000,      -0.69523,3.27617,1
 71.62141,5.27000,      -0.69612,3.27610,1
 71.72677,5.28000,      -0.69710,3.27602,1
 71.83208,5.29000,      -0.69794,3.27595,1
 71.93730,5.30000,      -0.69889,3.27588,1
 72.04261,5.31000,      -0.70002,3.27580,1
 72.14782,5.32000,      -0.70065,3.27573,1
 72.25302,5.33000,      -0.70187,3.27566,1
 72.35828,5.34000,      -0.70279,3.27558,1
 72.46356,5.35000,      -0.70368,3.27551,1
 72.56875,5.36000,      -0.70463,3.27543,1
 72.67393,5.37000,      -0.70539,3.27536,1
 72.77902,5.38000,      -0.70640,3.27529,1
 72.88408,5.39000,      -0.70756,3.27521,1
 72.98918,5.40000,      -0.70853,3.27514,1
 73.09423,5.41000,      -0.70945,3.27506,1
 73.19926,5.42000,      -0.71048,3.27499,1
 73.30421,5.43000,      -0.71143,3.27491,1
 73.40918,5.44000,      -0.71230,3.27484,1
 73.51418,5.45000,      -0.71320,3.27476,1
 73.61907,5.46000,      -0.71399,3.27469,1
 73.72393,5.47000,      -0.71491,3.27461,1
 73.82880,5.48000,      -0.71583,3.27454,1
 73.93361,5.49000,      -0.71678,3.27446,1
 74.03843,5.50000,      -0.71762,3.27439,1
 74.14316,5.51000,      -0.71852,3.27431,1
 74.24792,5.52000,      -0.71947,3.27423,1
 74.35259,5.53000,      -0.72034,3.27416,1
 74.45728,5.54000,      -0.72081,3.27408,1
 74.56190,5.55000,      -0.72195,3.27401,1
 74.66646,5.56000,      -0.72330,3.27393,1
 74.77107,5.57000,      -0.72395,3.27386,1
 74.87566,5.58000,      -0.72469,3.27378,1
 74.98023,5.59000,      -0.72572,3.27370,1
 75.08480,5.60000,      -0.72651,3.27363,1
 75.18934,5.61000,      -0.72719,3.27355,1
 75.29380,5.62000,      -0.72806,3.27347,1
 75.39830,5.63000,      -0.72893,3.27340,1
 75.50275,5.64000,      -0.72964,3.27332,1
 75.60720,5.65000,      -0.73052,3.27324,1
 75.71162,5.66000,      -0.73136,3.27316,1
 75.81607,5.67000,      -0.73223,3.27309,1
 75.92048,5.68000,      -0.73305,3.27301,1
 76.02487,5.69000,      -0.73389,3.27293,1
 76.12923,5.70000,      -0.73471,3.27286,1
 76.23357,5.71000,      -0.73553,3.27278,1
 76.33785,5.72000,      -0.73629,3.27270,1
 76.44216,5.73000,      -0.73697,3.27262,1
 76.54644,5.74000,      -0.73766,3.27254,1
 76.65077,5.75000,      -0.73869,3.27247,1
 76.75505,5.76000,      -0.73924,3.27239,1
 76.85928,5.77000,      -0.74022,3.27231,1
 76.96351,5.78000,      -0.74104,3.27223,1
 77.06769,5.79000,      -0.74178,3.27215,1
 77.17184,5.80000,      -0.74262,3.27208,1
 77.27598,5.81000,      -0.74317,3.27200,1
 77.38015,5.82000,      -0.74383,3.27192,1
 77.48423,5.83000,      -0.74462,3.27184,1
 77.58839,5.84000,      -0.74549,3.27176,1
 77.69257,5.85000,      -0.74621,3.27168,1
 77.79661,5.86000,      -0.74708,3.27160,1
 77.90062,5.87000,      -0.74782,3.27152,1
 78.00464,5.88000,      -0.74861,3.27144,1
 78.10859,5.89000,      -0.74929,3.27136,1
 78.21261,5.90000,      -0.74969,3.27128,1
 78.31656,5.91000,      -0.75042,3.27121,1
 78.42054,5.92000,      -0.75127,3.27113,1
 78.52446,5.93000,      -0.75203,3.27105,1
 78.62839,5.94000,      -0.75275,3.27097,1
 78.73223,5.95000,      -0.75362,3.27089,1
 78.83602,5.96000,      -0.75433,3.27081,1
 78.93990,5.97000,      -0.75467,3.27073,1
 79.04372,5.98000,      -0.75536,3.27065,1
 79.14751,5.99000,      -0.75610,3.27057,1
 79.25128,6.00000,      -0.75689,3.27048,1
 79.35500,6.01000,      -0.75723,3.27040,1
 79.45877,6.02000,      -0.75797,3.27032,1
 79.56249,6.03000,      -0.75889,3.27024,1
 79.66618,6.04000,      -0.75939,3.27016,1
 79.76979,6.05000,      -0.76011,3.27008,1
 79.87341,6.06000,      -0.76071,3.27000,1
 79.97698,6.07000,      -0.76129,3.26992,1
 80.08061,6.08000,      -0.76161,3.26984,1
 80.18423,6.09000,      -0.76240,3.26976,1
 80.28777,6.10000,      -0.76303,3.26967,1
 80.39130,6.11000,      -0.76359,3.26959,1
 80.49484,6.12000,      -0.76417,3.26951,1
 80.59831,6.13000,      -0.76475,3.26943,1
 80.70184,6.14000,      -0.76527,3.26935,1
 80.80528,6.15000,      -0.76561,3.26927,1
 80.90879,6.16000,      -0.76617,3.26918,1
 81.01221,6.17000,      -0.76675,3.26910,1
 81.11559,6.18000,      -0.76733,3.26902,1
 81.21903,6.19000,      -0.76788,3.26894,1
 81.32249,6.20000,      -0.76835,3.26886,1
 81.42589,6.21000,      -0.76891,3.26877,1
 81.52930,6.22000,      -0.76912,3.26869,1
 81.63262,6.23000,      -0.76948,3.26861,1
 81.73600,6.24000,      -0.77020,3.26852,1
 81.83934,6.25000,      -0.77067,3.26844,1
 81.94266,6.26000,      -0.77125,3.26836,1
 82.04602,6.27000,      -0.77167,3.26828,1
 82.14930,6.28000,      -0.77209,3.26819,1
 82.25261,6.29000,      -0.77254,3.26811,1
 82.35584,6.30000,      -0.77304,3.26803,1
 82.45915,6.31000,      -0.77346,3.26794,1
 82.56238,6.32000,      -0.77386,3.26786,1
 82.66564,6.33000,      -0.77428,3.26777,1
 82.76887,6.34000,      -0.77475,3.26769,1
 82.87202,6.35000,      -0.77520,3.26761,1
 82.97521,6.36000,      -0.77557,3.26752,1
 83.07836,6.37000,      -0.77599,3.26744,1
 83.18159,6.38000,      -0.77644,3.26735,1
 83.28477,6.39000,      -0.77689,3.26727,1
 83.38785,6.40000,      -0.77725,3.26719,1
 83.49103,6.41000,      -0.77744,3.26710,1
 83.59415,6.42000,      -0.77756,3.26702,1
 83.69728,6.43000,      -0.77825,3.26693,1
 83.80043,6.44000,      -0.77854,3.26685,1
 83.90349,6.45000,      -0.77893,3.26676,1
 84.00656,6.46000,      -0.77933,3.26668,1
 84.10964,6.47000,      -0.77978,3.26659,1
 84.21267,6.48000,      -0.78012,3.26651,1
 84.31572,6.49000,      -0.78030,3.26642,1
 84.41880,6.50000,      -0.78083,3.26634,1
 84.52188,6.51000,      -0.78120,3.26625,1
 84.62490,6.52000,      -0.78162,3.26616,1
 84.72789,6.53000,      -0.78180,3.26608,1
 84.83087,6.54000,      -0.78204,3.26599,1
 84.93389,6.55000,      -0.78243,3.26591,1
 85.03685,6.56000,      -0.78275,3.26582,1
 85.13987,6.57000,      -0.78306,3.26573,1
 85.24272,6.58000,      -0.78341,3.26565,1
 85.34564,6.59000,      -0.78372,3.26556,1
 85.44861,6.60000,      -0.78380,3.26548,1
 85.55159,6.61000,      -0.78438,3.26539,1
 85.65448,6.62000,      -0.78453,3.26530,1
 85.75741,6.63000,      -0.78477,3.26522,1
 85.86028,6.64000,      -0.78503,3.26513,1
 85.96311,6.65000,      -0.78514,3.26504,1
 86.06603,6.66000,      -0.78529,3.26495,1
 86.16895,6.67000,      -0.78579,3.26487,1
 86.27185,6.68000,      -0.78595,3.26478,1
 86.37470,6.69000,      -0.78608,3.26469,1
 86.47752,6.70000,      -0.78629,3.26461,1
 86.58029,6.71000,      -0.78666,3.26452,1
 86.68310,6.72000,      -0.78692,3.26443,1
 86.78589,6.73000,      -0.78705,3.26434,1
 86.88867,6.74000,      -0.78720,3.26425,1
 86.99146,6.75000,      -0.78728,3.26417,1
 87.09418,6.76000,      -0.78744,3.26408,1
 87.19693,6.77000,      -0.78775,3.26399,1
 87.29970,6.78000,      -0.78802,3.26390,1
 87.40243,6.79000,      -0.78806,3.26381,1
 87.50511,6.80000,      -0.78817,3.26373,1
 87.60782,6.81000,      -0.78827,3.26364,1
 87.71048,6.82000,      -0.78848,3.26355,1
 87.81316,6.83000,      -0.78874,3.26346,1
 87.91582,6.84000,      -0.78895,3.26337,1
 88.01851,6.85000,      -0.78906,3.26328,1
 88.12111,6.86000,      -0.78913,3.26319,1
 88.22377,6.87000,      -0.78921,3.26310,1
 88.32634,6.88000,      -0.78926,3.26301,1
 88.42892,6.89000,      -0.78936,3.26292,1
 88.53146,6.90000,      -0.78944,3.26284,1
 88.63403,6.91000,      -0.78946,3.26275,1
 88.73656,6.92000,      -0.78962,3.26266,1
 88.83910,6.93000,      -0.78980,3.26257,1
 88.94162,6.94000,      -0.78982,3.26248,1
 89.04420,6.95000,      -0.78990,3.26239,1
 89.14672,6.96000,      -0.78998,3.26230,1
 89.24923,6.97000,      -0.79011,3.26221,1
 89.35175,6.98000,      -0.79013,3.26212,1
 89.45426,6.99000,      -0.79026,3.26203,1
 89.55674,7.00000,      -0.79028,3.26193,1
 89.65918,7.01000,      -0.79022,3.26184,1
 89.76161,7.02000,      -0.79022,3.26175,1
 89.86407,7.03000,      -0.79027,3.26166,1
 89.96649,7.04000,      -0.79037,3.26157,1
 90.06890,7.05000,      -0.79045,3.26148,1
 90.17128,7.06000,      -0.79047,3.26139,1
 90.27364,7.07000,      -0.79042,3.26130,1
 90.37600,7.08000,      -0.79039,3.26121,1
 90.47833,7.09000,      -0.79033,3.26112,1
 90.58070,7.10000,      -0.79035,3.26103,1
 90.68315,7.11000,      -0.79043,3.26093,1
 90.78552,7.12000,      -0.79043,3.26084,1
 90.88787,7.13000,      -0.79040,3.26075,1
 90.99020,7.14000,      -0.79037,3.26066,1
 91.09252,7.15000,      -0.79020,3.26057,1
 91.19480,7.16000,      -0.79017,3.26047,1
 91.29707,7.17000,      -0.78998,3.26038,1
 91.39934,7.18000,      -0.79006,3.26029,1
 91.50156,7.19000,      -0.79006,3.26020,1
 91.60379,7.20000,      -0.78989,3.26011,1
 91.70607,7.21000,      -0.78976,3.26001,1
 91.80826,7.22000,      -0.78981,3.25992,1
 91.91044,7.23000,      -0.78973,3.25983,1
 92.01261,7.24000,      -0.78962,3.25973,1
 92.11474,7.25000,      -0.78940,3.25964,1
 92.21690,7.26000,      -0.78916,3.25955,1
 92.31905,7.27000,      -0.78894,3.25946,1
 92.42118,7.28000,      -0.78883,3.25936,1
 92.52331,7.29000,      -0.78885,3.25927,1
 92.62546,7.30000,      -0.78880,3.25918,1
 92.72756,7.31000,      -0.78853,3.25908,1
 92.82969,7.32000,      -0.78820,3.25899,1
 92.93184,7.33000,      -0.78807,3.25889,1
 93.03392,7.34000,      -0.78804,3.25880,1
 93.13598,7.35000,      -0.78806,3.25871,1
 93.23803,7.36000,      -0.78768,3.25861,1
 93.34007,7.37000,      -0.78760,3.25852,1
 93.44211,7.38000,      -0.78760,3.25842,1
 93.54420,7.39000,      -0.78749,3.25833,1
 93.64623,7.40000,      -0.78722,3.25824,1
 93.74821,7.41000,      -0.78703,3.25814,1
 93.85025,7.42000,      -0.78668,3.25805,1
 93.95225,7.43000,      -0.78638,3.25795,1
 94.05431,7.44000,      -0.78619,3.25786,1
 94.15630,7.45000,      -0.78608,3.25776,1
 94.25833,7.46000,      -0.78597,3.25767,1
 94.36033,7.47000,      -0.78578,3.25757,1
 94.46228,7.48000,      -0.78551,3.25748,1
 94.56425,7.49000,      -0.78532,3.25738,1
 94.66616,7.50000,      -0.78505,3.25729,1
 94.76811,7.51000,      -0.78473,3.25719,1
 94.86998,7.52000,      -0.78462,3.25710,1
 94.97182,7.53000,      -0.78419,3.25700,1
 95.07366,7.54000,      -0.78368,3.25690,1
 95.17549,7.55000,      -0.78354,3.25681,1
 95.27736,7.56000,      -0.78341,3.25671,1
 95.37921,7.57000,      -0.78295,3.25662,1
 95.48100,7.58000,      -0.78246,3.25652,1
 95.58275,7.59000,      -0.78222,3.25642,1
 95.68457,7.60000,      -0.78192,3.25633,1
 95.78636,7.61000,      -0.78144,3.25623,1
 95.88810,7.62000,      -0.78120,3.25613,1
 95.98984,7.63000,      -0.78103,3.25604,1
 96.09156,7.64000,      -0.78071,3.25594,1
 96.19323,7.65000,      -0.78020,3.25584,1
 96.29489,7.66000,      -0.77996,3.25575,1
 96.39654,7.67000,      -0.77953,3.25565,1
 96.49816,7.68000,      -0.77899,3.25555,1
 96.59980,7.69000,      -0.77853,3.25546,1
 96.70141,7.70000,      -0.77848,3.25536,1
 96.80300,7.71000,      -0.77807,3.25526,1
 96.90454,7.72000,      -0.77756,3.25517,1
 97.00608,7.73000,      -0.77700,3.25507,1
 97.10759,7.74000,      -0.77638,3.25497,1
 97.20913,7.75000,      -0.77597,3.25487,1
 97.31061,7.76000,      -0.77549,3.25477,1
 97.41211,7.77000,      -0.77498,3.25468,1
 97.51361,7.78000,      -0.77439,3.25458,1
 97.61511,7.79000,      -0.77393,3.25448,1
 97.71652,7.80000,      -0.77342,3.25438,1
 97.81793,7.81000,      -0.77304,3.25428,1
 97.91934,7.82000,      -0.77242,3.25419,1
 98.02072,7.83000,      -0.77189,3.25409,1
 98.12213,7.84000,      -0.77130,3.25399,1
 98.22351,7.85000,      -0.77097,3.25389,1
 98.32490,7.86000,      -0.77078,3.25379,1
 98.42628,7.87000,      -0.77014,3.25369,1
 98.52774,7.88000,      -0.76968,3.25359,1
 98.62910,7.89000,      -0.76912,3.25350,1
 98.73048,7.90000,      -0.76863,3.25340,1
 98.83187,7.91000,      -0.76844,3.25330,1
 98.93330,7.92000,      -0.76796,3.25320,1
 99.03474,7.93000,      -0.76761,3.25310,1
 99.13611,7.94000,      -0.76747,3.25300,1
 99.23756,7.95000,      -0.76712,3.25290,1
 99.33900,7.96000,      -0.76648,3.25280,1
 99.44039,7.97000,      -0.76629,3.25270,1
 99.54182,7.98000,      -0.76610,3.25260,1
 99.64325,7.99000,      -0.76572,3.25250,1
 99.74467,8.00000,      -0.76526,3.25240,1
 99.84616,8.01000,      -0.76489,3.25230,1
 99.94761,8.02000,      -0.76459,3.25220,1
100.04907,8.03000,      -0.76424,3.25210,1
100.15049,8.04000,      -0.76386,3.25200,1
100.25192,8.05000,      -0.76340,3.25190,1
100.35334,8.06000,      -0.76303,3.25180,1
100.45479,8.07000,      -0.76238,3.25170,1
100.55620,8.08000,      -0.76182,3.25159,1
100.65761,8.09000,      -0.76123,3.25149,1
100.75903,8.10000,      -0.76037,3.25139,1
100.86048,8.11000,      -0.76004,3.25129,1
100.96185,8.12000,      -0.75921,3.25119,1
101.06333,8.13000,      -0.75849,3.25109,1
101.16480,8.14000,      -0.75773,3.25099,1
101.26626,8.15000,      -0.75674,3.25088,1
101.36767,8.16000,      -0.75577,3.25078,1
101.46911,8.17000,      -0.75507,3.25068,1
101.57054,8.18000,      -0.75472,3.25058,1
101.67197,8.19000,      -0.75381,3.25048,1
101.77338,8.20000,      -0.75279,3.25037,1
101.87479,8.21000,      -0.75196,3.25027,1
101.97615,8.22000,      -0.75118,3.25017,1
102.07762,8.23000,      -0.75045,3.25007,1
102.17902,8.24000,      -0.74970,3.24996,1
102.28052,8.25000,      -0.74889,3.24986,1
102.38192,8.26000,      -0.74817,3.24976,1
102.48338,8.27000,      -0.74747,3.24965,1
102.58479,8.28000,      -0.74685,3.24955,1
102.68626,8.29000,      -0.74615,3.24945,1
102.78769,8.30000,      -0.74537,3.24934,1
102.88900,8.31000,      -0.74462,3.24924,1
102.99038,8.32000,      -0.74384,3.24914,1
103.09169,8.33000,      -0.74314,3.24903,1
103.19298,8.34000,      -0.74244,3.24893,1
103.29425,8.35000,      -0.74161,3.24883,1
103.39557,8.36000,      -0.74080,3.24872,1
103.49687,8.37000,      -0.74000,3.24862,1
103.59810,8.38000,      -0.73930,3.24851,1
103.69939,8.39000,      -0.73871,3.24841,1
103.80066,8.40000,      -0.73798,3.24831,1
103.90195,8.41000,      -0.73731,3.24820,1
104.00318,8.42000,      -0.73639,3.24810,1
104.10438,8.43000,      -0.73553,3.24799,1
104.20559,8.44000,      -0.73481,3.24789,1
104.30679,8.45000,      -0.73413,3.24778,1
104.40793,8.46000,      -0.73343,3.24768,1
104.50911,8.47000,      -0.73260,3.24757,1
104.61034,8.48000,      -0.73163,3.24747,1
104.71151,8.49000,      -0.73123,3.24736,1
104.81270,8.50000,      -0.73048,3.24726,1
104.91392,8.51000,      -0.72959,3.24715,1
105.01511,8.52000,      -0.72859,3.24705,1
105.11636,8.53000,      -0.72781,3.24694,1
105.21762,8.54000,      -0.72706,3.24684,1
105.31880,8.55000,      -0.72647,3.24673,1
105.41995,8.56000,      -0.72555,3.24663,1
105.52118,8.57000,      -0.72469,3.24652,1
105.62241,8.58000,      -0.72389,3.24641,1
105.72359,8.59000,      -0.72311,3.24631,1
105.82479,8.60000,      -0.72224,3.24620,1
105.92592,8.61000,      -0.72152,3.24609,1
106.02710,8.62000,      -0.72076,3.24599,1
106.12833,8.63000,      -0.72001,3.24588,1
106.22952,8.64000,      -0.71923,3.24577,1
106.33072,8.65000,      -0.71842,3.24567,1
106.43193,8.66000,      -0.71759,3.24556,1
106.53313,8.67000,      -0.71673,3.24545,1
106.63429,8.68000,      -0.71603,3.24535,1
106.73546,8.69000,      -0.71519,3.24524,1
106.83666,8.70000,      -0.71433,3.24513,1
106.93782,8.71000,      -0.71353,3.24503,1
107.03892,8.72000,      -0.71269,3.24492,1
107.14007,8.73000,      -0.71183,3.24481,1
107.24120,8.74000,      -0.71100,3.24470,1
107.34233,8.75000,      -0.71013,3.24460,1
107.44344,8.76000,      -0.70935,3.24449,1
107.54459,8.77000,      -0.70852,3.24438,1
107.64569,8.78000,      -0.70758,3.24427,1
107.74682,8.79000,      -0.70674,3.24416,1
107.84797,8.80000,      -0.70599,3.24405,1
107.94913,8.81000,      -0.70529,3.24395,1
108.05025,8.82000,      -0.70451,3.24384,1
108.15130,8.83000,      -0.70367,3.24373,1
108.25236,8.84000,      -0.70268,3.24362,1
108.35346,8.85000,      -0.70195,3.24351,1
108.45452,8.86000,      -0.70109,3.24340,1
108.55564,8.87000,      -0.70006,3.24329,1
108.65674,8.88000,      -0.69920,3.24319,1
108.75780,8.89000,      -0.69831,3.24308,1
108.85882,8.90000,      -0.69737,3.24297,1
108.95984,8.91000,      -0.69638,3.24286,1
109.06089,8.92000,      -0.69546,3.24275,1
109.16187,8.93000,      -0.69481,3.24264,1
109.26279,8.94000,      -0.69379,3.24253,1
109.36370,8.95000,      -0.69298,3.24242,1
109.46464,8.96000,      -0.69217,3.24231,1
109.56559,8.97000,      -0.69134,3.24220,1
109.66648,8.98000,      -0.69045,3.24209,1
109.76733,8.99000,      -0.68937,3.24198,1
109.86816,9.00000,      -0.68837,3.24187,1
109.96893,9.01000,      -0.68746,3.24176,1
110.06972,9.02000,      -0.68668,3.24165,1
110.17056,9.03000,      -0.68576,3.24154,1
110.27138,9.04000,      -0.68487,3.24143,1
110.37223,9.05000,      -0.68393,3.24132,1
110.47297,9.06000,      -0.68290,3.24121,1
110.57371,9.07000,      -0.68180,3.24110,1
110.67444,9.08000,      -0.68131,3.24099,1
110.77511,9.09000,      -0.68007,3.24088,1
110.87579,9.10000,      -0.67908,3.24077,1
110.97646,9.11000,      -0.67811,3.24065,1
111.07715,9.12000,      -0.67719,3.24054,1
111.17779,9.13000,      -0.67630,3.24043,1
111.27848,9.14000,      -0.67533,3.24032,1
111.37913,9.15000,      -0.67441,3.24021,1
111.47979,9.16000,      -0.67342,3.24010,1
111.58048,9.17000,      -0.67239,3.23999,1
111.68113,9.18000,      -0.67134,3.23987,1
111.78175,9.19000,      -0.67042,3.23976,1
111.88243,9.20000,      -0.66977,3.23965,1
111.98307,9.21000,      -0.66854,3.23954,1
112.08379,9.22000,      -0.66762,3.23943,1
112.18443,9.23000,      -0.66654,3.23931,1
112.28507,9.24000,      -0.66568,3.23920,1
112.38566,9.25000,      -0.66476,3.23909,1
112.48631,9.26000,      -0.66387,3.23898,1
112.58695,9.27000,      -0.66284,3.23887,1
112.68757,9.28000,      -0.66185,3.23875,1
112.78818,9.29000,      -0.66079,3.23864,1
112.88884,9.30000,      -0.65985,3.23853,1
112.98948,9.31000,      -0.65888,3.23841,1
113.09007,9.32000,      -0.65796,3.23830,1
113.19074,9.33000,      -0.65707,3.23819,1
113.29138,9.34000,      -0.65618,3.23807,1
113.39203,9.35000,      -0.65526,3.23796,1
113.49270,9.36000,      -0.65437,3.23785,1
113.59329,9.37000,      -0.65324,3.23773,1
113.69389,9.38000,      -0.65219,3.23762,1
113.79449,9.39000,      -0.65119,3.23751,1
113.89507,9.40000,      -0.65027,3.23739,1
113.99569,9.41000,      -0.64938,3.23728,1
114.09628,9.42000,      -0.64835,3.23716,1
114.19682,9.43000,      -0.64738,3.23705,1
114.29736,9.44000,      -0.64635,3.23694,1
114.39793,9.45000,      -0.64538,3.23682,1
114.49846,9.46000,      -0.64446,3.23671,1
114.59900,9.47000,      -0.64352,3.23659,1
114.69952,9.48000,      -0.64249,3.23648,1
114.80003,9.49000,      -0.64133,3.23636,1
114.90054,9.50000,      -0.64090,3.23625,1
115.00107,9.51000,      -0.63963,3.23613,1
115.10156,9.52000,      -0.63855,3.23602,1
115.20205,9.53000,      -0.63747,3.23590,1
115.30248,9.54000,      -0.63644,3.23579,1
115.40293,9.55000,      -0.63544,3.23567,1
115.50339,9.56000,      -0.63450,3.23556,1
115.60389,9.57000,      -0.63353,3.23544,1
115.70439,9.58000,      -0.63247,3.23533,1
115.80489,9.59000,      -0.63147,3.23521,1
115.90536,9.60000,      -0.63039,3.23510,1
116.00579,9.61000,      -0.62929,3.23498,1
116.10623,9.62000,      -0.62829,3.23486,1
116.20664,9.63000,      -0.62742,3.23475,1
116.30710,9.64000,      -0.62650,3.23463,1
116.40752,9.65000,      -0.62588,3.23452,1
116.50793,9.66000,      -0.62472,3.23440,1
116.60833,9.67000,      -0.62369,3.23428,1
116.70864,9.68000,      -0.62266,3.23417,1
116.80903,9.69000,      -0.62166,3.23405,1
116.90941,9.70000,      -0.62074,3.23393,1
117.00980,9.71000,      -0.61966,3.23382,1
117.11025,9.72000,      -0.61858,3.23370,1
117.21066,9.73000,      -0.61755,3.23358,1
117.31111,9.74000,      -0.61650,3.23347,1
117.41154,9.75000,      -0.61550,3.23335,1
117.51198,9.76000,      -0.61444,3.23323,1
117.61239,9.77000,      -0.61350,3.23311,1
117.71279,9.78000,      -0.61252,3.23300,1
117.81320,9.79000,      -0.61155,3.23288,1
117.91359,9.80000,      -0.61049,3.23276,1
118.01393,9.81000,      -0.60952,3.23264,1
118.11433,9.82000,      -0.60849,3.23253,1
118.21475,9.83000,      -0.60744,3.23241,1
118.31516,9.84000,      -0.60649,3.23229,1
118.41556,9.85000,      -0.60554,3.23217,1
118.51593,9.86000,      -0.60444,3.23205,1
118.61639,9.87000,      -0.60357,3.23194,1
118.71685,9.88000,      -0.60251,3.23182,1
118.81733,9.89000,      -0.60146,3.23170,1
118.91725,9.90000,      -0.60054,3.23158,1
119.01765,9.91000,      -0.59954,3.23146,1
119.11794,9.92000,      -0.59848,3.23134,1
119.21826,9.93000,      -0.59737,3.23122,1
119.31846,9.94000,      -0.59632,3.23110,1
119.41864,9.95000,      -0.59534,3.23099,1
119.51892,9.96000,      -0.59439,3.23087,1
119.61895,9.97000,      -0.59345,3.23075,1
119.71862,9.98000,      -0.59250,3.23063,1
119.81714,9.99000,      -0.59147,3.23051,1
119.88900,9.99917,      -0.59080,3.23043,1