File: DSC图/ExpAll_常规3.csv
#EXPORTTYPE:                 ,ALL
#FILE:                       ,常规3.ngb-sd7
#FORMAT:                     ,NETZSCH5
#FTYPE:                      ,ANSI
#IDENTITY:                   ,3
#DECIMAL:                    ,POINT
#SEPARATOR:                  ,COMMA
#MTYPE:                      ,DSC
#INSTRUMENT:                 ,NETZSCH DSC 204F1 Phoenix
#PROJECT:                    ,1
#DATE/TIME:                  ,2023/4/24 15:41:47 (UTC+8)
#CORR. FILE:                 ,
#TEMPCAL:                    ,applied
#SENSITIVITY:                ,applied
#LABORATORY:                 ,
#OPERATOR:                   ,0
#REMARK:                     ,
#SAMPLE:                     ,常规
#SAMPLE MASS /mg:            ,7.97
#MATERIAL:                   ,
#REFERENCE:                  ,
#REFERENCE MASS /mg:         ,0
#TYPE OF CRUCIBLE:           ,Concavus Pan Al, open
#SAMPLE CRUCIBLE MASS /mg:   ,0
#REFERENCE CRUCIBLE MASS /mg:,0
#M.RANGE /μV:                ,5000
#TAU-R:                      ,---
#CORR. CODE:                 ,000
#EXO:                        ,+1
#RANGE:                      ,20°C/10.0(K/min)/120°C
#SEGMENT:                    ,S1/1
#SEG. 1:                     ,20°C/10.0(K/min)/120°C

#*RESULTS:     ,File,Segment,Result,Unit,Y_value,Unit ,Range_Xmin,Unit,Range_Xmax,Unit,Range_Ymin,Unit ,Range_Ymax,Unit
#*Area (DSC)(o),常规3 ,1      ,-65.23,J/g ,-      ,-    ,44.2      ,°C  ,120.0     ,°C  ,-0.2975   ,mW/mg,-0.4353   ,mW/mg
#*Onset (DSC)  ,常规3 ,1      ,44.2  ,°C  ,-0.2894,mW/mg,35.9      ,°C  ,84.1      ,°C  ,-0.244    ,mW/mg,-0.6113   ,mW/mg
#*Peak (DSC)   ,常规3 ,1      ,85.3  ,°C  ,-0.6121,mW/mg,35.9      ,°C  ,104.0     ,°C  ,-0.244    ,mW/mg,-0.5501   ,mW/mg
#*End (DSC)    ,常规3 ,1      ,120.2 ,°C  ,-0.4346,mW/mg,86.3      ,°C  ,119.9     ,°C  ,-0.6119   ,mW/mg,-0.436    ,mW/mg

##Temp./°C,Time/min,DSC/(mW/mg),Sensit./(uV/mW),Segment
 19.86100,0.00000,-5.370284e-002,3.29775,1
 19.86200,0.01000,-5.373217e-002,3.29775,1
 19.86300,0.02000,-5.384858e-002,3.29775,1
 19.86653,0.03000,-5.381986e-002,3.29775,1
 19.87844,0.04000,-5.350117e-002,3.29775,1
 19.90100,0.05000,-5.315437e-002,3.29775,1
 19.93524,0.06000,-5.283930e-002,3.29774,1
 19.98074,0.07000,-5.267265e-002,3.29774,1
 20.03631,0.08000,-5.346603e-002,3.29773,1
 20.10042,0.09000,-5.510421e-002,3.29772,1
 20.17166,0.10000,-5.703655e-002,3.29771,1
 20.22666,0.11000,-5.998664e-002,3.29770,1
 20.28680,0.12000,-6.299719e-002,3.29769,1
 20.35205,0.13000,-6.691061e-002,3.29769,1
 20.42251,0.14000,-7.085400e-002,3.29768,1
 20.49807,0.15000,-7.529298e-002,3.29766,1
 20.57852,0.16000,-8.022669e-002,3.29765,1
 20.66338,0.17000,-8.489980e-002,3.29764,1
 20.75210,0.18000,-9.015501e-002,3.29763,1
 20.84443,0.19000,-9.535222e-002,3.29761,1
 20.93974,0.20000,      -0.10046,3.29760,1
 21.03756,0.21000,      -0.10555,3.29758,1
 21.13751,0.22000,      -0.11080,3.29757,1
 21.23923,0.23000,      -0.11600,3.29755,1
 21.34223,0.24000,      -0.12097,3.29754,1
 21.44636,0.25000,      -0.12570,3.29752,1
 21.55133,0.26000,      -0.13058,3.29751,1
 21.65692,0.27000,      -0.13538,3.29749,1
 21.76307,0.28000,      -0.13942,3.29747,1
 21.86954,0.29000,      -0.14363,3.29746,1
 21.97631,0.30000,      -0.14781,3.29744,1
 22.08321,0.31000,      -0.15145,3.29742,1
 22.19020,0.32000,      -0.15499,3.29740,1
 22.29723,0.33000,      -0.15836,3.29739,1
 22.40430,0.34000,      -0.16153,3.29737,1
 22.51141,0.35000,      -0.16461,3.29735,1
 22.61844,0.36000,      -0.16732,3.29733,1
 22.72546,0.37000,      -0.16993,3.29731,1
 22.83248,0.38000,      -0.17194,3.29730,1
 22.93944,0.39000,      -0.17421,3.29728,1
 23.04638,0.40000,      -0.17642,3.29726,1
 23.15328,0.41000,      -0.17834,3.29724,1
 23.26015,0.42000,      -0.18011,3.29722,1
 23.36693,0.43000,      -0.18177,3.29720,1
 23.47379,0.44000,      -0.18343,3.29718,1
 23.58062,0.45000,      -0.18503,3.29717,1
 23.68741,0.46000,      -0.18643,3.29715,1
 23.79415,0.47000,      -0.18748,3.29713,1
 23.90089,0.48000,      -0.18861,3.29711,1
 24.00757,0.49000,      -0.18986,3.29709,1
 24.11430,0.50000,      -0.19083,3.29707,1
 24.22095,0.51000,      -0.19185,3.29705,1
 24.32761,0.52000,      -0.19284,3.29703,1
 24.43436,0.53000,      -0.19374,3.29701,1
 24.54111,0.54000,      -0.19435,3.29699,1
 24.64784,0.55000,      -0.19529,3.29697,1
 24.75452,0.56000,      -0.19613,3.29695,1
 24.86125,0.57000,      -0.19695,3.29693,1
 24.96789,0.58000,      -0.19748,3.29691,1
 25.07466,0.59000,      -0.19826,3.29689,1
 25.18136,0.60000,      -0.19905,3.29687,1
 25.28800,0.61000,      -0.19949,3.29684,1
 25.39462,0.62000,      -0.20002,3.29682,1
 25.50125,0.63000,      -0.20072,3.29680,1
 25.60784,0.64000,      -0.20110,3.29678,1
 25.71431,0.65000,      -0.20168,3.29676,1
 25.82085,0.66000,      -0.20210,3.29674,1
 25.92736,0.67000,      -0.20265,3.29672,1
 26.03382,0.68000,      -0.20306,3.29669,1
 26.14028,0.69000,      -0.20350,3.29667,1
 26.24670,0.70000,      -0.20400,3.29665,1
 26.35307,0.71000,      -0.20450,3.29663,1
 26.45949,0.72000,      -0.20488,3.29661,1
 26.56582,0.73000,      -0.20537,3.29658,1
 26.67205,0.74000,      -0.20584,3.29656,1
 26.77825,0.75000,      -0.20620,3.29654,1
 26.88444,0.76000,      -0.20661,3.29652,1
 26.99057,0.77000,      -0.20713,3.29649,1
 27.09675,0.78000,      -0.20754,3.29647,1
 27.20277,0.79000,      -0.20784,3.29645,1
 27.30877,0.80000,      -0.20804,3.29642,1
 27.41475,0.81000,      -0.20860,3.29640,1
 27.52069,0.82000,      -0.20916,3.29638,1
 27.62656,0.83000,      -0.20968,3.29635,1
 27.73238,0.84000,      -0.21018,3.29633,1
 27.83818,0.85000,      -0.21059,3.29631,1
 27.94385,0.86000,      -0.21086,3.29628,1
 28.04948,0.87000,      -0.21124,3.29626,1
 28.15515,0.88000,      -0.21168,3.29623,1
 28.26072,0.89000,      -0.21212,3.29621,1
 28.36621,0.90000,      -0.21259,3.29619,1
 28.47172,0.91000,      -0.21302,3.29616,1
 28.57710,0.92000,      -0.21346,3.29614,1
 28.68246,0.93000,      -0.21387,3.29611,1
 28.78779,0.94000,      -0.21440,3.29609,1
 28.89308,0.95000,      -0.21461,3.29606,1
 28.99831,0.96000,      -0.21496,3.29604,1
 29.10348,0.97000,      -0.21549,3.29601,1
 29.20856,0.98000,      -0.21581,3.29599,1
 29.31359,0.99000,      -0.21619,3.29596,1
 29.41857,1.00000,      -0.21663,3.29594,1
 29.52352,1.01000,      -0.21710,3.29591,1
 29.62846,1.02000,      -0.21760,3.29589,1
 29.73348,1.03000,      -0.21815,3.29586,1
 29.83833,1.04000,      -0.21836,3.29583,1
 29.94315,1.05000,      -0.21851,3.29581,1
 30.04798,1.06000,      -0.21912,3.29578,1
 30.15274,1.07000,      -0.21968,3.29576,1
 30.25748,1.08000,      -0.22003,3.29573,1
 30.36210,1.09000,      -0.22027,3.29570,1
 30.46669,1.10000,      -0.22079,3.29568,1
 30.57123,1.11000,      -0.22115,3.29565,1
 30.67574,1.12000,      -0.22156,3.29562,1
 30.78018,1.13000,      -0.22188,3.29560,1
 30.88459,1.14000,      -0.22229,3.29557,1
 30.98902,1.15000,      -0.22273,3.29554,1
 31.09339,1.16000,      -0.22317,3.29552,1
 31.19772,1.17000,      -0.22372,3.29549,1
 31.30203,1.18000,      -0.22411,3.29546,1
 31.40626,1.19000,      -0.22443,3.29543,1
 31.51054,1.20000,      -0.22493,3.29541,1
 31.61469,1.21000,      -0.22519,3.29538,1
 31.71882,1.22000,      -0.22572,3.29535,1
 31.82284,1.23000,      -0.22616,3.29532,1
 31.92688,1.24000,      -0.22666,3.29529,1
 32.03087,1.25000,      -0.22701,3.29527,1
 32.13484,1.26000,      -0.22745,3.29524,1
 32.23872,1.27000,      -0.22786,3.29521,1
 32.34257,1.28000,      -0.22821,3.29518,1
 32.44643,1.29000,      -0.22845,3.29515,1
 32.55018,1.30000,      -0.22894,3.29512,1
 32.65398,1.31000,      -0.22938,3.29510,1
 32.75769,1.32000,      -0.22977,3.29507,1
 32.86139,1.33000,      -0.23003,3.29504,1
 32.96500,1.34000,      -0.23067,3.29501,1
 33.06854,1.35000,      -0.23103,3.29498,1
 33.17205,1.36000,      -0.23138,3.29495,1
 33.27556,1.37000,      -0.23193,3.29492,1
 33.37898,1.38000,      -0.23237,3.29489,1
 33.48236,1.39000,      -0.23302,3.29486,1
 33.58577,1.40000,      -0.23357,3.29483,1
 33.68913,1.41000,      -0.23407,3.29480,1
 33.79244,1.42000,      -0.23425,3.29477,1
 33.89567,1.43000,      -0.23460,3.29474,1
 33.99887,1.44000,      -0.23507,3.29471,1
 34.10210,1.45000,      -0.23554,3.29468,1
 34.20520,1.46000,      -0.23601,3.29465,1
 34.30831,1.47000,      -0.23645,3.29462,1
 34.41146,1.48000,      -0.23671,3.29459,1
 34.51451,1.49000,      -0.23744,3.29456,1
 34.61759,1.50000,      -0.23779,3.29453,1
 34.72054,1.51000,      -0.23817,3.29450,1
 34.82348,1.52000,      -0.23876,3.29447,1
 34.92646,1.53000,      -0.23926,3.29444,1
 35.02943,1.54000,      -0.23984,3.29441,1
 35.13231,1.55000,      -0.24028,3.29437,1
 35.23515,1.56000,      -0.24078,3.29434,1
 35.33797,1.57000,      -0.24134,3.29431,1
 35.44072,1.58000,      -0.24172,3.29428,1
 35.54351,1.59000,      -0.24213,3.29425,1
 35.64623,1.60000,      -0.24268,3.29422,1
 35.74889,1.61000,      -0.24327,3.29418,1
 35.85151,1.62000,      -0.24380,3.29415,1
 35.95416,1.63000,      -0.24429,3.29412,1
 36.05677,1.64000,      -0.24476,3.29409,1
 36.15938,1.65000,      -0.24529,3.29406,1
 36.26197,1.66000,      -0.24585,3.29402,1
 36.36449,1.67000,      -0.24637,3.29399,1
 36.46695,1.68000,      -0.24696,3.29396,1
 36.56941,1.69000,      -0.24760,3.29393,1
 36.67185,1.70000,      -0.24816,3.29389,1
 36.77433,1.71000,      -0.24871,3.29386,1
 36.87677,1.72000,      -0.24930,3.29383,1
 36.97911,1.73000,      -0.24985,3.29379,1
 37.08136,1.74000,      -0.25041,3.29376,1
 37.18367,1.75000,      -0.25091,3.29373,1
 37.28600,1.76000,      -0.25117,3.29369,1
 37.38823,1.77000,      -0.25167,3.29366,1
 37.49052,1.78000,      -0.25240,3.29363,1
 37.59269,1.79000,      -0.25328,3.29359,1
 37.69480,1.80000,      -0.25369,3.29356,1
 37.79695,1.81000,      -0.25401,3.29352,1
 37.89908,1.82000,      -0.25460,3.29349,1
 38.00116,1.83000,      -0.25536,3.29346,1
 38.10323,1.84000,      -0.25609,3.29342,1
 38.20520,1.85000,      -0.25670,3.29339,1
 38.30716,1.86000,      -0.25726,3.29335,1
 38.40915,1.87000,      -0.25784,3.29332,1
 38.51116,1.88000,      -0.25817,3.29328,1
 38.61305,1.89000,      -0.25866,3.29325,1
 38.71495,1.90000,      -0.25922,3.29321,1
 38.81680,1.91000,      -0.25989,3.29318,1
 38.91864,1.92000,      -0.26060,3.29314,1
 39.02044,1.93000,      -0.26124,3.29311,1
 39.12230,1.94000,      -0.26185,3.29307,1
 39.22420,1.95000,      -0.26238,3.29304,1
 39.32598,1.96000,      -0.26282,3.29300,1
 39.42777,1.97000,      -0.26338,3.29297,1
 39.52957,1.98000,      -0.26402,3.29293,1
 39.63141,1.99000,      -0.26484,3.29289,1
 39.73326,2.00000,      -0.26563,3.29286,1
 39.83510,2.01000,      -0.26624,3.29282,1
 39.93692,2.02000,      -0.26686,3.29279,1
 40.03872,2.03000,      -0.26753,3.29275,1
 40.14056,2.04000,      -0.26811,3.29271,1
 40.24239,2.05000,      -0.26876,3.29268,1
 40.34426,2.06000,      -0.26946,3.29264,1
 40.44608,2.07000,      -0.27028,3.29260,1
 40.54782,2.08000,      -0.27098,3.29257,1
 40.64969,2.09000,      -0.27165,3.29253,1
 40.75159,2.10000,      -0.27239,3.29249,1
 40.85341,2.11000,      -0.27309,3.29245,1
 40.95529,2.12000,      -0.27376,3.29242,1
 41.05718,2.13000,      -0.27432,3.29238,1
 41.15903,2.14000,      -0.27505,3.29234,1
 41.26089,2.15000,      -0.27581,3.29230,1
 41.36272,2.16000,      -0.27663,3.29227,1
 41.46454,2.17000,      -0.27736,3.29223,1
 41.56638,2.18000,      -0.27806,3.29219,1
 41.66820,2.19000,      -0.27876,3.29215,1
 41.76997,2.20000,      -0.27941,3.29211,1
 41.87175,2.21000,      -0.28025,3.29208,1
 41.97351,2.22000,      -0.28101,3.29204,1
 42.07521,2.23000,      -0.28181,3.29200,1
 42.17695,2.24000,      -0.28259,3.29196,1
 42.27867,2.25000,      -0.28333,3.29192,1
 42.38036,2.26000,      -0.28406,3.29188,1
 42.48205,2.27000,      -0.28470,3.29184,1
 42.58370,2.28000,      -0.28543,3.29180,1
 42.68531,2.29000,      -0.28637,3.29177,1
 42.78682,2.30000,      -0.28724,3.29173,1
 42.88833,2.31000,      -0.28757,3.29169,1
 42.98984,2.32000,      -0.28821,3.29165,1
 43.09130,2.33000,      -0.28897,3.29161,1
 43.19269,2.34000,      -0.28988,3.29157,1
 43.29403,2.35000,      -0.29087,3.29153,1
 43.39534,2.36000,      -0.29149,3.29149,1
 43.49672,2.37000,      -0.29211,3.29145,1
 43.59803,2.38000,      -0.29292,3.29141,1
 43.69931,2.39000,      -0.29374,3.29137,1
 43.80059,2.40000,      -0.29453,3.29133,1
 43.90182,2.41000,      -0.29532,3.29129,1
 44.00303,2.42000,      -0.29597,3.29125,1
 44.10426,2.43000,      -0.29676,3.29121,1
 44.20546,2.44000,      -0.29758,3.29117,1
 44.30657,2.45000,      -0.29837,3.29113,1
 44.40767,2.46000,      -0.29916,3.29108,1
 44.50880,2.47000,      -0.29992,3.29104,1
 44.60987,2.48000,      -0.30059,3.29100,1
 44.71098,2.49000,      -0.30132,3.29096,1
 44.81210,2.50000,      -0.30211,3.29092,1
 44.91323,2.51000,      -0.30287,3.29088,1
 45.01429,2.52000,      -0.30355,3.29084,1
 45.11536,2.53000,      -0.30431,3.29080,1
 45.21649,2.54000,      -0.30516,3.29075,1
 45.31761,2.55000,      -0.30609,3.29071,1
 45.41874,2.56000,      -0.30680,3.29067,1
 45.51985,2.57000,      -0.30762,3.29063,1
 45.62098,2.58000,      -0.30832,3.29059,1
 45.72207,2.59000,      -0.30908,3.29054,1
 45.82318,2.60000,      -0.31010,3.29050,1
 45.92431,2.61000,      -0.31086,3.29046,1
 46.02544,2.62000,      -0.31160,3.29042,1
 46.12657,2.63000,      -0.31230,3.29037,1
 46.22769,2.64000,      -0.31306,3.29033,1
 46.32885,2.65000,      -0.31406,3.29029,1
 46.43003,2.66000,      -0.31508,3.29024,1
 46.53118,2.67000,      -0.31593,3.29020,1
 46.63239,2.68000,      -0.31640,3.29016,1
 46.73354,2.69000,      -0.31760,3.29011,1
 46.83461,2.70000,      -0.31856,3.29007,1
 46.93574,2.71000,      -0.31938,3.29003,1
 47.03684,2.72000,      -0.32009,3.28998,1
 47.13802,2.73000,      -0.32096,3.28994,1
 47.23915,2.74000,      -0.32193,3.28989,1
 47.34031,2.75000,      -0.32278,3.28985,1
 47.44146,2.76000,      -0.32366,3.28981,1
 47.54257,2.77000,      -0.32451,3.28976,1
 47.64369,2.78000,      -0.32530,3.28972,1
 47.74480,2.79000,      -0.32626,3.28967,1
 47.84585,2.80000,      -0.32714,3.28963,1
 47.94690,2.81000,      -0.32805,3.28958,1
 48.04792,2.82000,      -0.32884,3.28954,1
 48.14897,2.83000,      -0.32963,3.28949,1
 48.24992,2.84000,      -0.33051,3.28945,1
 48.35090,2.85000,      -0.33150,3.28940,1
 48.45184,2.86000,      -0.33265,3.28936,1
 48.55274,2.87000,      -0.33326,3.28931,1
 48.65362,2.88000,      -0.33411,3.28927,1
 48.75451,2.89000,      -0.33508,3.28922,1
 48.85551,2.90000,      -0.33625,3.28918,1
 48.95646,2.91000,      -0.33724,3.28913,1
 49.05738,2.92000,      -0.33757,3.28909,1
 49.15826,2.93000,      -0.33856,3.28904,1
 49.25910,2.94000,      -0.33944,3.28899,1
 49.35990,2.95000,      -0.34038,3.28895,1
 49.46066,2.96000,      -0.34155,3.28890,1
 49.56143,2.97000,      -0.34228,3.28885,1
 49.66213,2.98000,      -0.34319,3.28881,1
 49.76287,2.99000,      -0.34413,3.28876,1
 49.86356,3.00000,      -0.34506,3.28872,1
 49.96420,3.01000,      -0.34591,3.28867,1
 50.06484,3.02000,      -0.34673,3.28862,1
 50.16546,3.03000,      -0.34759,3.28857,1
 50.26618,3.04000,      -0.34861,3.28853,1
 50.36684,3.05000,      -0.34949,3.28848,1
 50.46751,3.06000,      -0.35037,3.28843,1
 50.56818,3.07000,      -0.35122,3.28839,1
 50.66892,3.08000,      -0.35213,3.28834,1
 50.76966,3.09000,      -0.35295,3.28829,1
 50.87031,3.10000,      -0.35388,3.28824,1
 50.97090,3.11000,      -0.35473,3.28820,1
 51.07148,3.12000,      -0.35561,3.28815,1
 51.17205,3.13000,      -0.35661,3.28810,1
 51.27262,3.14000,      -0.35763,3.28805,1
 51.37321,3.15000,      -0.35866,3.28800,1
 51.47387,3.16000,      -0.35960,3.28795,1
 51.57444,3.17000,      -0.36051,3.28791,1
 51.67503,3.18000,      -0.36127,3.28786,1
 51.77570,3.19000,      -0.36224,3.28781,1
 51.87634,3.20000,      -0.36317,3.28776,1
 51.97703,3.21000,      -0.36423,3.28771,1
 52.07769,3.22000,      -0.36520,3.28766,1
 52.17830,3.23000,      -0.36610,3.28761,1
 52.27890,3.24000,      -0.36719,3.28756,1
 52.37951,3.25000,      -0.36816,3.28751,1
 52.48013,3.26000,      -0.36904,3.28747,1
 52.58070,3.27000,      -0.36989,3.28742,1
 52.68121,3.28000,      -0.37062,3.28737,1
 52.78166,3.29000,      -0.37162,3.28732,1
 52.88221,3.30000,      -0.37270,3.28727,1
 52.98277,3.31000,      -0.37405,3.28722,1
 53.08330,3.32000,      -0.37475,3.28717,1
 53.18389,3.33000,      -0.37534,3.28712,1
 53.28441,3.34000,      -0.37663,3.28707,1
 53.38500,3.35000,      -0.37766,3.28702,1
 53.48557,3.36000,      -0.37862,3.28697,1
 53.58616,3.37000,      -0.37953,3.28691,1
 53.68679,3.38000,      -0.38018,3.28686,1
 53.78734,3.39000,      -0.38112,3.28681,1
 53.88792,3.40000,      -0.38220,3.28676,1
 53.98849,3.41000,      -0.38332,3.28671,1
 54.08905,3.42000,      -0.38411,3.28666,1
 54.18970,3.43000,      -0.38499,3.28661,1
 54.29034,3.44000,      -0.38625,3.28656,1
 54.39095,3.45000,      -0.38751,3.28651,1
 54.49159,3.46000,      -0.38856,3.28645,1
 54.59220,3.47000,      -0.38895,3.28640,1
 54.69290,3.48000,      -0.38974,3.28635,1
 54.79362,3.49000,      -0.39121,3.28630,1
 54.89433,3.50000,      -0.39232,3.28625,1
 54.99505,3.51000,      -0.39341,3.28619,1
 55.09575,3.52000,      -0.39429,3.28614,1
 55.19651,3.53000,      -0.39520,3.28609,1
 55.29728,3.54000,      -0.39640,3.28604,1
 55.39802,3.55000,      -0.39745,3.28599,1
 55.49875,3.56000,      -0.39845,3.28593,1
 55.59954,3.57000,      -0.39945,3.28588,1
 55.70033,3.58000,      -0.40027,3.28583,1
 55.80113,3.59000,      -0.40113,3.28577,1
 55.90192,3.60000,      -0.40212,3.28572,1
 56.00269,3.61000,      -0.40335,3.28567,1
 56.10348,3.62000,      -0.40444,3.28561,1
 56.20429,3.63000,      -0.40561,3.28556,1
 56.30503,3.64000,      -0.40658,3.28551,1
 56.40580,3.65000,      -0.40755,3.28545,1
 56.50657,3.66000,      -0.40852,3.28540,1
 56.60734,3.67000,      -0.40955,3.28534,1
 56.70810,3.68000,      -0.41063,3.28529,1
 56.80879,3.69000,      -0.41163,3.28524,1
 56.90951,3.70000,      -0.41272,3.28518,1
 57.01023,3.71000,      -0.41377,3.28513,1
 57.11098,3.72000,      -0.41457,3.28507,1
 57.21169,3.73000,      -0.41563,3.28502,1
 57.31234,3.74000,      -0.41677,3.28496,1
 57.41305,3.75000,      -0.41786,3.28491,1
 57.51374,3.76000,      -0.41891,3.28485,1
 57.61438,3.77000,      -0.41945,3.28480,1
 57.71497,3.78000,      -0.42053,3.28474,1
 57.81554,3.79000,      -0.42179,3.28469,1
 57.91613,3.80000,      -0.42288,3.28463,1
 58.01672,3.81000,      -0.42382,3.28458,1
 58.11734,3.82000,      -0.42482,3.28452,1
 58.21784,3.83000,      -0.42576,3.28447,1
 58.31834,3.84000,      -0.42684,3.28441,1
 58.41893,3.85000,      -0.42790,3.28436,1
 58.51941,3.86000,      -0.42881,3.28430,1
 58.61990,3.87000,      -0.42967,3.28424,1
 58.72041,3.88000,      -0.43087,3.28419,1
 58.82089,3.89000,      -0.43181,3.28413,1
 58.92134,3.90000,      -0.43281,3.28408,1
 59.02179,3.91000,      -0.43384,3.28402,1
 59.12225,3.92000,      -0.43478,3.28396,1
 59.22274,3.93000,      -0.43575,3.28391,1
 59.32321,3.94000,      -0.43672,3.28385,1
 59.42367,3.95000,      -0.43775,3.28379,1
 59.52410,3.96000,      -0.43872,3.28374,1
 59.62459,3.97000,      -0.43975,3.28368,1
 59.72502,3.98000,      -0.44057,3.28362,1
 59.82549,3.99000,      -0.44137,3.28356,1
 59.92595,4.00000,      -0.44237,3.28351,1
 60.02641,4.01000,      -0.44351,3.28345,1
 60.12689,4.02000,      -0.44457,3.28339,1
 60.22739,4.03000,      -0.44560,3.28333,1
 60.32790,4.04000,      -0.44672,3.28328,1
 60.42843,4.05000,      -0.44781,3.28322,1
 60.52895,4.06000,      -0.44843,3.28316,1
 60.62946,4.07000,      -0.44954,3.28310,1
 60.73002,4.08000,      -0.45075,3.28304,1
 60.83056,4.09000,      -0.45160,3.28299,1
 60.93111,4.10000,      -0.45251,3.28293,1
 61.03162,4.11000,      -0.45346,3.28287,1
 61.13215,4.12000,      -0.45449,3.28281,1
 61.23262,4.13000,      -0.45566,3.28275,1
 61.33311,4.14000,      -0.45655,3.28269,1
 61.43359,4.15000,      -0.45757,3.28263,1
 61.53407,4.16000,      -0.45858,3.28257,1
 61.63449,4.17000,      -0.45995,3.28252,1
 61.73493,4.18000,      -0.46081,3.28246,1
 61.83536,4.19000,      -0.46158,3.28240,1
 61.93584,4.20000,      -0.46278,3.28234,1
 62.03625,4.21000,      -0.46361,3.28228,1
 62.13662,4.22000,      -0.46452,3.28222,1
 62.23703,4.23000,      -0.46558,3.28216,1
 62.33743,4.24000,      -0.46655,3.28210,1
 62.43779,4.25000,      -0.46779,3.28204,1
 62.53816,4.26000,      -0.46890,3.28198,1
 62.63856,4.27000,      -0.46947,3.28192,1
 62.73893,4.28000,      -0.47041,3.28186,1
 62.83931,4.29000,      -0.47138,3.28180,1
 62.93967,4.30000,      -0.47270,3.28174,1
 63.04003,4.31000,      -0.47368,3.28168,1
 63.14036,4.32000,      -0.47453,3.28162,1
 63.24069,4.33000,      -0.47521,3.28156,1
 63.34105,4.34000,      -0.47616,3.28149,1
 63.44138,4.35000,      -0.47745,3.28143,1
 63.54172,4.36000,      -0.47851,3.28137,1
 63.64208,4.37000,      -0.47939,3.28131,1
 63.74241,4.38000,      -0.48034,3.28125,1
 63.84275,4.39000,      -0.48157,3.28119,1
 63.94308,4.40000,      -0.48257,3.28113,1
 64.04343,4.41000,      -0.48320,3.28106,1
 64.14374,4.42000,      -0.48414,3.28100,1
 64.24402,4.43000,      -0.48502,3.28094,1
 64.34431,4.44000,      -0.48635,3.28088,1
 64.44462,4.45000,      -0.48744,3.28082,1
 64.54492,4.46000,      -0.48824,3.28075,1
 64.64521,4.47000,      -0.48921,3.28069,1
 64.74551,4.48000,      -0.48992,3.28063,1
 64.84580,4.49000,      -0.49083,3.28057,1
 64.94610,4.50000,      -0.49189,3.28050,1
 65.04641,4.51000,      -0.49293,3.28044,1
 65.14667,4.52000,      -0.49364,3.28038,1
 65.24702,4.53000,      -0.49470,3.28032,1
 65.34728,4.54000,      -0.49552,3.28025,1
 65.44757,4.55000,      -0.49653,3.28019,1
 65.54790,4.56000,      -0.49744,3.28013,1
 65.64821,4.57000,      -0.49841,3.28006,1
 65.74856,4.58000,      -0.49942,3.28000,1
 65.84887,4.59000,      -0.50019,3.27994,1
 65.94921,4.60000,      -0.50136,3.27987,1
 66.04952,4.61000,      -0.50251,3.27981,1
 66.14987,4.62000,      -0.50343,3.27975,1
 66.25023,4.63000,      -0.50432,3.27968,1
 66.35064,4.64000,      -0.50529,3.27962,1
 66.45107,4.65000,      -0.50620,3.27955,1
 66.55143,4.66000,      -0.50718,3.27949,1
 66.65184,4.67000,      -0.50804,3.27942,1
 66.75223,4.68000,      -0.50898,3.27936,1
 66.85267,4.69000,      -0.50984,3.27929,1
 66.95313,4.70000,      -0.51084,3.27923,1
 67.05354,4.71000,      -0.51182,3.27916,1
 67.15403,4.72000,      -0.51273,3.27910,1
 67.25459,4.73000,      -0.51362,3.27903,1
 67.35505,4.74000,      -0.51456,3.27897,1
 67.45554,4.75000,      -0.51557,3.27890,1
 67.55598,4.76000,      -0.51634,3.27884,1
 67.65651,4.77000,      -0.51711,3.27877,1
 67.75697,4.78000,      -0.51817,3.27871,1
 67.85746,4.79000,      -0.51917,3.27864,1
 67.95793,4.80000,      -0.52006,3.27858,1
 68.05846,4.81000,      -0.52121,3.27851,1
 68.15897,4.82000,      -0.52224,3.27844,1
 68.25954,4.83000,      -0.52310,3.27838,1
 68.36002,4.84000,      -0.52393,3.27831,1
 68.46056,4.85000,      -0.52473,3.27824,1
 68.56110,4.86000,      -0.52559,3.27818,1
 68.66169,4.87000,      -0.52662,3.27811,1
 68.76218,4.88000,      -0.52763,3.27804,1
 68.86267,4.89000,      -0.52860,3.27798,1
 68.96313,4.90000,      -0.52934,3.27791,1
 69.06359,4.91000,      -0.53023,3.27784,1
 69.16405,4.92000,      -0.53121,3.27778,1
 69.26448,4.93000,      -0.53212,3.27771,1
 69.36490,4.94000,      -0.53298,3.27764,1
 69.46536,4.95000,      -0.53378,3.27757,1
 69.56582,4.96000,      -0.53461,3.27751,1
 69.66625,4.97000,      -0.53553,3.27744,1
 69.76670,4.98000,      -0.53636,3.27737,1
 69.86713,4.99000,      -0.53672,3.27730,1
 69.96759,5.00000,      -0.53808,3.27723,1
 70.06800,5.01000,      -0.53894,3.27717,1
 70.16844,5.02000,      -0.53968,3.27710,1
 70.26875,5.03000,      -0.54066,3.27703,1
 70.36916,5.04000,      -0.54157,3.27696,1
 70.46952,5.05000,      -0.54234,3.27689,1
 70.56984,5.06000,      -0.54315,3.27682,1
 70.67011,5.07000,      -0.54398,3.27675,1
 70.77041,5.08000,      -0.54489,3.27669,1
 70.87072,5.09000,      -0.54581,3.27662,1
 70.97105,5.10000,      -0.54655,3.27655,1
 71.07139,5.11000,      -0.54738,3.27648,1
 71.17169,5.12000,      -0.54822,3.27641,1
 71.27197,5.13000,      -0.54896,3.27634,1
 71.37225,5.14000,      -0.54985,3.27627,1
 71.47256,5.15000,      -0.55027,3.27620,1
 71.57289,5.16000,      -0.55113,3.27613,1
 71.67315,5.17000,      -0.55205,3.27606,1
 71.77339,5.18000,      -0.55279,3.27599,1
 71.87357,5.19000,      -0.55359,3.27592,1
 71.97382,5.20000,      -0.55433,3.27585,1
 72.07408,5.21000,      -0.55505,3.27578,1
 72.17434,5.22000,      -0.55588,3.27571,1
 72.27457,5.23000,      -0.55627,3.27564,1
 72.37482,5.24000,      -0.55728,3.27557,1
 72.47507,5.25000,      -0.55811,3.27550,1
 72.57531,5.26000,      -0.55871,3.27543,1
 72.67556,5.27000,      -0.55948,3.27536,1
 72.77587,5.28000,      -0.56022,3.27529,1
 72.87620,5.29000,      -0.56094,3.27522,1
 72.97651,5.30000,      -0.56180,3.27515,1
 73.07680,5.31000,      -0.56257,3.27507,1
 73.17718,5.32000,      -0.56337,3.27500,1
 73.27757,5.33000,      -0.56412,3.27493,1
 73.37797,5.34000,      -0.56492,3.27486,1
 73.47846,5.35000,      -0.56566,3.27479,1
 73.57885,5.36000,      -0.56635,3.27472,1
 73.67926,5.37000,      -0.56709,3.27464,1
 73.77964,5.38000,      -0.56786,3.27457,1
 73.88016,5.39000,      -0.56820,3.27450,1
 73.98067,5.40000,      -0.56903,3.27443,1
 74.08113,5.41000,      -0.56986,3.27436,1
 74.18164,5.42000,      -0.57061,3.27428,1
 74.28216,5.43000,      -0.57135,3.27421,1
 74.38277,5.44000,      -0.57213,3.27414,1
 74.48339,5.45000,      -0.57278,3.27406,1
 74.58395,5.46000,      -0.57329,3.27399,1
 74.68457,5.47000,      -0.57404,3.27392,1
 74.78518,5.48000,      -0.57464,3.27384,1
 74.88580,5.49000,      -0.57532,3.27377,1
 74.98646,5.50000,      -0.57610,3.27370,1
 75.08707,5.51000,      -0.57684,3.27362,1
 75.18775,5.52000,      -0.57750,3.27355,1
 75.28833,5.53000,      -0.57813,3.27348,1
 75.38897,5.54000,      -0.57878,3.27340,1
 75.48961,5.55000,      -0.57953,3.27333,1
 75.59021,5.56000,      -0.58036,3.27325,1
 75.69082,5.57000,      -0.58061,3.27318,1
 75.79148,5.58000,      -0.58144,3.27311,1
 75.89215,5.59000,      -0.58210,3.27303,1
 75.99279,5.60000,      -0.58285,3.27296,1
 76.09343,5.61000,      -0.58356,3.27288,1
 76.19408,5.62000,      -0.58422,3.27281,1
 76.29469,5.63000,      -0.58464,3.27273,1
 76.39528,5.64000,      -0.58507,3.27266,1
 76.49585,5.65000,      -0.58590,3.27258,1
 76.59651,5.66000,      -0.58653,3.27251,1
 76.69710,5.67000,      -0.58716,3.27243,1
 76.79770,5.68000,      -0.58784,3.27236,1
 76.89831,5.69000,      -0.58844,3.27228,1
 76.99887,5.70000,      -0.58884,3.27221,1
 77.09939,5.71000,      -0.58944,3.27213,1
 77.19993,5.72000,      -0.59007,3.27205,1
 77.30049,5.73000,      -0.59073,3.27198,1
 77.40105,5.74000,      -0.59127,3.27190,1
 77.50154,5.75000,      -0.59175,3.27183,1
 77.60202,5.76000,      -0.59220,3.27175,1
 77.70256,5.77000,      -0.59266,3.27167,1
 77.80308,5.78000,      -0.59317,3.27160,1
 77.90356,5.79000,      -0.59383,3.27152,1
 78.00403,5.80000,      -0.59463,3.27144,1
 78.10452,5.81000,      -0.59494,3.27137,1
 78.20495,5.82000,      -0.59525,3.27129,1
 78.30541,5.83000,      -0.59614,3.27121,1
 78.40587,5.84000,      -0.59627,3.27114,1
 78.50625,5.85000,      -0.59675,3.27106,1
 78.60666,5.86000,      -0.59721,3.27098,1
 78.70703,5.87000,      -0.59766,3.27091,1
 78.80743,5.88000,      -0.59817,3.27083,1
 78.90779,5.89000,      -0.59872,3.27075,1
 79.00820,5.90000,      -0.59917,3.27067,1
 79.10854,5.91000,      -0.59945,3.27060,1
 79.20884,5.92000,      -0.59976,3.27052,1
 79.30918,5.93000,      -0.60021,3.27044,1
 79.40946,5.94000,      -0.60063,3.27036,1
 79.50974,5.95000,      -0.60109,3.27028,1
 79.61002,5.96000,      -0.60131,3.27021,1
 79.71028,5.97000,      -0.60185,3.27013,1
 79.81049,5.98000,      -0.60236,3.27005,1
 79.91072,5.99000,      -0.60267,3.26997,1
 80.01087,6.00000,      -0.60301,3.26989,1
 80.11098,6.01000,      -0.60338,3.26981,1
 80.21123,6.02000,      -0.60348,3.26973,1
 80.31139,6.03000,      -0.60370,3.26966,1
 80.41159,6.04000,      -0.60421,3.26958,1
 80.51179,6.05000,      -0.60458,3.26950,1
 80.61198,6.06000,      -0.60503,3.26942,1
 80.71211,6.07000,      -0.60528,3.26934,1
 80.81218,6.08000,      -0.60556,3.26926,1
 80.91228,6.09000,      -0.60578,3.26918,1
 81.01238,6.10000,      -0.60635,3.26910,1
 81.11244,6.11000,      -0.60646,3.26902,1
 81.21257,6.12000,      -0.60644,3.26894,1
 81.31267,6.13000,      -0.60658,3.26886,1
 81.41274,6.14000,      -0.60700,3.26878,1
 81.51282,6.15000,      -0.60716,3.26870,1
 81.61292,6.16000,      -0.60741,3.26862,1
 81.71303,6.17000,      -0.60757,3.26854,1
 81.81310,6.18000,      -0.60788,3.26846,1
 81.91315,6.19000,      -0.60805,3.26838,1
 82.01325,6.20000,      -0.60838,3.26830,1
 82.11336,6.21000,      -0.60869,3.26822,1
 82.21334,6.22000,      -0.60871,3.26814,1
 82.31338,6.23000,      -0.60890,3.26806,1
 82.41334,6.24000,      -0.60909,3.26798,1
 82.51333,6.25000,      -0.60922,3.26790,1
 82.61326,6.26000,      -0.60944,3.26782,1
 82.71331,6.27000,      -0.60969,3.26774,1
 82.81336,6.28000,      -0.60986,3.26765,1
 82.91338,6.29000,      -0.60990,3.26757,1
 83.01336,6.30000,      -0.61003,3.26749,1
 83.11341,6.31000,      -0.61017,3.26741,1
 83.21336,6.32000,      -0.61033,3.26733,1
 83.31331,6.33000,      -0.61032,3.26725,1
 83.41334,6.34000,      -0.61036,3.26717,1
 83.51338,6.35000,      -0.61079,3.26708,1
 83.61341,6.36000,      -0.61077,3.26700,1
 83.71344,6.37000,      -0.61105,3.26692,1
 83.81346,6.38000,      -0.61107,3.26684,1
 83.91344,6.39000,      -0.61117,3.26675,1
 84.01344,6.40000,      -0.61131,3.26667,1
 84.11343,6.41000,      -0.61135,3.26659,1
 84.21351,6.42000,      -0.61146,3.26651,1
 84.31357,6.43000,      -0.61147,3.26642,1
 84.41362,6.44000,      -0.61149,3.26634,1
 84.51367,6.45000,      -0.61159,3.26626,1
 84.61370,6.46000,      -0.61170,3.26617,1
 84.71370,6.47000,      -0.61171,3.26609,1
 84.81372,6.48000,      -0.61173,3.26601,1
 84.91377,6.49000,      -0.61183,3.26592,1
 85.01374,6.50000,      -0.61194,3.26584,1
 85.11370,6.51000,      -0.61198,3.26576,1
 85.21370,6.52000,      -0.61203,3.26567,1
 85.31375,6.53000,      -0.61211,3.26559,1
 85.41375,6.54000,      -0.61209,3.26550,1
 85.51369,6.55000,      -0.61211,3.26542,1
 85.61369,6.56000,      -0.61204,3.26534,1
 85.71369,6.57000,      -0.61205,3.26525,1
 85.81367,6.58000,      -0.61207,3.26517,1
 85.91372,6.59000,      -0.61206,3.26508,1
 86.01375,6.60000,      -0.61210,3.26500,1
 86.11379,6.61000,      -0.61203,3.26491,1
 86.21382,6.62000,      -0.61205,3.26483,1
 86.31382,6.63000,      -0.61192,3.26474,1
 86.41385,6.64000,      -0.61188,3.26466,1
 86.51392,6.65000,      -0.61189,3.26457,1
 86.61393,6.66000,      -0.61185,3.26449,1
 86.71400,6.67000,      -0.61187,3.26440,1
 86.81403,6.68000,      -0.61180,3.26432,1
 86.91403,6.69000,      -0.61178,3.26423,1
 87.01408,6.70000,      -0.61157,3.26415,1
 87.11413,6.71000,      -0.61161,3.26406,1
 87.21425,6.72000,      -0.61157,3.26398,1
 87.31429,6.73000,      -0.61156,3.26389,1
 87.41441,6.74000,      -0.61143,3.26380,1
 87.51449,6.75000,      -0.61118,3.26372,1
 87.61456,6.76000,      -0.61123,3.26363,1
 87.71459,6.77000,      -0.61110,3.26354,1
 87.81466,6.78000,      -0.61105,3.26346,1
 87.91474,6.79000,      -0.61081,3.26337,1
 88.01484,6.80000,      -0.61074,3.26328,1
 88.11487,6.81000,      -0.61052,3.26320,1
 88.21490,6.82000,      -0.61045,3.26311,1
 88.31495,6.83000,      -0.61038,3.26302,1
 88.41495,6.84000,      -0.61022,3.26294,1
 88.51487,6.85000,      -0.61009,3.26285,1
 88.61485,6.86000,      -0.60993,3.26276,1
 88.71480,6.87000,      -0.60977,3.26267,1
 88.81479,6.88000,      -0.60955,3.26259,1
 88.91477,6.89000,      -0.60951,3.26250,1
 89.01479,6.90000,      -0.60941,3.26241,1
 89.11477,6.91000,      -0.60899,3.26232,1
 89.21469,6.92000,      -0.60868,3.26224,1
 89.31462,6.93000,      -0.60867,3.26215,1
 89.41449,6.94000,      -0.60857,3.26206,1
 89.51446,6.95000,      -0.60835,3.26197,1
 89.61439,6.96000,      -0.60813,3.26188,1
 89.71438,6.97000,      -0.60783,3.26180,1
 89.81438,6.98000,      -0.60773,3.26171,1
 89.91434,6.99000,      -0.60742,3.26162,1
 90.01423,7.00000,      -0.60712,3.26153,1
 90.11421,7.01000,      -0.60678,3.26144,1
 90.21415,7.02000,      -0.60659,3.26135,1
 90.31408,7.03000,      -0.60667,3.26126,1
 90.41407,7.04000,      -0.60654,3.26117,1
 90.51408,7.05000,      -0.60632,3.26108,1
 90.61408,7.06000,      -0.60602,3.26100,1
 90.71410,7.07000,      -0.60553,3.26091,1
 90.81407,7.08000,      -0.60526,3.26082,1
 90.91408,7.09000,      -0.60507,3.26073,1
 91.01408,7.10000,      -0.60488,3.26064,1
 91.11413,7.11000,      -0.60446,3.26055,1
 91.21416,7.12000,      -0.60445,3.26046,1
 91.31421,7.13000,      -0.60429,3.26037,1
 91.41428,7.14000,      -0.60404,3.26028,1
 91.51433,7.15000,      -0.60373,3.26019,1
 91.61439,7.16000,      -0.60340,3.26010,1
 91.71438,7.17000,      -0.60286,3.26000,1
 91.81443,7.18000,      -0.60279,3.25991,1
 91.91438,7.19000,      -0.60263,3.25982,1
 92.01446,7.20000,      -0.60247,3.25973,1
 92.11449,7.21000,      -0.60176,3.25964,1
 92.21462,7.22000,      -0.60151,3.25955,1
 92.31469,7.23000,      -0.60120,3.25946,1
 92.41472,7.24000,      -0.60084,3.25937,1
 92.51477,7.25000,      -0.60053,3.25928,1
 92.61484,7.26000,      -0.60026,3.25919,1
 92.71495,7.27000,      -0.59992,3.25909,1
 92.81508,7.28000,      -0.59965,3.25900,1
 92.91523,7.29000,      -0.59946,3.25891,1
 93.01536,7.30000,      -0.59921,3.25882,1
 93.11548,7.31000,      -0.59888,3.25873,1
 93.21561,7.32000,      -0.59854,3.25863,1
 93.31577,7.33000,      -0.59847,3.25854,1
 93.41590,7.34000,      -0.59808,3.25845,1
 93.51605,7.35000,      -0.59751,3.25836,1
 93.61620,7.36000,      -0.59744,3.25826,1
 93.71638,7.37000,      -0.59701,3.25817,1
 93.81649,7.38000,      -0.59647,3.25808,1
 93.91670,7.39000,      -0.59611,3.25799,1
 94.01684,7.40000,      -0.59595,3.25789,1
 94.11700,7.41000,      -0.59553,3.25780,1
 94.21716,7.42000,      -0.59508,3.25771,1
 94.31736,7.43000,      -0.59471,3.25761,1
 94.41757,7.44000,      -0.59438,3.25752,1
 94.51784,7.45000,      -0.59413,3.25743,1
 94.61803,7.46000,      -0.59382,3.25733,1
 94.71823,7.47000,      -0.59343,3.25724,1
 94.81841,7.48000,      -0.59312,3.25714,1
 94.91859,7.49000,      -0.59288,3.25705,1
 95.01875,7.50000,      -0.59260,3.25696,1
 95.11897,7.51000,      -0.59218,3.25686,1
 95.21908,7.52000,      -0.59176,3.25677,1
 95.31920,7.53000,      -0.59136,3.25667,1
 95.41928,7.54000,      -0.59079,3.25658,1
 95.51939,7.55000,      -0.59052,3.25648,1
 95.61956,7.56000,      -0.59018,3.25639,1
 95.71975,7.57000,      -0.58952,3.25629,1
 95.81990,7.58000,      -0.58919,3.25620,1
 95.92003,7.59000,      -0.58882,3.25610,1
 96.02015,7.60000,      -0.58834,3.25601,1
 96.12030,7.61000,      -0.58792,3.25591,1
 96.22039,7.62000,      -0.58779,3.25582,1
 96.32049,7.63000,      -0.58725,3.25572,1
 96.42062,7.64000,      -0.58683,3.25563,1
 96.52069,7.65000,      -0.58646,3.25553,1
 96.62082,7.66000,      -0.58598,3.25544,1
 96.72092,7.67000,      -0.58553,3.25534,1
 96.82103,7.68000,      -0.58516,3.25525,1
 96.92113,7.69000,      -0.58468,3.25515,1
 97.02128,7.70000,      -0.58437,3.25505,1
 97.12138,7.71000,      -0.58378,3.25496,1
 97.22154,7.72000,      -0.58326,3.25486,1
 97.32170,7.73000,      -0.58252,3.25476,1
 97.42185,7.74000,      -0.58212,3.25467,1
 97.52203,7.75000,      -0.58194,3.25457,1
 97.62218,7.76000,      -0.58137,3.25447,1
 97.72229,7.77000,      -0.58085,3.25438,1
 97.82246,7.78000,      -0.58022,3.25428,1
 97.92261,7.79000,      -0.58001,3.25418,1
 98.02280,7.80000,      -0.57970,3.25409,1
 98.12302,7.81000,      -0.57887,3.25399,1
 98.22325,7.82000,      -0.57833,3.25389,1
 98.32346,7.83000,      -0.57811,3.25379,1
 98.42369,7.84000,      -0.57795,3.25370,1
 98.52395,7.85000,      -0.57723,3.25360,1
 98.62418,7.86000,      -0.57696,3.25350,1
 98.72452,7.87000,      -0.57668,3.25340,1
 98.82480,7.88000,      -0.57652,3.25330,1
 98.92518,7.89000,      -0.57630,3.25321,1
 99.02551,7.90000,      -0.57597,3.25311,1
 99.12584,7.91000,      -0.57552,3.25301,1
 99.22625,7.92000,      -0.57533,3.25291,1
 99.32664,7.93000,      -0.57523,3.25281,1
 99.42703,7.94000,      -0.57484,3.25271,1
 99.52751,7.95000,      -0.57468,3.25261,1
 99.62789,7.96000,      -0.57443,3.25251,1
 99.72830,7.97000,      -0.57451,3.25242,1
 99.82869,7.98000,      -0.57411,3.25232,1
 99.92913,7.99000,      -0.57366,3.25222,1
100.02954,8.00000,      -0.57339,3.25212,1
100.12995,8.01000,      -0.57299,3.25202,1
100.23036,8.02000,      -0.57278,3.25192,1
100.33085,8.03000,      -0.57250,3.25182,1
100.43138,8.04000,      -0.57208,3.25172,1
100.53184,8.05000,      -0.57156,3.25162,1
100.63230,8.06000,      -0.57114,3.25152,1
100.73274,8.07000,      -0.57072,3.25142,1
100.83318,8.08000,      -0.56991,3.25132,1
100.93359,8.09000,      -0.56928,3.25122,1
101.03397,8.10000,      -0.56868,3.25112,1
101.13433,8.11000,      -0.56782,3.25102,1
101.23474,8.12000,      -0.56713,3.25092,1
101.33508,8.13000,      -0.56644,3.25081,1
101.43544,8.14000,      -0.56558,3.25071,1
101.53574,8.15000,      -0.56503,3.25061,1
101.63607,8.16000,      -0.56458,3.25051,1
101.73639,8.17000,      -0.56380,3.25041,1
101.83669,8.18000,      -0.56320,3.25031,1
101.93695,8.19000,      -0.56258,3.25021,1
102.03725,8.20000,      -0.56198,3.25011,1
102.13754,8.21000,      -0.56132,3.25001,1
102.23779,8.22000,      -0.56066,3.24990,1
102.33797,8.23000,      -0.55997,3.24980,1
102.43810,8.24000,      -0.55928,3.24970,1
102.53825,8.25000,      -0.55909,3.24960,1
102.63844,8.26000,      -0.55823,3.24950,1
102.73857,8.27000,      -0.55751,3.24939,1
102.83870,8.28000,      -0.55667,3.24929,1
102.93882,8.29000,      -0.55619,3.24919,1
103.03895,8.30000,      -0.55565,3.24909,1
103.13903,8.31000,      -0.55502,3.24899,1
103.23913,8.32000,      -0.55442,3.24888,1
103.33921,8.33000,      -0.55387,3.24878,1
103.43933,8.34000,      -0.55324,3.24868,1
103.53949,8.35000,      -0.55261,3.24858,1
103.63962,8.36000,      -0.55207,3.24847,1
103.73977,8.37000,      -0.55135,3.24837,1
103.83987,8.38000,      -0.55078,3.24827,1
103.93998,8.39000,      -0.55039,3.24816,1
104.04008,8.40000,      -0.54988,3.24806,1
104.14010,8.41000,      -0.54919,3.24796,1
104.24018,8.42000,      -0.54838,3.24785,1
104.34034,8.43000,      -0.54775,3.24775,1
104.44046,8.44000,      -0.54741,3.24765,1
104.54052,8.45000,      -0.54693,3.24754,1
104.64059,8.46000,      -0.54598,3.24744,1
104.74064,8.47000,      -0.54555,3.24733,1
104.84069,8.48000,      -0.54501,3.24723,1
104.94072,8.49000,      -0.54447,3.24713,1
105.04077,8.50000,      -0.54363,3.24702,1
105.14085,8.51000,      -0.54309,3.24692,1
105.24093,8.52000,      -0.54270,3.24681,1
105.34095,8.53000,      -0.54218,3.24671,1
105.44105,8.54000,      -0.54123,3.24660,1
105.54105,8.55000,      -0.54063,3.24650,1
105.64110,8.56000,      -0.54053,3.24639,1
105.74110,8.57000,      -0.53972,3.24629,1
105.84116,8.58000,      -0.53888,3.24618,1
105.94121,8.59000,      -0.53828,3.24608,1
106.04123,8.60000,      -0.53768,3.24597,1
106.14131,8.61000,      -0.53693,3.24587,1
106.24134,8.62000,      -0.53645,3.24576,1
106.34131,8.63000,      -0.53594,3.24566,1
106.44134,8.64000,      -0.53539,3.24555,1
106.54138,8.65000,      -0.53479,3.24545,1
106.64146,8.66000,      -0.53419,3.24534,1
106.74156,8.67000,      -0.53350,3.24523,1
106.84161,8.68000,      -0.53281,3.24513,1
106.94162,8.69000,      -0.53262,3.24502,1
107.04162,8.70000,      -0.53187,3.24492,1
107.14162,8.71000,      -0.53092,3.24481,1
107.24162,8.72000,      -0.53008,3.24470,1
107.34164,8.73000,      -0.52974,3.24460,1
107.44156,8.74000,      -0.52917,3.24449,1
107.54154,8.75000,      -0.52834,3.24438,1
107.64151,8.76000,      -0.52759,3.24428,1
107.74146,8.77000,      -0.52693,3.24417,1
107.84141,8.78000,      -0.52638,3.24406,1
107.94138,8.79000,      -0.52572,3.24395,1
108.04136,8.80000,      -0.52530,3.24385,1
108.14134,8.81000,      -0.52431,3.24374,1
108.24128,8.82000,      -0.52383,3.24363,1
108.34125,8.83000,      -0.52323,3.24353,1
108.44116,8.84000,      -0.52274,3.24342,1
108.54102,8.85000,      -0.52191,3.24331,1
108.64092,8.86000,      -0.52113,3.24320,1
108.74084,8.87000,      -0.52041,3.24309,1
108.84077,8.88000,      -0.52001,3.24299,1
108.94075,8.89000,      -0.51953,3.24288,1
109.04072,8.90000,      -0.51881,3.24277,1
109.14069,8.91000,      -0.51770,3.24266,1
109.24056,8.92000,      -0.51681,3.24255,1
109.34048,8.93000,      -0.51644,3.24244,1
109.44043,8.94000,      -0.51587,3.24234,1
109.54038,8.95000,      -0.51524,3.24223,1
109.64031,8.96000,      -0.51449,3.24212,1
109.74020,8.97000,      -0.51368,3.24201,1
109.84013,8.98000,      -0.51269,3.24190,1
109.94007,8.99000,      -0.51197,3.24179,1
110.03997,9.00000,      -0.51163,3.24168,1
110.13982,9.01000,      -0.51118,3.24157,1
110.23975,9.02000,      -0.51052,3.24146,1
110.33964,9.03000,      -0.50933,3.24135,1
110.43961,9.04000,      -0.50866,3.24125,1
110.53957,9.05000,      -0.50809,3.24114,1
110.63949,9.06000,      -0.50749,3.24103,1
110.73938,9.07000,      -0.50697,3.24092,1
110.83930,9.08000,      -0.50637,3.24081,1
110.93918,9.09000,      -0.50550,3.24070,1
111.03911,9.10000,      -0.50481,3.24059,1
111.13911,9.11000,      -0.50400,3.24048,1
111.23910,9.12000,      -0.50319,3.24036,1
111.33920,9.13000,      -0.50230,3.24025,1
111.43921,9.14000,      -0.50211,3.24014,1
111.53921,9.15000,      -0.50124,3.24003,1
111.63920,9.16000,      -0.50046,3.23992,1
111.73925,9.17000,      -0.49968,3.23981,1
111.83933,9.18000,      -0.49896,3.23970,1
111.93938,9.19000,      -0.49830,3.23959,1
112.03944,9.20000,      -0.49778,3.23948,1
112.13951,9.21000,      -0.49706,3.23936,1
112.23961,9.22000,      -0.49625,3.23925,1
112.33967,9.23000,      -0.49547,3.23914,1
112.43975,9.24000,      -0.49466,3.23903,1
112.53984,9.25000,      -0.49421,3.23892,1
112.63993,9.26000,      -0.49331,3.23881,1
112.74002,9.27000,      -0.49262,3.23869,1
112.84018,9.28000,      -0.49184,3.23858,1
112.94028,9.29000,      -0.49117,3.23847,1
113.04041,9.30000,      -0.49042,3.23836,1
113.14052,9.31000,      -0.48976,3.23824,1
113.24056,9.32000,      -0.48916,3.23813,1
113.34057,9.33000,      -0.48844,3.23802,1
113.44061,9.34000,      -0.48772,3.23791,1
113.54069,9.35000,      -0.48685,3.23779,1
113.64075,9.36000,      -0.48610,3.23768,1
113.74079,9.37000,      -0.48531,3.23757,1
113.84090,9.38000,      -0.48456,3.23745,1
113.94093,9.39000,      -0.48402,3.23734,1
114.04092,9.40000,      -0.48333,3.23723,1
114.14093,9.41000,      -0.48255,3.23711,1
114.24095,9.42000,      -0.48174,3.23700,1
114.34097,9.43000,      -0.48110,3.23689,1
114.44100,9.44000,      -0.48026,3.23677,1
114.54100,9.45000,      -0.47933,3.23666,1
114.64102,9.46000,      -0.47858,3.23655,1
114.74102,9.47000,      -0.47780,3.23643,1
114.84097,9.48000,      -0.47705,3.23632,1
114.94095,9.49000,      -0.47642,3.23620,1
115.04085,9.50000,      -0.47555,3.23609,1
115.14077,9.51000,      -0.47479,3.23597,1
115.24070,9.52000,      -0.47401,3.23586,1
115.34067,9.53000,      -0.47326,3.23575,1
115.44062,9.54000,      -0.47263,3.23563,1
115.54054,9.55000,      -0.47185,3.23552,1
115.64044,9.56000,      -0.47086,3.23540,1
115.74041,9.57000,      -0.46999,3.23529,1
115.84029,9.58000,      -0.46915,3.23517,1
115.94023,9.59000,      -0.46825,3.23506,1
116.04016,9.60000,      -0.46744,3.23494,1
116.14011,9.61000,      -0.46683,3.23483,1
116.24005,9.62000,      -0.46602,3.23471,1
116.33995,9.63000,      -0.46515,3.23459,1
116.43984,9.64000,      -0.46434,3.23448,1
116.53972,9.65000,      -0.46347,3.23436,1
116.63954,9.66000,      -0.46304,3.23425,1
116.73943,9.67000,      -0.46199,3.23413,1
116.83933,9.68000,      -0.46115,3.23402,1
116.93920,9.69000,      -0.46043,3.23390,1
117.03913,9.70000,      -0.45965,3.23378,1
117.13905,9.71000,      -0.45872,3.23367,1
117.23900,9.72000,      -0.45793,3.23355,1
117.33890,9.73000,      -0.45724,3.23343,1
117.43885,9.74000,      -0.45637,3.23332,1
117.53877,9.75000,      -0.45556,3.23320,1
117.63866,9.76000,      -0.45466,3.23308,1
117.73854,9.77000,      -0.45388,3.23297,1
117.83841,9.78000,      -0.45303,3.23285,1
117.93831,9.79000,      -0.45222,3.23273,1
118.03823,9.80000,      -0.45144,3.23262,1
118.13810,9.81000,      -0.45063,3.23250,1
118.23800,9.82000,      -0.44979,3.23238,1
118.33793,9.83000,      -0.44897,3.23226,1
118.43785,9.84000,      -0.44804,3.23215,1
118.53780,9.85000,      -0.44753,3.23203,1
118.63777,9.86000,      -0.44683,3.23191,1
118.73774,9.87000,      -0.44578,3.23179,1
118.83771,9.88000,      -0.44488,3.23167,1
118.93764,9.89000,      -0.44401,3.23156,1
119.03700,9.90000,      -0.44317,3.23144,1
119.13687,9.91000,      -0.44241,3.23132,1
119.23669,9.92000,      -0.44163,3.23120,1
119.33649,9.93000,      -0.44085,3.23108,1
119.43635,9.94000,      -0.44018,3.23096,1
119.53606,9.95000,      -0.43946,3.23085,1
119.63584,9.96000,      -0.43865,3.23073,1
119.73542,9.97000,      -0.43751,3.23061,1
119.83454,9.98000,      -0.43652,3.23049,1
119.93200,9.99000,      -0.43579,3.23037,1
120.00300,9.99917,      -0.43529,3.23029,1